2021-11-24 18:39:06,520 18172 news_content_collection ERROR Exception in getting data from url speedtalk.com/forum/viewtopic.php?t=51650
Traceback (most recent call last):
  File "C:\Users\User\Desktop\ia2\FakeNewsNet\code\news_content_collection.py", line 25, in crawl_link_article
    article.parse()
  File "C:\Users\User\AppData\Local\Packages\PythonSoftwareFoundation.Python.3.9_qbz5n2kfra8p0\LocalCache\local-packages\Python39\site-packages\newspaper\article.py", line 191, in parse
    self.throw_if_not_downloaded_verbose()
  File "C:\Users\User\AppData\Local\Packages\PythonSoftwareFoundation.Python.3.9_qbz5n2kfra8p0\LocalCache\local-packages\Python39\site-packages\newspaper\article.py", line 531, in throw_if_not_downloaded_verbose
    raise ArticleException('Article `download()` failed with %s on URL %s' %
newspaper.article.ArticleException: Article `download()` failed with 404 Client Error: Not Found for url: https://www.speed-talk.com/forum/viewtopic.php?t=51650 on URL http://speedtalk.com/forum/viewtopic.php?t=51650
2021-11-24 18:39:13,302 18172 news_content_collection ERROR Exception in getting data from url speedtalk.com/forum/viewtopic.php?t=51650
Traceback (most recent call last):
  File "C:\Users\User\Desktop\ia2\FakeNewsNet\code\news_content_collection.py", line 36, in crawl_link_article
    article.parse()
  File "C:\Users\User\AppData\Local\Packages\PythonSoftwareFoundation.Python.3.9_qbz5n2kfra8p0\LocalCache\local-packages\Python39\site-packages\newspaper\article.py", line 191, in parse
    self.throw_if_not_downloaded_verbose()
  File "C:\Users\User\AppData\Local\Packages\PythonSoftwareFoundation.Python.3.9_qbz5n2kfra8p0\LocalCache\local-packages\Python39\site-packages\newspaper\article.py", line 531, in throw_if_not_downloaded_verbose
    raise ArticleException('Article `download()` failed with %s on URL %s' %
newspaper.article.ArticleException: Article `download()` failed with 404 Client Error: Not Found for url: https://www.speed-talk.com/forum/viewtopic.php?t=51650 on URL https://speedtalk.com/forum/viewtopic.php?t=51650
2021-11-24 18:39:15,911 18172 news_content_collection ERROR Exception in getting data from url politics2020.info/index.php/2018/03/13/court-orders-obama-to-pay-400-million-in-restitution/
Traceback (most recent call last):
  File "C:\Users\User\Desktop\ia2\FakeNewsNet\code\news_content_collection.py", line 25, in crawl_link_article
    article.parse()
  File "C:\Users\User\AppData\Local\Packages\PythonSoftwareFoundation.Python.3.9_qbz5n2kfra8p0\LocalCache\local-packages\Python39\site-packages\newspaper\article.py", line 191, in parse
    self.throw_if_not_downloaded_verbose()
  File "C:\Users\User\AppData\Local\Packages\PythonSoftwareFoundation.Python.3.9_qbz5n2kfra8p0\LocalCache\local-packages\Python39\site-packages\newspaper\article.py", line 531, in throw_if_not_downloaded_verbose
    raise ArticleException('Article `download()` failed with %s on URL %s' %
newspaper.article.ArticleException: Article `download()` failed with HTTPConnectionPool(host='politics2020.info', port=80): Max retries exceeded with url: /index.php/2018/03/13/court-orders-obama-to-pay-400-million-in-restitution/ (Caused by NewConnectionError('<urllib3.connection.HTTPConnection object at 0x000001C9C25EF490>: Failed to establish a new connection: [Errno 11001] getaddrinfo failed')) on URL http://politics2020.info/index.php/2018/03/13/court-orders-obama-to-pay-400-million-in-restitution/
2021-11-24 18:39:17,946 18172 news_content_collection ERROR Exception in getting data from url politics2020.info/index.php/2018/03/13/court-orders-obama-to-pay-400-million-in-restitution/
Traceback (most recent call last):
  File "C:\Users\User\Desktop\ia2\FakeNewsNet\code\news_content_collection.py", line 36, in crawl_link_article
    article.parse()
  File "C:\Users\User\AppData\Local\Packages\PythonSoftwareFoundation.Python.3.9_qbz5n2kfra8p0\LocalCache\local-packages\Python39\site-packages\newspaper\article.py", line 191, in parse
    self.throw_if_not_downloaded_verbose()
  File "C:\Users\User\AppData\Local\Packages\PythonSoftwareFoundation.Python.3.9_qbz5n2kfra8p0\LocalCache\local-packages\Python39\site-packages\newspaper\article.py", line 531, in throw_if_not_downloaded_verbose
    raise ArticleException('Article `download()` failed with %s on URL %s' %
newspaper.article.ArticleException: Article `download()` failed with HTTPSConnectionPool(host='politics2020.info', port=443): Max retries exceeded with url: /index.php/2018/03/13/court-orders-obama-to-pay-400-million-in-restitution/ (Caused by NewConnectionError('<urllib3.connection.VerifiedHTTPSConnection object at 0x000001C9C25EF730>: Failed to establish a new connection: [Errno 11001] getaddrinfo failed')) on URL https://politics2020.info/index.php/2018/03/13/court-orders-obama-to-pay-400-million-in-restitution/
2021-11-24 18:39:55,365 18172 news_content_collection ERROR Exception in getting data from url http://yournewswire.com/youngest-leader-george-soros/
Traceback (most recent call last):
  File "C:\Users\User\Desktop\ia2\FakeNewsNet\code\news_content_collection.py", line 49, in crawl_link_article
    article.parse()
  File "C:\Users\User\AppData\Local\Packages\PythonSoftwareFoundation.Python.3.9_qbz5n2kfra8p0\LocalCache\local-packages\Python39\site-packages\newspaper\article.py", line 191, in parse
    self.throw_if_not_downloaded_verbose()
  File "C:\Users\User\AppData\Local\Packages\PythonSoftwareFoundation.Python.3.9_qbz5n2kfra8p0\LocalCache\local-packages\Python39\site-packages\newspaper\article.py", line 531, in throw_if_not_downloaded_verbose
    raise ArticleException('Article `download()` failed with %s on URL %s' %
newspaper.article.ArticleException: Article `download()` failed with 404 Client Error: Not Found for url: http://yournewswire.com/youngest-leader-george-soros/ on URL http://yournewswire.com/youngest-leader-george-soros/
2021-11-24 18:40:07,482 18172 news_content_collection ERROR Exception in getting data from url http://dailyfeed.news/barack-obama-tweets-sick-attack-on-john-mccain-says-he-should-have-died/
Traceback (most recent call last):
  File "C:\Users\User\Desktop\ia2\FakeNewsNet\code\news_content_collection.py", line 49, in crawl_link_article
    article.parse()
  File "C:\Users\User\AppData\Local\Packages\PythonSoftwareFoundation.Python.3.9_qbz5n2kfra8p0\LocalCache\local-packages\Python39\site-packages\newspaper\article.py", line 191, in parse
    self.throw_if_not_downloaded_verbose()
  File "C:\Users\User\AppData\Local\Packages\PythonSoftwareFoundation.Python.3.9_qbz5n2kfra8p0\LocalCache\local-packages\Python39\site-packages\newspaper\article.py", line 531, in throw_if_not_downloaded_verbose
    raise ArticleException('Article `download()` failed with %s on URL %s' %
newspaper.article.ArticleException: Article `download()` failed with 404 Client Error: Not Found for url: https://cde.news/newsfeed/barack-obama-tweets-sick-attack-on-john-mccain-says-he-should-have-died on URL http://dailyfeed.news/barack-obama-tweets-sick-attack-on-john-mccain-says-he-should-have-died/
2021-11-24 18:40:26,058 18172 news_content_collection ERROR Exception in getting data from url http://therightists.com/gretchen-carlson-the-2nd-amendment-was-written-before-guns-were-invented/
Traceback (most recent call last):
  File "C:\Users\User\Desktop\ia2\FakeNewsNet\code\news_content_collection.py", line 49, in crawl_link_article
    article.parse()
  File "C:\Users\User\AppData\Local\Packages\PythonSoftwareFoundation.Python.3.9_qbz5n2kfra8p0\LocalCache\local-packages\Python39\site-packages\newspaper\article.py", line 191, in parse
    self.throw_if_not_downloaded_verbose()
  File "C:\Users\User\AppData\Local\Packages\PythonSoftwareFoundation.Python.3.9_qbz5n2kfra8p0\LocalCache\local-packages\Python39\site-packages\newspaper\article.py", line 531, in throw_if_not_downloaded_verbose
    raise ArticleException('Article `download()` failed with %s on URL %s' %
newspaper.article.ArticleException: Article `download()` failed with 404 Client Error: Not Found for url: https://therightists.com/gretchen-carlson-the-2nd-amendment-was-written-before-guns-were-invented/ on URL http://therightists.com/gretchen-carlson-the-2nd-amendment-was-written-before-guns-were-invented/
2021-11-24 18:40:32,620 18172 news_content_collection ERROR Exception in getting data from url http://yournewswire.com/pope-francis-jesus-metaphorical/
Traceback (most recent call last):
  File "C:\Users\User\Desktop\ia2\FakeNewsNet\code\news_content_collection.py", line 49, in crawl_link_article
    article.parse()
  File "C:\Users\User\AppData\Local\Packages\PythonSoftwareFoundation.Python.3.9_qbz5n2kfra8p0\LocalCache\local-packages\Python39\site-packages\newspaper\article.py", line 191, in parse
    self.throw_if_not_downloaded_verbose()
  File "C:\Users\User\AppData\Local\Packages\PythonSoftwareFoundation.Python.3.9_qbz5n2kfra8p0\LocalCache\local-packages\Python39\site-packages\newspaper\article.py", line 531, in throw_if_not_downloaded_verbose
    raise ArticleException('Article `download()` failed with %s on URL %s' %
newspaper.article.ArticleException: Article `download()` failed with 404 Client Error: Not Found for url: http://yournewswire.com/pope-francis-jesus-metaphorical/ on URL http://yournewswire.com/pope-francis-jesus-metaphorical/
2021-11-24 18:40:54,863 18172 news_content_collection ERROR Exception in getting data from url http://nrtonline.info/breaking-nancy-pelosi-to-resign-after-new-revelations/
Traceback (most recent call last):
  File "C:\Users\User\Desktop\ia2\FakeNewsNet\code\news_content_collection.py", line 49, in crawl_link_article
    article.parse()
  File "C:\Users\User\AppData\Local\Packages\PythonSoftwareFoundation.Python.3.9_qbz5n2kfra8p0\LocalCache\local-packages\Python39\site-packages\newspaper\article.py", line 191, in parse
    self.throw_if_not_downloaded_verbose()
  File "C:\Users\User\AppData\Local\Packages\PythonSoftwareFoundation.Python.3.9_qbz5n2kfra8p0\LocalCache\local-packages\Python39\site-packages\newspaper\article.py", line 531, in throw_if_not_downloaded_verbose
    raise ArticleException('Article `download()` failed with %s on URL %s' %
newspaper.article.ArticleException: Article `download()` failed with HTTPConnectionPool(host='nrtonline.info', port=80): Max retries exceeded with url: /breaking-nancy-pelosi-to-resign-after-new-revelations/ (Caused by NewConnectionError('<urllib3.connection.HTTPConnection object at 0x000001C9C2404DC0>: Failed to establish a new connection: [Errno 11001] getaddrinfo failed')) on URL http://nrtonline.info/breaking-nancy-pelosi-to-resign-after-new-revelations/
2021-11-24 18:41:04,952 18172 news_content_collection ERROR Exception in getting data from url usaconservativereport.com/2017/08/breaking-leaked-picture-obama-dragged-judge-handcuffs-wiretapping-trump/
Traceback (most recent call last):
  File "C:\Users\User\Desktop\ia2\FakeNewsNet\code\news_content_collection.py", line 25, in crawl_link_article
    article.parse()
  File "C:\Users\User\AppData\Local\Packages\PythonSoftwareFoundation.Python.3.9_qbz5n2kfra8p0\LocalCache\local-packages\Python39\site-packages\newspaper\article.py", line 191, in parse
    self.throw_if_not_downloaded_verbose()
  File "C:\Users\User\AppData\Local\Packages\PythonSoftwareFoundation.Python.3.9_qbz5n2kfra8p0\LocalCache\local-packages\Python39\site-packages\newspaper\article.py", line 531, in throw_if_not_downloaded_verbose
    raise ArticleException('Article `download()` failed with %s on URL %s' %
newspaper.article.ArticleException: Article `download()` failed with HTTPConnectionPool(host='usaconservativereport.com', port=80): Max retries exceeded with url: /2017/08/breaking-leaked-picture-obama-dragged-judge-handcuffs-wiretapping-trump/ (Caused by NewConnectionError('<urllib3.connection.HTTPConnection object at 0x000001C9C2492C10>: Failed to establish a new connection: [Errno 11001] getaddrinfo failed')) on URL http://usaconservativereport.com/2017/08/breaking-leaked-picture-obama-dragged-judge-handcuffs-wiretapping-trump/
2021-11-24 18:41:06,985 18172 news_content_collection ERROR Exception in getting data from url usaconservativereport.com/2017/08/breaking-leaked-picture-obama-dragged-judge-handcuffs-wiretapping-trump/
Traceback (most recent call last):
  File "C:\Users\User\Desktop\ia2\FakeNewsNet\code\news_content_collection.py", line 36, in crawl_link_article
    article.parse()
  File "C:\Users\User\AppData\Local\Packages\PythonSoftwareFoundation.Python.3.9_qbz5n2kfra8p0\LocalCache\local-packages\Python39\site-packages\newspaper\article.py", line 191, in parse
    self.throw_if_not_downloaded_verbose()
  File "C:\Users\User\AppData\Local\Packages\PythonSoftwareFoundation.Python.3.9_qbz5n2kfra8p0\LocalCache\local-packages\Python39\site-packages\newspaper\article.py", line 531, in throw_if_not_downloaded_verbose
    raise ArticleException('Article `download()` failed with %s on URL %s' %
newspaper.article.ArticleException: Article `download()` failed with HTTPSConnectionPool(host='usaconservativereport.com', port=443): Max retries exceeded with url: /2017/08/breaking-leaked-picture-obama-dragged-judge-handcuffs-wiretapping-trump/ (Caused by NewConnectionError('<urllib3.connection.VerifiedHTTPSConnection object at 0x000001C9C2492BE0>: Failed to establish a new connection: [Errno 11001] getaddrinfo failed')) on URL https://usaconservativereport.com/2017/08/breaking-leaked-picture-obama-dragged-judge-handcuffs-wiretapping-trump/
2021-11-24 18:41:14,217 18172 news_content_collection ERROR Exception in getting data from url https://www.puppetstringnews.com/blog/clinton-campaign-official-arrested-by-fbi-on-child-rapetrafficking-charges
Traceback (most recent call last):
  File "C:\Users\User\Desktop\ia2\FakeNewsNet\code\news_content_collection.py", line 49, in crawl_link_article
    article.parse()
  File "C:\Users\User\AppData\Local\Packages\PythonSoftwareFoundation.Python.3.9_qbz5n2kfra8p0\LocalCache\local-packages\Python39\site-packages\newspaper\article.py", line 191, in parse
    self.throw_if_not_downloaded_verbose()
  File "C:\Users\User\AppData\Local\Packages\PythonSoftwareFoundation.Python.3.9_qbz5n2kfra8p0\LocalCache\local-packages\Python39\site-packages\newspaper\article.py", line 531, in throw_if_not_downloaded_verbose
    raise ArticleException('Article `download()` failed with %s on URL %s' %
newspaper.article.ArticleException: Article `download()` failed with 404 Client Error: Not Found for url: https://puppetstringnews.com/blog/clinton-campaign-official-arrested-by-fbi-on-child-rapetrafficking-charges on URL https://www.puppetstringnews.com/blog/clinton-campaign-official-arrested-by-fbi-on-child-rapetrafficking-charges
2021-11-24 18:41:21,158 18172 news_content_collection ERROR Exception in getting data from url donaldtrainews.blogspot.com/2017/11/breaking-rosa-parks-granddaughter-slams.html
Traceback (most recent call last):
  File "C:\Users\User\Desktop\ia2\FakeNewsNet\code\news_content_collection.py", line 25, in crawl_link_article
    article.parse()
  File "C:\Users\User\AppData\Local\Packages\PythonSoftwareFoundation.Python.3.9_qbz5n2kfra8p0\LocalCache\local-packages\Python39\site-packages\newspaper\article.py", line 191, in parse
    self.throw_if_not_downloaded_verbose()
  File "C:\Users\User\AppData\Local\Packages\PythonSoftwareFoundation.Python.3.9_qbz5n2kfra8p0\LocalCache\local-packages\Python39\site-packages\newspaper\article.py", line 531, in throw_if_not_downloaded_verbose
    raise ArticleException('Article `download()` failed with %s on URL %s' %
newspaper.article.ArticleException: Article `download()` failed with 404 Client Error: Not Found for url: http://donaldtrainews.blogspot.com/2017/11/breaking-rosa-parks-granddaughter-slams.html on URL http://donaldtrainews.blogspot.com/2017/11/breaking-rosa-parks-granddaughter-slams.html
2021-11-24 18:41:23,683 18172 news_content_collection ERROR Exception in getting data from url donaldtrainews.blogspot.com/2017/11/breaking-rosa-parks-granddaughter-slams.html
Traceback (most recent call last):
  File "C:\Users\User\Desktop\ia2\FakeNewsNet\code\news_content_collection.py", line 36, in crawl_link_article
    article.parse()
  File "C:\Users\User\AppData\Local\Packages\PythonSoftwareFoundation.Python.3.9_qbz5n2kfra8p0\LocalCache\local-packages\Python39\site-packages\newspaper\article.py", line 191, in parse
    self.throw_if_not_downloaded_verbose()
  File "C:\Users\User\AppData\Local\Packages\PythonSoftwareFoundation.Python.3.9_qbz5n2kfra8p0\LocalCache\local-packages\Python39\site-packages\newspaper\article.py", line 531, in throw_if_not_downloaded_verbose
    raise ArticleException('Article `download()` failed with %s on URL %s' %
newspaper.article.ArticleException: Article `download()` failed with 404 Client Error: Not Found for url: https://donaldtrainews.blogspot.com/2017/11/breaking-rosa-parks-granddaughter-slams.html on URL https://donaldtrainews.blogspot.com/2017/11/breaking-rosa-parks-granddaughter-slams.html
2021-11-24 18:41:47,991 18172 news_content_collection ERROR Exception in getting data from url http://yournewswire.com/clinton-email-we-must-destroy-syria-for-israel/
Traceback (most recent call last):
  File "C:\Users\User\Desktop\ia2\FakeNewsNet\code\news_content_collection.py", line 49, in crawl_link_article
    article.parse()
  File "C:\Users\User\AppData\Local\Packages\PythonSoftwareFoundation.Python.3.9_qbz5n2kfra8p0\LocalCache\local-packages\Python39\site-packages\newspaper\article.py", line 191, in parse
    self.throw_if_not_downloaded_verbose()
  File "C:\Users\User\AppData\Local\Packages\PythonSoftwareFoundation.Python.3.9_qbz5n2kfra8p0\LocalCache\local-packages\Python39\site-packages\newspaper\article.py", line 531, in throw_if_not_downloaded_verbose
    raise ArticleException('Article `download()` failed with %s on URL %s' %
newspaper.article.ArticleException: Article `download()` failed with 404 Client Error: Not Found for url: http://yournewswire.com/clinton-email-we-must-destroy-syria-for-israel/ on URL http://yournewswire.com/clinton-email-we-must-destroy-syria-for-israel/
2021-11-24 18:41:54,547 18172 news_content_collection ERROR Exception in getting data from url https://quickening-spirit.com/fareed-zakaria-calls-for-jihad-rape-of-white-women/
Traceback (most recent call last):
  File "C:\Users\User\Desktop\ia2\FakeNewsNet\code\news_content_collection.py", line 49, in crawl_link_article
    article.parse()
  File "C:\Users\User\AppData\Local\Packages\PythonSoftwareFoundation.Python.3.9_qbz5n2kfra8p0\LocalCache\local-packages\Python39\site-packages\newspaper\article.py", line 191, in parse
    self.throw_if_not_downloaded_verbose()
  File "C:\Users\User\AppData\Local\Packages\PythonSoftwareFoundation.Python.3.9_qbz5n2kfra8p0\LocalCache\local-packages\Python39\site-packages\newspaper\article.py", line 531, in throw_if_not_downloaded_verbose
    raise ArticleException('Article `download()` failed with %s on URL %s' %
newspaper.article.ArticleException: Article `download()` failed with HTTPSConnectionPool(host='quickening-spirit.com', port=443): Max retries exceeded with url: /fareed-zakaria-calls-for-jihad-rape-of-white-women/ (Caused by SSLError(SSLCertVerificationError(1, '[SSL: CERTIFICATE_VERIFY_FAILED] certificate verify failed: self signed certificate in certificate chain (_ssl.c:1129)'))) on URL https://quickening-spirit.com/fareed-zakaria-calls-for-jihad-rape-of-white-women/
2021-11-24 18:42:02,170 18172 news_content_collection ERROR Exception in getting data from url www.newsweek.com/president-donald-trump-kim-jong-un-nobel-peace-prize-north-korea-south-korea-905146
Traceback (most recent call last):
  File "C:\Users\User\Desktop\ia2\FakeNewsNet\code\news_content_collection.py", line 25, in crawl_link_article
    article.parse()
  File "C:\Users\User\AppData\Local\Packages\PythonSoftwareFoundation.Python.3.9_qbz5n2kfra8p0\LocalCache\local-packages\Python39\site-packages\newspaper\article.py", line 191, in parse
    self.throw_if_not_downloaded_verbose()
  File "C:\Users\User\AppData\Local\Packages\PythonSoftwareFoundation.Python.3.9_qbz5n2kfra8p0\LocalCache\local-packages\Python39\site-packages\newspaper\article.py", line 531, in throw_if_not_downloaded_verbose
    raise ArticleException('Article `download()` failed with %s on URL %s' %
newspaper.article.ArticleException: Article `download()` failed with 403 Client Error: Forbidden for url: https://www.newsweek.com/president-donald-trump-kim-jong-un-nobel-peace-prize-north-korea-south-korea-905146 on URL http://www.newsweek.com/president-donald-trump-kim-jong-un-nobel-peace-prize-north-korea-south-korea-905146
2021-11-24 18:42:04,744 18172 news_content_collection ERROR Exception in getting data from url www.newsweek.com/president-donald-trump-kim-jong-un-nobel-peace-prize-north-korea-south-korea-905146
Traceback (most recent call last):
  File "C:\Users\User\Desktop\ia2\FakeNewsNet\code\news_content_collection.py", line 36, in crawl_link_article
    article.parse()
  File "C:\Users\User\AppData\Local\Packages\PythonSoftwareFoundation.Python.3.9_qbz5n2kfra8p0\LocalCache\local-packages\Python39\site-packages\newspaper\article.py", line 191, in parse
    self.throw_if_not_downloaded_verbose()
  File "C:\Users\User\AppData\Local\Packages\PythonSoftwareFoundation.Python.3.9_qbz5n2kfra8p0\LocalCache\local-packages\Python39\site-packages\newspaper\article.py", line 531, in throw_if_not_downloaded_verbose
    raise ArticleException('Article `download()` failed with %s on URL %s' %
newspaper.article.ArticleException: Article `download()` failed with 403 Client Error: Forbidden for url: https://www.newsweek.com/president-donald-trump-kim-jong-un-nobel-peace-prize-north-korea-south-korea-905146 on URL https://www.newsweek.com/president-donald-trump-kim-jong-un-nobel-peace-prize-north-korea-south-korea-905146
2021-11-24 18:42:12,191 18172 news_content_collection ERROR Exception in getting data from url www.usacarry.com/forums/politics-and-news/62789-update-hillary-clinton-leaves-country-mueller-indictment-announced.html
Traceback (most recent call last):
  File "C:\Users\User\Desktop\ia2\FakeNewsNet\code\news_content_collection.py", line 25, in crawl_link_article
    article.parse()
  File "C:\Users\User\AppData\Local\Packages\PythonSoftwareFoundation.Python.3.9_qbz5n2kfra8p0\LocalCache\local-packages\Python39\site-packages\newspaper\article.py", line 191, in parse
    self.throw_if_not_downloaded_verbose()
  File "C:\Users\User\AppData\Local\Packages\PythonSoftwareFoundation.Python.3.9_qbz5n2kfra8p0\LocalCache\local-packages\Python39\site-packages\newspaper\article.py", line 531, in throw_if_not_downloaded_verbose
    raise ArticleException('Article `download()` failed with %s on URL %s' %
newspaper.article.ArticleException: Article `download()` failed with 403 Client Error: Forbidden for url: https://forums.usacarry.com/politics-and-news/62789-update-hillary-clinton-leaves-country-mueller-indictment-announced.html on URL http://www.usacarry.com/forums/politics-and-news/62789-update-hillary-clinton-leaves-country-mueller-indictment-announced.html
2021-11-24 18:42:14,957 18172 news_content_collection ERROR Exception in getting data from url www.usacarry.com/forums/politics-and-news/62789-update-hillary-clinton-leaves-country-mueller-indictment-announced.html
Traceback (most recent call last):
  File "C:\Users\User\Desktop\ia2\FakeNewsNet\code\news_content_collection.py", line 36, in crawl_link_article
    article.parse()
  File "C:\Users\User\AppData\Local\Packages\PythonSoftwareFoundation.Python.3.9_qbz5n2kfra8p0\LocalCache\local-packages\Python39\site-packages\newspaper\article.py", line 191, in parse
    self.throw_if_not_downloaded_verbose()
  File "C:\Users\User\AppData\Local\Packages\PythonSoftwareFoundation.Python.3.9_qbz5n2kfra8p0\LocalCache\local-packages\Python39\site-packages\newspaper\article.py", line 531, in throw_if_not_downloaded_verbose
    raise ArticleException('Article `download()` failed with %s on URL %s' %
newspaper.article.ArticleException: Article `download()` failed with 403 Client Error: Forbidden for url: https://forums.usacarry.com/politics-and-news/62789-update-hillary-clinton-leaves-country-mueller-indictment-announced.html on URL https://www.usacarry.com/forums/politics-and-news/62789-update-hillary-clinton-leaves-country-mueller-indictment-announced.html
2021-11-24 18:42:30,694 18172 news_content_collection ERROR Exception in getting data from url www.smoaky.com/forum/index.php?/topic/161489-barrels-removed-from-clinton-property-contain-parts-from-3-missing-women/
Traceback (most recent call last):
  File "C:\Users\User\Desktop\ia2\FakeNewsNet\code\news_content_collection.py", line 25, in crawl_link_article
    article.parse()
  File "C:\Users\User\AppData\Local\Packages\PythonSoftwareFoundation.Python.3.9_qbz5n2kfra8p0\LocalCache\local-packages\Python39\site-packages\newspaper\article.py", line 191, in parse
    self.throw_if_not_downloaded_verbose()
  File "C:\Users\User\AppData\Local\Packages\PythonSoftwareFoundation.Python.3.9_qbz5n2kfra8p0\LocalCache\local-packages\Python39\site-packages\newspaper\article.py", line 531, in throw_if_not_downloaded_verbose
    raise ArticleException('Article `download()` failed with %s on URL %s' %
newspaper.article.ArticleException: Article `download()` failed with 403 Client Error: Forbidden for url: http://www.smoaky.com/forum/index.php?/topic/161489-barrels-removed-from-clinton-property-contain-parts-from-3-missing-women/ on URL http://www.smoaky.com/forum/index.php?/topic/161489-barrels-removed-from-clinton-property-contain-parts-from-3-missing-women/
2021-11-24 18:42:32,858 18172 news_content_collection ERROR Exception in getting data from url www.smoaky.com/forum/index.php?/topic/161489-barrels-removed-from-clinton-property-contain-parts-from-3-missing-women/
Traceback (most recent call last):
  File "C:\Users\User\Desktop\ia2\FakeNewsNet\code\news_content_collection.py", line 36, in crawl_link_article
    article.parse()
  File "C:\Users\User\AppData\Local\Packages\PythonSoftwareFoundation.Python.3.9_qbz5n2kfra8p0\LocalCache\local-packages\Python39\site-packages\newspaper\article.py", line 191, in parse
    self.throw_if_not_downloaded_verbose()
  File "C:\Users\User\AppData\Local\Packages\PythonSoftwareFoundation.Python.3.9_qbz5n2kfra8p0\LocalCache\local-packages\Python39\site-packages\newspaper\article.py", line 531, in throw_if_not_downloaded_verbose
    raise ArticleException('Article `download()` failed with %s on URL %s' %
newspaper.article.ArticleException: Article `download()` failed with 403 Client Error: Forbidden for url: https://www.smoaky.com/forum/index.php?/topic/161489-barrels-removed-from-clinton-property-contain-parts-from-3-missing-women/ on URL https://www.smoaky.com/forum/index.php?/topic/161489-barrels-removed-from-clinton-property-contain-parts-from-3-missing-women/
2021-11-24 18:42:36,648 18172 news_content_collection ERROR Exception in getting data from url http://londonwebnews.com/2017/06/01/liberal-women-hate-me-because-of-my-striking-beauty-and-intellect-says-kellyanne-conway/
Traceback (most recent call last):
  File "C:\Users\User\Desktop\ia2\FakeNewsNet\code\news_content_collection.py", line 49, in crawl_link_article
    article.parse()
  File "C:\Users\User\AppData\Local\Packages\PythonSoftwareFoundation.Python.3.9_qbz5n2kfra8p0\LocalCache\local-packages\Python39\site-packages\newspaper\article.py", line 191, in parse
    self.throw_if_not_downloaded_verbose()
  File "C:\Users\User\AppData\Local\Packages\PythonSoftwareFoundation.Python.3.9_qbz5n2kfra8p0\LocalCache\local-packages\Python39\site-packages\newspaper\article.py", line 531, in throw_if_not_downloaded_verbose
    raise ArticleException('Article `download()` failed with %s on URL %s' %
newspaper.article.ArticleException: Article `download()` failed with 404 Client Error: Not Found for url: http://londonwebnews.com/2017/06/01/liberal-women-hate-me-because-of-my-striking-beauty-and-intellect-says-kellyanne-conway/ on URL http://londonwebnews.com/2017/06/01/liberal-women-hate-me-because-of-my-striking-beauty-and-intellect-says-kellyanne-conway/
2021-11-24 18:43:09,888 18172 news_content_collection ERROR Exception in getting data from url https://yournewswire.com/broward-county-sheriff-fired/
Traceback (most recent call last):
  File "C:\Users\User\Desktop\ia2\FakeNewsNet\code\news_content_collection.py", line 49, in crawl_link_article
    article.parse()
  File "C:\Users\User\AppData\Local\Packages\PythonSoftwareFoundation.Python.3.9_qbz5n2kfra8p0\LocalCache\local-packages\Python39\site-packages\newspaper\article.py", line 191, in parse
    self.throw_if_not_downloaded_verbose()
  File "C:\Users\User\AppData\Local\Packages\PythonSoftwareFoundation.Python.3.9_qbz5n2kfra8p0\LocalCache\local-packages\Python39\site-packages\newspaper\article.py", line 531, in throw_if_not_downloaded_verbose
    raise ArticleException('Article `download()` failed with %s on URL %s' %
newspaper.article.ArticleException: Article `download()` failed with 404 Client Error: Not Found for url: https://yournewswire.com/broward-county-sheriff-fired/ on URL https://yournewswire.com/broward-county-sheriff-fired/
2021-11-24 18:43:25,527 18172 news_content_collection ERROR Exception in getting data from url http://www.newslo.com/price-better-budget-cancer-patients-die-quickly/
Traceback (most recent call last):
  File "C:\Users\User\Desktop\ia2\FakeNewsNet\code\news_content_collection.py", line 49, in crawl_link_article
    article.parse()
  File "C:\Users\User\AppData\Local\Packages\PythonSoftwareFoundation.Python.3.9_qbz5n2kfra8p0\LocalCache\local-packages\Python39\site-packages\newspaper\article.py", line 191, in parse
    self.throw_if_not_downloaded_verbose()
  File "C:\Users\User\AppData\Local\Packages\PythonSoftwareFoundation.Python.3.9_qbz5n2kfra8p0\LocalCache\local-packages\Python39\site-packages\newspaper\article.py", line 531, in throw_if_not_downloaded_verbose
    raise ArticleException('Article `download()` failed with %s on URL %s' %
newspaper.article.ArticleException: Article `download()` failed with HTTPSConnectionPool(host='newslo.com', port=443): Read timed out. (read timeout=7) on URL http://www.newslo.com/price-better-budget-cancer-patients-die-quickly/
2021-11-24 18:43:32,826 18172 news_content_collection ERROR Exception in getting data from url https://sentinelksmo.org/breaking-greitens-accuser-admits-photo-session-may-dream/
Traceback (most recent call last):
  File "C:\Users\User\Desktop\ia2\FakeNewsNet\code\news_content_collection.py", line 49, in crawl_link_article
    article.parse()
  File "C:\Users\User\AppData\Local\Packages\PythonSoftwareFoundation.Python.3.9_qbz5n2kfra8p0\LocalCache\local-packages\Python39\site-packages\newspaper\article.py", line 191, in parse
    self.throw_if_not_downloaded_verbose()
  File "C:\Users\User\AppData\Local\Packages\PythonSoftwareFoundation.Python.3.9_qbz5n2kfra8p0\LocalCache\local-packages\Python39\site-packages\newspaper\article.py", line 531, in throw_if_not_downloaded_verbose
    raise ArticleException('Article `download()` failed with %s on URL %s' %
newspaper.article.ArticleException: Article `download()` failed with ('Connection aborted.', ConnectionResetError(10054, 'An existing connection was forcibly closed by the remote host', None, 10054, None)) on URL https://sentinelksmo.org/breaking-greitens-accuser-admits-photo-session-may-dream/
2021-11-24 18:43:44,213 18172 news_content_collection ERROR Exception in getting data from url www.christforums.org/topic/4569-pope-francis-to-followers-%E2%80%9Ckoran-and-holy-bible-are-the-same%E2%80%9D/
Traceback (most recent call last):
  File "C:\Users\User\Desktop\ia2\FakeNewsNet\code\news_content_collection.py", line 25, in crawl_link_article
    article.parse()
  File "C:\Users\User\AppData\Local\Packages\PythonSoftwareFoundation.Python.3.9_qbz5n2kfra8p0\LocalCache\local-packages\Python39\site-packages\newspaper\article.py", line 191, in parse
    self.throw_if_not_downloaded_verbose()
  File "C:\Users\User\AppData\Local\Packages\PythonSoftwareFoundation.Python.3.9_qbz5n2kfra8p0\LocalCache\local-packages\Python39\site-packages\newspaper\article.py", line 531, in throw_if_not_downloaded_verbose
    raise ArticleException('Article `download()` failed with %s on URL %s' %
newspaper.article.ArticleException: Article `download()` failed with 404 Client Error: Not Found for url: http://www.christforums.org/topic/4569-pope-francis-to-followers-%E2%80%9Ckoran-and-holy-bible-are-the-same%E2%80%9D/ on URL http://www.christforums.org/topic/4569-pope-francis-to-followers-%E2%80%9Ckoran-and-holy-bible-are-the-same%E2%80%9D/
2021-11-24 18:43:46,841 18172 news_content_collection ERROR Exception in getting data from url www.christforums.org/topic/4569-pope-francis-to-followers-%E2%80%9Ckoran-and-holy-bible-are-the-same%E2%80%9D/
Traceback (most recent call last):
  File "C:\Users\User\Desktop\ia2\FakeNewsNet\code\news_content_collection.py", line 36, in crawl_link_article
    article.parse()
  File "C:\Users\User\AppData\Local\Packages\PythonSoftwareFoundation.Python.3.9_qbz5n2kfra8p0\LocalCache\local-packages\Python39\site-packages\newspaper\article.py", line 191, in parse
    self.throw_if_not_downloaded_verbose()
  File "C:\Users\User\AppData\Local\Packages\PythonSoftwareFoundation.Python.3.9_qbz5n2kfra8p0\LocalCache\local-packages\Python39\site-packages\newspaper\article.py", line 531, in throw_if_not_downloaded_verbose
    raise ArticleException('Article `download()` failed with %s on URL %s' %
newspaper.article.ArticleException: Article `download()` failed with HTTPSConnectionPool(host='www.christforums.org', port=443): Max retries exceeded with url: /topic/4569-pope-francis-to-followers-%E2%80%9Ckoran-and-holy-bible-are-the-same%E2%80%9D/ (Caused by SSLError(SSLCertVerificationError(1, '[SSL: CERTIFICATE_VERIFY_FAILED] certificate verify failed: self signed certificate (_ssl.c:1129)'))) on URL https://www.christforums.org/topic/4569-pope-francis-to-followers-%E2%80%9Ckoran-and-holy-bible-are-the-same%E2%80%9D/
2021-11-24 18:43:54,276 18172 news_content_collection ERROR Exception in getting data from url http://mysteriousearth.club/2018/04/08/cia-release-documents-of-moon-moon-has-more-than-250-million-citizens/
Traceback (most recent call last):
  File "C:\Users\User\Desktop\ia2\FakeNewsNet\code\news_content_collection.py", line 49, in crawl_link_article
    article.parse()
  File "C:\Users\User\AppData\Local\Packages\PythonSoftwareFoundation.Python.3.9_qbz5n2kfra8p0\LocalCache\local-packages\Python39\site-packages\newspaper\article.py", line 191, in parse
    self.throw_if_not_downloaded_verbose()
  File "C:\Users\User\AppData\Local\Packages\PythonSoftwareFoundation.Python.3.9_qbz5n2kfra8p0\LocalCache\local-packages\Python39\site-packages\newspaper\article.py", line 531, in throw_if_not_downloaded_verbose
    raise ArticleException('Article `download()` failed with %s on URL %s' %
newspaper.article.ArticleException: Article `download()` failed with 404 Client Error: Not Found for url: https://mysteriousearth.club/2018/04/08/cia-release-documents-of-moon-moon-has-more-than-250-million-citizens/ on URL http://mysteriousearth.club/2018/04/08/cia-release-documents-of-moon-moon-has-more-than-250-million-citizens/
2021-11-24 18:44:06,177 18172 news_content_collection ERROR Exception in getting data from url https://exclusive103.com/2018/04/30/thousands-killed-as-israel-drops-tactical-nuclear-bomb-on-syria/
Traceback (most recent call last):
  File "C:\Users\User\Desktop\ia2\FakeNewsNet\code\news_content_collection.py", line 49, in crawl_link_article
    article.parse()
  File "C:\Users\User\AppData\Local\Packages\PythonSoftwareFoundation.Python.3.9_qbz5n2kfra8p0\LocalCache\local-packages\Python39\site-packages\newspaper\article.py", line 191, in parse
    self.throw_if_not_downloaded_verbose()
  File "C:\Users\User\AppData\Local\Packages\PythonSoftwareFoundation.Python.3.9_qbz5n2kfra8p0\LocalCache\local-packages\Python39\site-packages\newspaper\article.py", line 531, in throw_if_not_downloaded_verbose
    raise ArticleException('Article `download()` failed with %s on URL %s' %
newspaper.article.ArticleException: Article `download()` failed with HTTPSConnectionPool(host='exclusive103.com', port=443): Max retries exceeded with url: /2018/04/30/thousands-killed-as-israel-drops-tactical-nuclear-bomb-on-syria/ (Caused by NewConnectionError('<urllib3.connection.VerifiedHTTPSConnection object at 0x000001C9C24A3370>: Failed to establish a new connection: [Errno 11001] getaddrinfo failed')) on URL https://exclusive103.com/2018/04/30/thousands-killed-as-israel-drops-tactical-nuclear-bomb-on-syria/
2021-11-24 18:44:50,496 18172 news_content_collection ERROR Exception in getting data from url www.newslo.com/kasich-woman-not-intelligent-enough-keep-legs-closed-can-entrust-abortion-decision/
Traceback (most recent call last):
  File "C:\Users\User\Desktop\ia2\FakeNewsNet\code\news_content_collection.py", line 25, in crawl_link_article
    article.parse()
  File "C:\Users\User\AppData\Local\Packages\PythonSoftwareFoundation.Python.3.9_qbz5n2kfra8p0\LocalCache\local-packages\Python39\site-packages\newspaper\article.py", line 191, in parse
    self.throw_if_not_downloaded_verbose()
  File "C:\Users\User\AppData\Local\Packages\PythonSoftwareFoundation.Python.3.9_qbz5n2kfra8p0\LocalCache\local-packages\Python39\site-packages\newspaper\article.py", line 531, in throw_if_not_downloaded_verbose
    raise ArticleException('Article `download()` failed with %s on URL %s' %
newspaper.article.ArticleException: Article `download()` failed with HTTPSConnectionPool(host='newslo.com', port=443): Read timed out. (read timeout=7) on URL http://www.newslo.com/kasich-woman-not-intelligent-enough-keep-legs-closed-can-entrust-abortion-decision/
2021-11-24 18:44:59,960 18172 news_content_collection ERROR Exception in getting data from url www.newslo.com/kasich-woman-not-intelligent-enough-keep-legs-closed-can-entrust-abortion-decision/
Traceback (most recent call last):
  File "C:\Users\User\Desktop\ia2\FakeNewsNet\code\news_content_collection.py", line 36, in crawl_link_article
    article.parse()
  File "C:\Users\User\AppData\Local\Packages\PythonSoftwareFoundation.Python.3.9_qbz5n2kfra8p0\LocalCache\local-packages\Python39\site-packages\newspaper\article.py", line 191, in parse
    self.throw_if_not_downloaded_verbose()
  File "C:\Users\User\AppData\Local\Packages\PythonSoftwareFoundation.Python.3.9_qbz5n2kfra8p0\LocalCache\local-packages\Python39\site-packages\newspaper\article.py", line 531, in throw_if_not_downloaded_verbose
    raise ArticleException('Article `download()` failed with %s on URL %s' %
newspaper.article.ArticleException: Article `download()` failed with HTTPSConnectionPool(host='newslo.com', port=443): Read timed out. (read timeout=7) on URL https://www.newslo.com/kasich-woman-not-intelligent-enough-keep-legs-closed-can-entrust-abortion-decision/
2021-11-24 18:45:18,186 18172 news_content_collection ERROR Exception in getting data from url www.pirate4x4.com/forum/general-chit-chat/2543657-dea-just-raided-united-states-senator.html
Traceback (most recent call last):
  File "C:\Users\User\Desktop\ia2\FakeNewsNet\code\news_content_collection.py", line 25, in crawl_link_article
    article.parse()
  File "C:\Users\User\AppData\Local\Packages\PythonSoftwareFoundation.Python.3.9_qbz5n2kfra8p0\LocalCache\local-packages\Python39\site-packages\newspaper\article.py", line 191, in parse
    self.throw_if_not_downloaded_verbose()
  File "C:\Users\User\AppData\Local\Packages\PythonSoftwareFoundation.Python.3.9_qbz5n2kfra8p0\LocalCache\local-packages\Python39\site-packages\newspaper\article.py", line 531, in throw_if_not_downloaded_verbose
    raise ArticleException('Article `download()` failed with %s on URL %s' %
newspaper.article.ArticleException: Article `download()` failed with 503 Server Error: Service Temporarily Unavailable for url: https://www.pirate4x4.com/login/ on URL http://www.pirate4x4.com/forum/general-chit-chat/2543657-dea-just-raided-united-states-senator.html
2021-11-24 18:45:21,028 18172 news_content_collection ERROR Exception in getting data from url www.pirate4x4.com/forum/general-chit-chat/2543657-dea-just-raided-united-states-senator.html
Traceback (most recent call last):
  File "C:\Users\User\Desktop\ia2\FakeNewsNet\code\news_content_collection.py", line 36, in crawl_link_article
    article.parse()
  File "C:\Users\User\AppData\Local\Packages\PythonSoftwareFoundation.Python.3.9_qbz5n2kfra8p0\LocalCache\local-packages\Python39\site-packages\newspaper\article.py", line 191, in parse
    self.throw_if_not_downloaded_verbose()
  File "C:\Users\User\AppData\Local\Packages\PythonSoftwareFoundation.Python.3.9_qbz5n2kfra8p0\LocalCache\local-packages\Python39\site-packages\newspaper\article.py", line 531, in throw_if_not_downloaded_verbose
    raise ArticleException('Article `download()` failed with %s on URL %s' %
newspaper.article.ArticleException: Article `download()` failed with 503 Server Error: Service Temporarily Unavailable for url: https://www.pirate4x4.com/login/ on URL https://www.pirate4x4.com/forum/general-chit-chat/2543657-dea-just-raided-united-states-senator.html
2021-11-24 18:45:29,708 18172 news_content_collection ERROR Exception in getting data from url https://dailyworldupdate.us/2018/04/29/cnn-shocks-america-fires-journalist-who-made-fun-of-sarah-sanders-face/
Traceback (most recent call last):
  File "C:\Users\User\Desktop\ia2\FakeNewsNet\code\news_content_collection.py", line 49, in crawl_link_article
    article.parse()
  File "C:\Users\User\AppData\Local\Packages\PythonSoftwareFoundation.Python.3.9_qbz5n2kfra8p0\LocalCache\local-packages\Python39\site-packages\newspaper\article.py", line 191, in parse
    self.throw_if_not_downloaded_verbose()
  File "C:\Users\User\AppData\Local\Packages\PythonSoftwareFoundation.Python.3.9_qbz5n2kfra8p0\LocalCache\local-packages\Python39\site-packages\newspaper\article.py", line 531, in throw_if_not_downloaded_verbose
    raise ArticleException('Article `download()` failed with %s on URL %s' %
newspaper.article.ArticleException: Article `download()` failed with ('Connection aborted.', ConnectionResetError(10054, 'An existing connection was forcibly closed by the remote host', None, 10054, None)) on URL https://dailyworldupdate.us/2018/04/29/cnn-shocks-america-fires-journalist-who-made-fun-of-sarah-sanders-face/
2021-11-24 18:45:42,094 18172 news_content_collection ERROR Exception in getting data from url http://flashnewss.club/trumps-dhs-secretary-confirms-they-are-preparing-to-arrest-sanctuary-city-leaders/
Traceback (most recent call last):
  File "C:\Users\User\Desktop\ia2\FakeNewsNet\code\news_content_collection.py", line 49, in crawl_link_article
    article.parse()
  File "C:\Users\User\AppData\Local\Packages\PythonSoftwareFoundation.Python.3.9_qbz5n2kfra8p0\LocalCache\local-packages\Python39\site-packages\newspaper\article.py", line 191, in parse
    self.throw_if_not_downloaded_verbose()
  File "C:\Users\User\AppData\Local\Packages\PythonSoftwareFoundation.Python.3.9_qbz5n2kfra8p0\LocalCache\local-packages\Python39\site-packages\newspaper\article.py", line 531, in throw_if_not_downloaded_verbose
    raise ArticleException('Article `download()` failed with %s on URL %s' %
newspaper.article.ArticleException: Article `download()` failed with HTTPConnectionPool(host='flashnewss.club', port=80): Max retries exceeded with url: /trumps-dhs-secretary-confirms-they-are-preparing-to-arrest-sanctuary-city-leaders/ (Caused by NewConnectionError('<urllib3.connection.HTTPConnection object at 0x000001C9C24AFF40>: Failed to establish a new connection: [Errno 11002] getaddrinfo failed')) on URL http://flashnewss.club/trumps-dhs-secretary-confirms-they-are-preparing-to-arrest-sanctuary-city-leaders/
2021-11-24 18:45:51,978 18172 news_content_collection ERROR Exception in getting data from url http://eveningw.com/california-democrat-maxine-waters-charged-3-counts-support/
Traceback (most recent call last):
  File "C:\Users\User\Desktop\ia2\FakeNewsNet\code\news_content_collection.py", line 49, in crawl_link_article
    article.parse()
  File "C:\Users\User\AppData\Local\Packages\PythonSoftwareFoundation.Python.3.9_qbz5n2kfra8p0\LocalCache\local-packages\Python39\site-packages\newspaper\article.py", line 191, in parse
    self.throw_if_not_downloaded_verbose()
  File "C:\Users\User\AppData\Local\Packages\PythonSoftwareFoundation.Python.3.9_qbz5n2kfra8p0\LocalCache\local-packages\Python39\site-packages\newspaper\article.py", line 531, in throw_if_not_downloaded_verbose
    raise ArticleException('Article `download()` failed with %s on URL %s' %
newspaper.article.ArticleException: Article `download()` failed with HTTPConnectionPool(host='eveningw.com', port=80): Max retries exceeded with url: /california-democrat-maxine-waters-charged-3-counts-support/ (Caused by NewConnectionError('<urllib3.connection.HTTPConnection object at 0x000001C9C249FDC0>: Failed to establish a new connection: [Errno 11001] getaddrinfo failed')) on URL http://eveningw.com/california-democrat-maxine-waters-charged-3-counts-support/
2021-11-24 18:45:54,591 18172 news_content_collection ERROR Exception in getting data from url http://nrtonline.info/breaking-british-intelligence-seizes-clinton-foundation-warehouse-400-million-in-cash/
Traceback (most recent call last):
  File "C:\Users\User\Desktop\ia2\FakeNewsNet\code\news_content_collection.py", line 49, in crawl_link_article
    article.parse()
  File "C:\Users\User\AppData\Local\Packages\PythonSoftwareFoundation.Python.3.9_qbz5n2kfra8p0\LocalCache\local-packages\Python39\site-packages\newspaper\article.py", line 191, in parse
    self.throw_if_not_downloaded_verbose()
  File "C:\Users\User\AppData\Local\Packages\PythonSoftwareFoundation.Python.3.9_qbz5n2kfra8p0\LocalCache\local-packages\Python39\site-packages\newspaper\article.py", line 531, in throw_if_not_downloaded_verbose
    raise ArticleException('Article `download()` failed with %s on URL %s' %
newspaper.article.ArticleException: Article `download()` failed with HTTPConnectionPool(host='nrtonline.info', port=80): Max retries exceeded with url: /breaking-british-intelligence-seizes-clinton-foundation-warehouse-400-million-in-cash/ (Caused by NewConnectionError('<urllib3.connection.HTTPConnection object at 0x000001C9C249FD90>: Failed to establish a new connection: [Errno 11001] getaddrinfo failed')) on URL http://nrtonline.info/breaking-british-intelligence-seizes-clinton-foundation-warehouse-400-million-in-cash/
2021-11-24 18:46:05,664 18172 news_content_collection ERROR Exception in getting data from url http://hotgazette.com/rudy-giuliani/official-rudy-giuliani-officially-resigns-trumps-legal-team-on-its-last-leg/
Traceback (most recent call last):
  File "C:\Users\User\Desktop\ia2\FakeNewsNet\code\news_content_collection.py", line 49, in crawl_link_article
    article.parse()
  File "C:\Users\User\AppData\Local\Packages\PythonSoftwareFoundation.Python.3.9_qbz5n2kfra8p0\LocalCache\local-packages\Python39\site-packages\newspaper\article.py", line 191, in parse
    self.throw_if_not_downloaded_verbose()
  File "C:\Users\User\AppData\Local\Packages\PythonSoftwareFoundation.Python.3.9_qbz5n2kfra8p0\LocalCache\local-packages\Python39\site-packages\newspaper\article.py", line 531, in throw_if_not_downloaded_verbose
    raise ArticleException('Article `download()` failed with %s on URL %s' %
newspaper.article.ArticleException: Article `download()` failed with 404 Client Error: Not Found for url: http://hotgazette.com/rudy-giuliani/official-rudy-giuliani-officially-resigns-trumps-legal-team-on-its-last-leg/ on URL http://hotgazette.com/rudy-giuliani/official-rudy-giuliani-officially-resigns-trumps-legal-team-on-its-last-leg/
2021-11-24 18:46:17,468 18172 news_content_collection ERROR Exception in getting data from url https://www.nyfoxnews.co/michelle-obama-just-received-life-shattering-news-from-the-doctor/
Traceback (most recent call last):
  File "C:\Users\User\Desktop\ia2\FakeNewsNet\code\news_content_collection.py", line 49, in crawl_link_article
    article.parse()
  File "C:\Users\User\AppData\Local\Packages\PythonSoftwareFoundation.Python.3.9_qbz5n2kfra8p0\LocalCache\local-packages\Python39\site-packages\newspaper\article.py", line 191, in parse
    self.throw_if_not_downloaded_verbose()
  File "C:\Users\User\AppData\Local\Packages\PythonSoftwareFoundation.Python.3.9_qbz5n2kfra8p0\LocalCache\local-packages\Python39\site-packages\newspaper\article.py", line 531, in throw_if_not_downloaded_verbose
    raise ArticleException('Article `download()` failed with %s on URL %s' %
newspaper.article.ArticleException: Article `download()` failed with HTTPSConnectionPool(host='www.nyfoxnews.co', port=443): Max retries exceeded with url: /michelle-obama-just-received-life-shattering-news-from-the-doctor/ (Caused by NewConnectionError('<urllib3.connection.VerifiedHTTPSConnection object at 0x000001C9C24A3220>: Failed to establish a new connection: [WinError 10061] No connection could be made because the target machine actively refused it')) on URL https://www.nyfoxnews.co/michelle-obama-just-received-life-shattering-news-from-the-doctor/
2021-11-24 18:46:28,228 18172 news_content_collection ERROR Exception in getting data from url https://yournewswire.com/tens-of-thousands-of-scientists-declare-climate-change-a-hoax/
Traceback (most recent call last):
  File "C:\Users\User\Desktop\ia2\FakeNewsNet\code\news_content_collection.py", line 49, in crawl_link_article
    article.parse()
  File "C:\Users\User\AppData\Local\Packages\PythonSoftwareFoundation.Python.3.9_qbz5n2kfra8p0\LocalCache\local-packages\Python39\site-packages\newspaper\article.py", line 191, in parse
    self.throw_if_not_downloaded_verbose()
  File "C:\Users\User\AppData\Local\Packages\PythonSoftwareFoundation.Python.3.9_qbz5n2kfra8p0\LocalCache\local-packages\Python39\site-packages\newspaper\article.py", line 531, in throw_if_not_downloaded_verbose
    raise ArticleException('Article `download()` failed with %s on URL %s' %
newspaper.article.ArticleException: Article `download()` failed with 404 Client Error: Not Found for url: https://yournewswire.com/tens-of-thousands-of-scientists-declare-climate-change-a-hoax/ on URL https://yournewswire.com/tens-of-thousands-of-scientists-declare-climate-change-a-hoax/
2021-11-24 18:46:50,238 18172 news_content_collection ERROR Exception in getting data from url https://yournewswire.com/lisa-page-squeals-dnc-server-not-hacked-russia/
Traceback (most recent call last):
  File "C:\Users\User\Desktop\ia2\FakeNewsNet\code\news_content_collection.py", line 49, in crawl_link_article
    article.parse()
  File "C:\Users\User\AppData\Local\Packages\PythonSoftwareFoundation.Python.3.9_qbz5n2kfra8p0\LocalCache\local-packages\Python39\site-packages\newspaper\article.py", line 191, in parse
    self.throw_if_not_downloaded_verbose()
  File "C:\Users\User\AppData\Local\Packages\PythonSoftwareFoundation.Python.3.9_qbz5n2kfra8p0\LocalCache\local-packages\Python39\site-packages\newspaper\article.py", line 531, in throw_if_not_downloaded_verbose
    raise ArticleException('Article `download()` failed with %s on URL %s' %
newspaper.article.ArticleException: Article `download()` failed with 404 Client Error: Not Found for url: https://yournewswire.com/lisa-page-squeals-dnc-server-not-hacked-russia/ on URL https://yournewswire.com/lisa-page-squeals-dnc-server-not-hacked-russia/
2021-11-24 18:47:00,712 18172 news_content_collection ERROR Exception in getting data from url http://www.newsdonaldtrumps.com/robert-redford-says-michelle-and-barack-obama-should-get-five-years-in-prison/
Traceback (most recent call last):
  File "C:\Users\User\Desktop\ia2\FakeNewsNet\code\news_content_collection.py", line 49, in crawl_link_article
    article.parse()
  File "C:\Users\User\AppData\Local\Packages\PythonSoftwareFoundation.Python.3.9_qbz5n2kfra8p0\LocalCache\local-packages\Python39\site-packages\newspaper\article.py", line 191, in parse
    self.throw_if_not_downloaded_verbose()
  File "C:\Users\User\AppData\Local\Packages\PythonSoftwareFoundation.Python.3.9_qbz5n2kfra8p0\LocalCache\local-packages\Python39\site-packages\newspaper\article.py", line 531, in throw_if_not_downloaded_verbose
    raise ArticleException('Article `download()` failed with %s on URL %s' %
newspaper.article.ArticleException: Article `download()` failed with HTTPConnectionPool(host='www.newsdonaldtrumps.com', port=80): Max retries exceeded with url: /robert-redford-says-michelle-and-barack-obama-should-get-five-years-in-prison/ (Caused by NewConnectionError('<urllib3.connection.HTTPConnection object at 0x000001C9C249FB50>: Failed to establish a new connection: [Errno 11001] getaddrinfo failed')) on URL http://www.newsdonaldtrumps.com/robert-redford-says-michelle-and-barack-obama-should-get-five-years-in-prison/
2021-11-24 18:47:13,527 18172 news_content_collection ERROR Exception in getting data from url https://yournewswire.com/puerto-rico-mayor-fraud-disaster/
Traceback (most recent call last):
  File "C:\Users\User\Desktop\ia2\FakeNewsNet\code\news_content_collection.py", line 49, in crawl_link_article
    article.parse()
  File "C:\Users\User\AppData\Local\Packages\PythonSoftwareFoundation.Python.3.9_qbz5n2kfra8p0\LocalCache\local-packages\Python39\site-packages\newspaper\article.py", line 191, in parse
    self.throw_if_not_downloaded_verbose()
  File "C:\Users\User\AppData\Local\Packages\PythonSoftwareFoundation.Python.3.9_qbz5n2kfra8p0\LocalCache\local-packages\Python39\site-packages\newspaper\article.py", line 531, in throw_if_not_downloaded_verbose
    raise ArticleException('Article `download()` failed with %s on URL %s' %
newspaper.article.ArticleException: Article `download()` failed with 404 Client Error: Not Found for url: https://yournewswire.com/puerto-rico-mayor-fraud-disaster/ on URL https://yournewswire.com/puerto-rico-mayor-fraud-disaster/
2021-11-24 18:47:43,645 18172 news_content_collection ERROR Exception in getting data from url https://www.chicagosuntimes.live/queen-elizabeth-says-muslim-refugees-are-dividing-nationality-i-fully-agree-with-donald-trump-we-shouldvideo/
Traceback (most recent call last):
  File "C:\Users\User\Desktop\ia2\FakeNewsNet\code\news_content_collection.py", line 49, in crawl_link_article
    article.parse()
  File "C:\Users\User\AppData\Local\Packages\PythonSoftwareFoundation.Python.3.9_qbz5n2kfra8p0\LocalCache\local-packages\Python39\site-packages\newspaper\article.py", line 191, in parse
    self.throw_if_not_downloaded_verbose()
  File "C:\Users\User\AppData\Local\Packages\PythonSoftwareFoundation.Python.3.9_qbz5n2kfra8p0\LocalCache\local-packages\Python39\site-packages\newspaper\article.py", line 531, in throw_if_not_downloaded_verbose
    raise ArticleException('Article `download()` failed with %s on URL %s' %
newspaper.article.ArticleException: Article `download()` failed with HTTPSConnectionPool(host='www.chicagosuntimes.live', port=443): Max retries exceeded with url: /queen-elizabeth-says-muslim-refugees-are-dividing-nationality-i-fully-agree-with-donald-trump-we-shouldvideo/ (Caused by NewConnectionError('<urllib3.connection.VerifiedHTTPSConnection object at 0x000001C9C2C70100>: Failed to establish a new connection: [Errno 11001] getaddrinfo failed')) on URL https://www.chicagosuntimes.live/queen-elizabeth-says-muslim-refugees-are-dividing-nationality-i-fully-agree-with-donald-trump-we-shouldvideo/
2021-11-24 18:47:47,287 18172 news_content_collection ERROR Exception in getting data from url https://web.archive.org/web/20180819235451/https://www.chicagosuntimes.live/queen-elizabeth-says-muslim-refugees-are-dividing-nationality-i-fully-agree-with-donald-trump-we-shouldvideo/
Traceback (most recent call last):
  File "C:\Users\User\Desktop\ia2\FakeNewsNet\code\news_content_collection.py", line 49, in crawl_link_article
    article.parse()
  File "C:\Users\User\AppData\Local\Packages\PythonSoftwareFoundation.Python.3.9_qbz5n2kfra8p0\LocalCache\local-packages\Python39\site-packages\newspaper\article.py", line 191, in parse
    self.throw_if_not_downloaded_verbose()
  File "C:\Users\User\AppData\Local\Packages\PythonSoftwareFoundation.Python.3.9_qbz5n2kfra8p0\LocalCache\local-packages\Python39\site-packages\newspaper\article.py", line 531, in throw_if_not_downloaded_verbose
    raise ArticleException('Article `download()` failed with %s on URL %s' %
newspaper.article.ArticleException: Article `download()` failed with 404 Client Error: Not Found for url: https://web.archive.org/web/20180819235451/https://www.chicagosuntimes.live/queen-elizabeth-says-muslim-refugees-are-dividing-nationality-i-fully-agree-with-donald-trump-we-shouldvideo/ on URL https://web.archive.org/web/20180819235451/https://www.chicagosuntimes.live/queen-elizabeth-says-muslim-refugees-are-dividing-nationality-i-fully-agree-with-donald-trump-we-shouldvideo/
2021-11-24 18:47:49,321 18172 news_content_collection ERROR Exception in getting data from url https://theglobalheadlines.net/hollywood-actor-bruce-willis-trump-is-the-best-us-president-ever-anyone-who-dislikes-him-should-move-to-2/
Traceback (most recent call last):
  File "C:\Users\User\Desktop\ia2\FakeNewsNet\code\news_content_collection.py", line 49, in crawl_link_article
    article.parse()
  File "C:\Users\User\AppData\Local\Packages\PythonSoftwareFoundation.Python.3.9_qbz5n2kfra8p0\LocalCache\local-packages\Python39\site-packages\newspaper\article.py", line 191, in parse
    self.throw_if_not_downloaded_verbose()
  File "C:\Users\User\AppData\Local\Packages\PythonSoftwareFoundation.Python.3.9_qbz5n2kfra8p0\LocalCache\local-packages\Python39\site-packages\newspaper\article.py", line 531, in throw_if_not_downloaded_verbose
    raise ArticleException('Article `download()` failed with %s on URL %s' %
newspaper.article.ArticleException: Article `download()` failed with HTTPSConnectionPool(host='theglobalheadlines.net', port=443): Max retries exceeded with url: /hollywood-actor-bruce-willis-trump-is-the-best-us-president-ever-anyone-who-dislikes-him-should-move-to-2/ (Caused by NewConnectionError('<urllib3.connection.VerifiedHTTPSConnection object at 0x000001C9C2C70A90>: Failed to establish a new connection: [Errno 11001] getaddrinfo failed')) on URL https://theglobalheadlines.net/hollywood-actor-bruce-willis-trump-is-the-best-us-president-ever-anyone-who-dislikes-him-should-move-to-2/
2021-11-24 18:48:10,808 18172 news_content_collection ERROR Exception in getting data from url http://patriotcrier.com/1-6kk-0/
Traceback (most recent call last):
  File "C:\Users\User\Desktop\ia2\FakeNewsNet\code\news_content_collection.py", line 49, in crawl_link_article
    article.parse()
  File "C:\Users\User\AppData\Local\Packages\PythonSoftwareFoundation.Python.3.9_qbz5n2kfra8p0\LocalCache\local-packages\Python39\site-packages\newspaper\article.py", line 191, in parse
    self.throw_if_not_downloaded_verbose()
  File "C:\Users\User\AppData\Local\Packages\PythonSoftwareFoundation.Python.3.9_qbz5n2kfra8p0\LocalCache\local-packages\Python39\site-packages\newspaper\article.py", line 531, in throw_if_not_downloaded_verbose
    raise ArticleException('Article `download()` failed with %s on URL %s' %
newspaper.article.ArticleException: Article `download()` failed with HTTPConnectionPool(host='patriotcrier.com', port=80): Max retries exceeded with url: /1-6kk-0/ (Caused by NewConnectionError('<urllib3.connection.HTTPConnection object at 0x000001C9C2C6F100>: Failed to establish a new connection: [Errno 11002] getaddrinfo failed')) on URL http://patriotcrier.com/1-6kk-0/
2021-11-24 18:48:24,022 18172 news_content_collection ERROR Exception in getting data from url http://americannews.com/busted-nasa-accidentally-destroys-every-climate-change-advocate-exposing-massive-truth-behind-antartica/
Traceback (most recent call last):
  File "C:\Users\User\Desktop\ia2\FakeNewsNet\code\news_content_collection.py", line 49, in crawl_link_article
    article.parse()
  File "C:\Users\User\AppData\Local\Packages\PythonSoftwareFoundation.Python.3.9_qbz5n2kfra8p0\LocalCache\local-packages\Python39\site-packages\newspaper\article.py", line 191, in parse
    self.throw_if_not_downloaded_verbose()
  File "C:\Users\User\AppData\Local\Packages\PythonSoftwareFoundation.Python.3.9_qbz5n2kfra8p0\LocalCache\local-packages\Python39\site-packages\newspaper\article.py", line 531, in throw_if_not_downloaded_verbose
    raise ArticleException('Article `download()` failed with %s on URL %s' %
newspaper.article.ArticleException: Article `download()` failed with HTTPConnectionPool(host='americannews.com', port=80): Read timed out. (read timeout=7) on URL http://americannews.com/busted-nasa-accidentally-destroys-every-climate-change-advocate-exposing-massive-truth-behind-antartica/
2021-11-24 18:48:34,431 18172 news_content_collection ERROR Exception in getting data from url http://www.bluedotdaily.com/trump-police-officers-and-firefighters-make-too-much-money-hits-them-with-tax-penalty/
Traceback (most recent call last):
  File "C:\Users\User\Desktop\ia2\FakeNewsNet\code\news_content_collection.py", line 49, in crawl_link_article
    article.parse()
  File "C:\Users\User\AppData\Local\Packages\PythonSoftwareFoundation.Python.3.9_qbz5n2kfra8p0\LocalCache\local-packages\Python39\site-packages\newspaper\article.py", line 191, in parse
    self.throw_if_not_downloaded_verbose()
  File "C:\Users\User\AppData\Local\Packages\PythonSoftwareFoundation.Python.3.9_qbz5n2kfra8p0\LocalCache\local-packages\Python39\site-packages\newspaper\article.py", line 531, in throw_if_not_downloaded_verbose
    raise ArticleException('Article `download()` failed with %s on URL %s' %
newspaper.article.ArticleException: Article `download()` failed with 404 Client Error: Not Found for url: http://www.bluedotdaily.com/trump-police-officers-and-firefighters-make-too-much-money-hits-them-with-tax-penalty/ on URL http://www.bluedotdaily.com/trump-police-officers-and-firefighters-make-too-much-money-hits-them-with-tax-penalty/
2021-11-24 18:48:38,030 18172 news_content_collection ERROR Exception in getting data from url https://web.archive.org/web/20171227233221/http://www.bluedotdaily.com/trump-police-officers-and-firefighters-make-too-much-money-hits-them-with-tax-penalty/
Traceback (most recent call last):
  File "C:\Users\User\Desktop\ia2\FakeNewsNet\code\news_content_collection.py", line 49, in crawl_link_article
    article.parse()
  File "C:\Users\User\AppData\Local\Packages\PythonSoftwareFoundation.Python.3.9_qbz5n2kfra8p0\LocalCache\local-packages\Python39\site-packages\newspaper\article.py", line 191, in parse
    self.throw_if_not_downloaded_verbose()
  File "C:\Users\User\AppData\Local\Packages\PythonSoftwareFoundation.Python.3.9_qbz5n2kfra8p0\LocalCache\local-packages\Python39\site-packages\newspaper\article.py", line 531, in throw_if_not_downloaded_verbose
    raise ArticleException('Article `download()` failed with %s on URL %s' %
newspaper.article.ArticleException: Article `download()` failed with 403 Client Error: Forbidden for url: https://web.archive.org/web/20171227233221/http://www.bluedotdaily.com/trump-police-officers-and-firefighters-make-too-much-money-hits-them-with-tax-penalty/ on URL https://web.archive.org/web/20171227233221/http://www.bluedotdaily.com/trump-police-officers-and-firefighters-make-too-much-money-hits-them-with-tax-penalty/
2021-11-24 18:48:57,564 18172 news_content_collection ERROR Exception in getting data from url http://yournewswire.com/melanic-trump-exorcist-white-house/
Traceback (most recent call last):
  File "C:\Users\User\Desktop\ia2\FakeNewsNet\code\news_content_collection.py", line 49, in crawl_link_article
    article.parse()
  File "C:\Users\User\AppData\Local\Packages\PythonSoftwareFoundation.Python.3.9_qbz5n2kfra8p0\LocalCache\local-packages\Python39\site-packages\newspaper\article.py", line 191, in parse
    self.throw_if_not_downloaded_verbose()
  File "C:\Users\User\AppData\Local\Packages\PythonSoftwareFoundation.Python.3.9_qbz5n2kfra8p0\LocalCache\local-packages\Python39\site-packages\newspaper\article.py", line 531, in throw_if_not_downloaded_verbose
    raise ArticleException('Article `download()` failed with %s on URL %s' %
newspaper.article.ArticleException: Article `download()` failed with 404 Client Error: Not Found for url: http://yournewswire.com/melanic-trump-exorcist-white-house/ on URL http://yournewswire.com/melanic-trump-exorcist-white-house/
2021-11-24 18:49:11,112 18172 news_content_collection ERROR Exception in getting data from url http://maga2020.us/news/clint-eastwood-leaves-his-estate-to-the-trump-2020-campaign/
Traceback (most recent call last):
  File "C:\Users\User\Desktop\ia2\FakeNewsNet\code\news_content_collection.py", line 49, in crawl_link_article
    article.parse()
  File "C:\Users\User\AppData\Local\Packages\PythonSoftwareFoundation.Python.3.9_qbz5n2kfra8p0\LocalCache\local-packages\Python39\site-packages\newspaper\article.py", line 191, in parse
    self.throw_if_not_downloaded_verbose()
  File "C:\Users\User\AppData\Local\Packages\PythonSoftwareFoundation.Python.3.9_qbz5n2kfra8p0\LocalCache\local-packages\Python39\site-packages\newspaper\article.py", line 531, in throw_if_not_downloaded_verbose
    raise ArticleException('Article `download()` failed with %s on URL %s' %
newspaper.article.ArticleException: Article `download()` failed with HTTPConnectionPool(host='maga2020.us', port=80): Max retries exceeded with url: /news/clint-eastwood-leaves-his-estate-to-the-trump-2020-campaign/ (Caused by NewConnectionError('<urllib3.connection.HTTPConnection object at 0x000001C9C2C76790>: Failed to establish a new connection: [Errno 11001] getaddrinfo failed')) on URL http://maga2020.us/news/clint-eastwood-leaves-his-estate-to-the-trump-2020-campaign/
2021-11-24 18:49:34,600 18172 news_content_collection ERROR Exception in getting data from url https://www.tdtalliance.com/jefferson-davis-statue-replaced-obama-likeness/
Traceback (most recent call last):
  File "C:\Users\User\Desktop\ia2\FakeNewsNet\code\news_content_collection.py", line 49, in crawl_link_article
    article.parse()
  File "C:\Users\User\AppData\Local\Packages\PythonSoftwareFoundation.Python.3.9_qbz5n2kfra8p0\LocalCache\local-packages\Python39\site-packages\newspaper\article.py", line 191, in parse
    self.throw_if_not_downloaded_verbose()
  File "C:\Users\User\AppData\Local\Packages\PythonSoftwareFoundation.Python.3.9_qbz5n2kfra8p0\LocalCache\local-packages\Python39\site-packages\newspaper\article.py", line 531, in throw_if_not_downloaded_verbose
    raise ArticleException('Article `download()` failed with %s on URL %s' %
newspaper.article.ArticleException: Article `download()` failed with 404 Client Error: Not Found for url: https://tdtalliance.com/jefferson-davis-statue-replaced-obama-likeness/ on URL https://www.tdtalliance.com/jefferson-davis-statue-replaced-obama-likeness/
2021-11-24 18:50:03,487 18172 news_content_collection ERROR Exception in getting data from url mainerepublicemailalert.com/2017/03/24/breaking-autopsy-results-from-vince-fosters-exhumed-body-cause-of-death-to-be-changed/
Traceback (most recent call last):
  File "C:\Users\User\Desktop\ia2\FakeNewsNet\code\news_content_collection.py", line 25, in crawl_link_article
    article.parse()
  File "C:\Users\User\AppData\Local\Packages\PythonSoftwareFoundation.Python.3.9_qbz5n2kfra8p0\LocalCache\local-packages\Python39\site-packages\newspaper\article.py", line 191, in parse
    self.throw_if_not_downloaded_verbose()
  File "C:\Users\User\AppData\Local\Packages\PythonSoftwareFoundation.Python.3.9_qbz5n2kfra8p0\LocalCache\local-packages\Python39\site-packages\newspaper\article.py", line 531, in throw_if_not_downloaded_verbose
    raise ArticleException('Article `download()` failed with %s on URL %s' %
newspaper.article.ArticleException: Article `download()` failed with 404 Client Error: Not Found for url: https://mainerepublicemailalert.com/2017/03/24/breaking-autopsy-results-from-vince-fosters-exhumed-body-cause-of-death-to-be-changed/ on URL http://mainerepublicemailalert.com/2017/03/24/breaking-autopsy-results-from-vince-fosters-exhumed-body-cause-of-death-to-be-changed/
2021-11-24 18:50:06,473 18172 news_content_collection ERROR Exception in getting data from url mainerepublicemailalert.com/2017/03/24/breaking-autopsy-results-from-vince-fosters-exhumed-body-cause-of-death-to-be-changed/
Traceback (most recent call last):
  File "C:\Users\User\Desktop\ia2\FakeNewsNet\code\news_content_collection.py", line 36, in crawl_link_article
    article.parse()
  File "C:\Users\User\AppData\Local\Packages\PythonSoftwareFoundation.Python.3.9_qbz5n2kfra8p0\LocalCache\local-packages\Python39\site-packages\newspaper\article.py", line 191, in parse
    self.throw_if_not_downloaded_verbose()
  File "C:\Users\User\AppData\Local\Packages\PythonSoftwareFoundation.Python.3.9_qbz5n2kfra8p0\LocalCache\local-packages\Python39\site-packages\newspaper\article.py", line 531, in throw_if_not_downloaded_verbose
    raise ArticleException('Article `download()` failed with %s on URL %s' %
newspaper.article.ArticleException: Article `download()` failed with 404 Client Error: Not Found for url: https://mainerepublicemailalert.com/2017/03/24/breaking-autopsy-results-from-vince-fosters-exhumed-body-cause-of-death-to-be-changed/ on URL https://mainerepublicemailalert.com/2017/03/24/breaking-autopsy-results-from-vince-fosters-exhumed-body-cause-of-death-to-be-changed/
2021-11-24 18:50:11,544 18172 news_content_collection ERROR Exception in getting data from url https://web.archive.org/web/20170325151856/http://mainerepublicemailalert.com/2017/03/24/breaking-autopsy-results-from-vince-fosters-exhumed-body-cause-of-death-to-be-changed/
Traceback (most recent call last):
  File "C:\Users\User\Desktop\ia2\FakeNewsNet\code\news_content_collection.py", line 49, in crawl_link_article
    article.parse()
  File "C:\Users\User\AppData\Local\Packages\PythonSoftwareFoundation.Python.3.9_qbz5n2kfra8p0\LocalCache\local-packages\Python39\site-packages\newspaper\article.py", line 191, in parse
    self.throw_if_not_downloaded_verbose()
  File "C:\Users\User\AppData\Local\Packages\PythonSoftwareFoundation.Python.3.9_qbz5n2kfra8p0\LocalCache\local-packages\Python39\site-packages\newspaper\article.py", line 531, in throw_if_not_downloaded_verbose
    raise ArticleException('Article `download()` failed with %s on URL %s' %
newspaper.article.ArticleException: Article `download()` failed with 404 Client Error: Not Found for url: https://web.archive.org/web/20210505123012/https://mainerepublicemailalert.com/2017/03/24/breaking-autopsy-results-from-vince-fosters-exhumed-body-cause-of-death-to-be-changed/ on URL https://web.archive.org/web/20170325151856/http://mainerepublicemailalert.com/2017/03/24/breaking-autopsy-results-from-vince-fosters-exhumed-body-cause-of-death-to-be-changed/
2021-11-24 18:50:20,857 18172 news_content_collection ERROR Exception in getting data from url www.usacarry.com/forums/politics-and-news/62210-hrc-caught-tape-laughing-about-irma-wiping-out-all-those-florida-hillbillies.html
Traceback (most recent call last):
  File "C:\Users\User\Desktop\ia2\FakeNewsNet\code\news_content_collection.py", line 25, in crawl_link_article
    article.parse()
  File "C:\Users\User\AppData\Local\Packages\PythonSoftwareFoundation.Python.3.9_qbz5n2kfra8p0\LocalCache\local-packages\Python39\site-packages\newspaper\article.py", line 191, in parse
    self.throw_if_not_downloaded_verbose()
  File "C:\Users\User\AppData\Local\Packages\PythonSoftwareFoundation.Python.3.9_qbz5n2kfra8p0\LocalCache\local-packages\Python39\site-packages\newspaper\article.py", line 531, in throw_if_not_downloaded_verbose
    raise ArticleException('Article `download()` failed with %s on URL %s' %
newspaper.article.ArticleException: Article `download()` failed with 403 Client Error: Forbidden for url: https://forums.usacarry.com/politics-and-news/62210-hrc-caught-tape-laughing-about-irma-wiping-out-all-those-florida-hillbillies.html on URL http://www.usacarry.com/forums/politics-and-news/62210-hrc-caught-tape-laughing-about-irma-wiping-out-all-those-florida-hillbillies.html
2021-11-24 18:50:23,611 18172 news_content_collection ERROR Exception in getting data from url www.usacarry.com/forums/politics-and-news/62210-hrc-caught-tape-laughing-about-irma-wiping-out-all-those-florida-hillbillies.html
Traceback (most recent call last):
  File "C:\Users\User\Desktop\ia2\FakeNewsNet\code\news_content_collection.py", line 36, in crawl_link_article
    article.parse()
  File "C:\Users\User\AppData\Local\Packages\PythonSoftwareFoundation.Python.3.9_qbz5n2kfra8p0\LocalCache\local-packages\Python39\site-packages\newspaper\article.py", line 191, in parse
    self.throw_if_not_downloaded_verbose()
  File "C:\Users\User\AppData\Local\Packages\PythonSoftwareFoundation.Python.3.9_qbz5n2kfra8p0\LocalCache\local-packages\Python39\site-packages\newspaper\article.py", line 531, in throw_if_not_downloaded_verbose
    raise ArticleException('Article `download()` failed with %s on URL %s' %
newspaper.article.ArticleException: Article `download()` failed with 403 Client Error: Forbidden for url: https://forums.usacarry.com/politics-and-news/62210-hrc-caught-tape-laughing-about-irma-wiping-out-all-those-florida-hillbillies.html on URL https://www.usacarry.com/forums/politics-and-news/62210-hrc-caught-tape-laughing-about-irma-wiping-out-all-those-florida-hillbillies.html
2021-11-24 18:50:40,008 18172 news_content_collection ERROR Exception in getting data from url http://usamirrornews.com/roy-moores-accuser-arrested-and-charged-with-falsification/
Traceback (most recent call last):
  File "C:\Users\User\Desktop\ia2\FakeNewsNet\code\news_content_collection.py", line 49, in crawl_link_article
    article.parse()
  File "C:\Users\User\AppData\Local\Packages\PythonSoftwareFoundation.Python.3.9_qbz5n2kfra8p0\LocalCache\local-packages\Python39\site-packages\newspaper\article.py", line 191, in parse
    self.throw_if_not_downloaded_verbose()
  File "C:\Users\User\AppData\Local\Packages\PythonSoftwareFoundation.Python.3.9_qbz5n2kfra8p0\LocalCache\local-packages\Python39\site-packages\newspaper\article.py", line 531, in throw_if_not_downloaded_verbose
    raise ArticleException('Article `download()` failed with %s on URL %s' %
newspaper.article.ArticleException: Article `download()` failed with HTTPConnectionPool(host='usamirrornews.com', port=80): Max retries exceeded with url: /roy-moores-accuser-arrested-and-charged-with-falsification/ (Caused by ConnectTimeoutError(<urllib3.connection.HTTPConnection object at 0x000001C9C2C7D1C0>, 'Connection to usamirrornews.com timed out. (connect timeout=7)')) on URL http://usamirrornews.com/roy-moores-accuser-arrested-and-charged-with-falsification/
2021-11-24 18:51:10,107 18172 news_content_collection ERROR Exception in getting data from url http://wkrg.com/2017/11/14/curious-robocall-seeks-damaging-information-on-moore/
Traceback (most recent call last):
  File "C:\Users\User\Desktop\ia2\FakeNewsNet\code\news_content_collection.py", line 49, in crawl_link_article
    article.parse()
  File "C:\Users\User\AppData\Local\Packages\PythonSoftwareFoundation.Python.3.9_qbz5n2kfra8p0\LocalCache\local-packages\Python39\site-packages\newspaper\article.py", line 191, in parse
    self.throw_if_not_downloaded_verbose()
  File "C:\Users\User\AppData\Local\Packages\PythonSoftwareFoundation.Python.3.9_qbz5n2kfra8p0\LocalCache\local-packages\Python39\site-packages\newspaper\article.py", line 531, in throw_if_not_downloaded_verbose
    raise ArticleException('Article `download()` failed with %s on URL %s' %
newspaper.article.ArticleException: Article `download()` failed with 404 Client Error: Not Found for url: https://www.wkrg.com/2017/11/14/curious-robocall-seeks-damaging-information-on-moore/ on URL http://wkrg.com/2017/11/14/curious-robocall-seeks-damaging-information-on-moore/
2021-11-24 18:51:16,500 18172 news_content_collection ERROR Exception in getting data from url https://www.viralwdc.site/national-guard-storms-mexico-border-makes-game-changing-impact-in-just-30-days/
Traceback (most recent call last):
  File "C:\Users\User\Desktop\ia2\FakeNewsNet\code\news_content_collection.py", line 49, in crawl_link_article
    article.parse()
  File "C:\Users\User\AppData\Local\Packages\PythonSoftwareFoundation.Python.3.9_qbz5n2kfra8p0\LocalCache\local-packages\Python39\site-packages\newspaper\article.py", line 191, in parse
    self.throw_if_not_downloaded_verbose()
  File "C:\Users\User\AppData\Local\Packages\PythonSoftwareFoundation.Python.3.9_qbz5n2kfra8p0\LocalCache\local-packages\Python39\site-packages\newspaper\article.py", line 531, in throw_if_not_downloaded_verbose
    raise ArticleException('Article `download()` failed with %s on URL %s' %
newspaper.article.ArticleException: Article `download()` failed with HTTPSConnectionPool(host='www.viralwdc.site', port=443): Max retries exceeded with url: /national-guard-storms-mexico-border-makes-game-changing-impact-in-just-30-days/ (Caused by NewConnectionError('<urllib3.connection.VerifiedHTTPSConnection object at 0x000001C9C2C7BFD0>: Failed to establish a new connection: [Errno 11001] getaddrinfo failed')) on URL https://www.viralwdc.site/national-guard-storms-mexico-border-makes-game-changing-impact-in-just-30-days/
2021-11-24 18:51:31,609 18172 news_content_collection ERROR Exception in getting data from url http://flashnewss.club/breaking-shep-smith-to-be-canned-because-he-cant-control-his-hate-for-donald-trump/
Traceback (most recent call last):
  File "C:\Users\User\Desktop\ia2\FakeNewsNet\code\news_content_collection.py", line 49, in crawl_link_article
    article.parse()
  File "C:\Users\User\AppData\Local\Packages\PythonSoftwareFoundation.Python.3.9_qbz5n2kfra8p0\LocalCache\local-packages\Python39\site-packages\newspaper\article.py", line 191, in parse
    self.throw_if_not_downloaded_verbose()
  File "C:\Users\User\AppData\Local\Packages\PythonSoftwareFoundation.Python.3.9_qbz5n2kfra8p0\LocalCache\local-packages\Python39\site-packages\newspaper\article.py", line 531, in throw_if_not_downloaded_verbose
    raise ArticleException('Article `download()` failed with %s on URL %s' %
newspaper.article.ArticleException: Article `download()` failed with HTTPConnectionPool(host='flashnewss.club', port=80): Max retries exceeded with url: /breaking-shep-smith-to-be-canned-because-he-cant-control-his-hate-for-donald-trump/ (Caused by NewConnectionError('<urllib3.connection.HTTPConnection object at 0x000001C9C2C7B460>: Failed to establish a new connection: [Errno 11002] getaddrinfo failed')) on URL http://flashnewss.club/breaking-shep-smith-to-be-canned-because-he-cant-control-his-hate-for-donald-trump/
2021-11-24 18:51:56,600 18172 news_content_collection ERROR Exception in getting data from url http://eveningw.com/breaking-woman-says-offered-big-money-washington-post-accuse-roy-moore-misconduct/
Traceback (most recent call last):
  File "C:\Users\User\Desktop\ia2\FakeNewsNet\code\news_content_collection.py", line 49, in crawl_link_article
    article.parse()
  File "C:\Users\User\AppData\Local\Packages\PythonSoftwareFoundation.Python.3.9_qbz5n2kfra8p0\LocalCache\local-packages\Python39\site-packages\newspaper\article.py", line 191, in parse
    self.throw_if_not_downloaded_verbose()
  File "C:\Users\User\AppData\Local\Packages\PythonSoftwareFoundation.Python.3.9_qbz5n2kfra8p0\LocalCache\local-packages\Python39\site-packages\newspaper\article.py", line 531, in throw_if_not_downloaded_verbose
    raise ArticleException('Article `download()` failed with %s on URL %s' %
newspaper.article.ArticleException: Article `download()` failed with HTTPConnectionPool(host='eveningw.com', port=80): Max retries exceeded with url: /breaking-woman-says-offered-big-money-washington-post-accuse-roy-moore-misconduct/ (Caused by NewConnectionError('<urllib3.connection.HTTPConnection object at 0x000001C9C2C70D30>: Failed to establish a new connection: [Errno 11001] getaddrinfo failed')) on URL http://eveningw.com/breaking-woman-says-offered-big-money-washington-post-accuse-roy-moore-misconduct/
2021-11-24 18:52:03,735 18172 news_content_collection ERROR Exception in getting data from url https://www.conservativestories.com/2018/05/21/just-john-kerry-facing-prison/
Traceback (most recent call last):
  File "C:\Users\User\Desktop\ia2\FakeNewsNet\code\news_content_collection.py", line 49, in crawl_link_article
    article.parse()
  File "C:\Users\User\AppData\Local\Packages\PythonSoftwareFoundation.Python.3.9_qbz5n2kfra8p0\LocalCache\local-packages\Python39\site-packages\newspaper\article.py", line 191, in parse
    self.throw_if_not_downloaded_verbose()
  File "C:\Users\User\AppData\Local\Packages\PythonSoftwareFoundation.Python.3.9_qbz5n2kfra8p0\LocalCache\local-packages\Python39\site-packages\newspaper\article.py", line 531, in throw_if_not_downloaded_verbose
    raise ArticleException('Article `download()` failed with %s on URL %s' %
newspaper.article.ArticleException: Article `download()` failed with 404 Client Error: Not Found for url: https://www.conservativestories.com/2018/05/21/just-john-kerry-facing-prison/ on URL https://www.conservativestories.com/2018/05/21/just-john-kerry-facing-prison/
2021-11-24 18:52:25,090 18172 news_content_collection ERROR Exception in getting data from url http://realtimepolitics.com/2018/05/06/melania-hit-donald-trump/
Traceback (most recent call last):
  File "C:\Users\User\Desktop\ia2\FakeNewsNet\code\news_content_collection.py", line 49, in crawl_link_article
    article.parse()
  File "C:\Users\User\AppData\Local\Packages\PythonSoftwareFoundation.Python.3.9_qbz5n2kfra8p0\LocalCache\local-packages\Python39\site-packages\newspaper\article.py", line 191, in parse
    self.throw_if_not_downloaded_verbose()
  File "C:\Users\User\AppData\Local\Packages\PythonSoftwareFoundation.Python.3.9_qbz5n2kfra8p0\LocalCache\local-packages\Python39\site-packages\newspaper\article.py", line 531, in throw_if_not_downloaded_verbose
    raise ArticleException('Article `download()` failed with %s on URL %s' %
newspaper.article.ArticleException: Article `download()` failed with HTTPConnectionPool(host='realtimepolitics.com', port=80): Max retries exceeded with url: /2018/05/06/melania-hit-donald-trump/ (Caused by ConnectTimeoutError(<urllib3.connection.HTTPConnection object at 0x000001C9C2C70190>, 'Connection to realtimepolitics.com timed out. (connect timeout=7)')) on URL http://realtimepolitics.com/2018/05/06/melania-hit-donald-trump/
2021-11-24 18:52:29,424 18172 news_content_collection ERROR Exception in getting data from url https://web.archive.org/web/20180512222117/http://realtimepolitics.com:80/2018/05/06/melania-hit-donald-trump/
Traceback (most recent call last):
  File "C:\Users\User\Desktop\ia2\FakeNewsNet\code\news_content_collection.py", line 49, in crawl_link_article
    article.parse()
  File "C:\Users\User\AppData\Local\Packages\PythonSoftwareFoundation.Python.3.9_qbz5n2kfra8p0\LocalCache\local-packages\Python39\site-packages\newspaper\article.py", line 191, in parse
    self.throw_if_not_downloaded_verbose()
  File "C:\Users\User\AppData\Local\Packages\PythonSoftwareFoundation.Python.3.9_qbz5n2kfra8p0\LocalCache\local-packages\Python39\site-packages\newspaper\article.py", line 531, in throw_if_not_downloaded_verbose
    raise ArticleException('Article `download()` failed with %s on URL %s' %
newspaper.article.ArticleException: Article `download()` failed with 403 Client Error: Forbidden for url: https://web.archive.org/web/20180512222117/http://realtimepolitics.com:80/2018/05/06/melania-hit-donald-trump/ on URL https://web.archive.org/web/20180512222117/http://realtimepolitics.com:80/2018/05/06/melania-hit-donald-trump/
2021-11-24 18:52:38,607 18172 news_content_collection ERROR Exception in getting data from url https://portalstate.com/index.php/2017/05/08/obama-canceled-it-trump-reinstated-it-a-very-sacred-day-is-back/
Traceback (most recent call last):
  File "C:\Users\User\Desktop\ia2\FakeNewsNet\code\news_content_collection.py", line 49, in crawl_link_article
    article.parse()
  File "C:\Users\User\AppData\Local\Packages\PythonSoftwareFoundation.Python.3.9_qbz5n2kfra8p0\LocalCache\local-packages\Python39\site-packages\newspaper\article.py", line 191, in parse
    self.throw_if_not_downloaded_verbose()
  File "C:\Users\User\AppData\Local\Packages\PythonSoftwareFoundation.Python.3.9_qbz5n2kfra8p0\LocalCache\local-packages\Python39\site-packages\newspaper\article.py", line 531, in throw_if_not_downloaded_verbose
    raise ArticleException('Article `download()` failed with %s on URL %s' %
newspaper.article.ArticleException: Article `download()` failed with HTTPSConnectionPool(host='portalstate.com', port=443): Max retries exceeded with url: /index.php/2017/05/08/obama-canceled-it-trump-reinstated-it-a-very-sacred-day-is-back/ (Caused by ConnectTimeoutError(<urllib3.connection.VerifiedHTTPSConnection object at 0x000001C9C2C7BA60>, 'Connection to portalstate.com timed out. (connect timeout=7)')) on URL https://portalstate.com/index.php/2017/05/08/obama-canceled-it-trump-reinstated-it-a-very-sacred-day-is-back/
2021-11-24 18:52:59,530 18172 news_content_collection ERROR Exception in getting data from url http://uspostman.com/2017/03/nbc-just-fired-megyn-kelly-new-show-begins/
Traceback (most recent call last):
  File "C:\Users\User\Desktop\ia2\FakeNewsNet\code\news_content_collection.py", line 49, in crawl_link_article
    article.parse()
  File "C:\Users\User\AppData\Local\Packages\PythonSoftwareFoundation.Python.3.9_qbz5n2kfra8p0\LocalCache\local-packages\Python39\site-packages\newspaper\article.py", line 191, in parse
    self.throw_if_not_downloaded_verbose()
  File "C:\Users\User\AppData\Local\Packages\PythonSoftwareFoundation.Python.3.9_qbz5n2kfra8p0\LocalCache\local-packages\Python39\site-packages\newspaper\article.py", line 531, in throw_if_not_downloaded_verbose
    raise ArticleException('Article `download()` failed with %s on URL %s' %
newspaper.article.ArticleException: Article `download()` failed with HTTPConnectionPool(host='uspostman.com', port=80): Read timed out. (read timeout=7) on URL http://uspostman.com/2017/03/nbc-just-fired-megyn-kelly-new-show-begins/
2021-11-24 18:53:34,739 18172 news_content_collection ERROR Exception in getting data from url http://majorthoughts.com/chines-restaurant-in-coral-spring-florida-got-busted-for-selling-dog-meat-as-special-menu/
Traceback (most recent call last):
  File "C:\Users\User\Desktop\ia2\FakeNewsNet\code\news_content_collection.py", line 49, in crawl_link_article
    article.parse()
  File "C:\Users\User\AppData\Local\Packages\PythonSoftwareFoundation.Python.3.9_qbz5n2kfra8p0\LocalCache\local-packages\Python39\site-packages\newspaper\article.py", line 191, in parse
    self.throw_if_not_downloaded_verbose()
  File "C:\Users\User\AppData\Local\Packages\PythonSoftwareFoundation.Python.3.9_qbz5n2kfra8p0\LocalCache\local-packages\Python39\site-packages\newspaper\article.py", line 531, in throw_if_not_downloaded_verbose
    raise ArticleException('Article `download()` failed with %s on URL %s' %
newspaper.article.ArticleException: Article `download()` failed with HTTPConnectionPool(host='majorthoughts.com', port=80): Max retries exceeded with url: /chines-restaurant-in-coral-spring-florida-got-busted-for-selling-dog-meat-as-special-menu/ (Caused by NewConnectionError('<urllib3.connection.HTTPConnection object at 0x000001C9C2C70520>: Failed to establish a new connection: [Errno 11001] getaddrinfo failed')) on URL http://majorthoughts.com/chines-restaurant-in-coral-spring-florida-got-busted-for-selling-dog-meat-as-special-menu/
2021-11-24 18:53:49,141 18172 news_content_collection ERROR Exception in getting data from url https://yournewswire.com/bill-gates-doctor-vaccinate/
Traceback (most recent call last):
  File "C:\Users\User\Desktop\ia2\FakeNewsNet\code\news_content_collection.py", line 49, in crawl_link_article
    article.parse()
  File "C:\Users\User\AppData\Local\Packages\PythonSoftwareFoundation.Python.3.9_qbz5n2kfra8p0\LocalCache\local-packages\Python39\site-packages\newspaper\article.py", line 191, in parse
    self.throw_if_not_downloaded_verbose()
  File "C:\Users\User\AppData\Local\Packages\PythonSoftwareFoundation.Python.3.9_qbz5n2kfra8p0\LocalCache\local-packages\Python39\site-packages\newspaper\article.py", line 531, in throw_if_not_downloaded_verbose
    raise ArticleException('Article `download()` failed with %s on URL %s' %
newspaper.article.ArticleException: Article `download()` failed with 404 Client Error: Not Found for url: https://yournewswire.com/bill-gates-doctor-vaccinate/ on URL https://yournewswire.com/bill-gates-doctor-vaccinate/
2021-11-24 18:54:18,460 18172 news_content_collection ERROR Exception in getting data from url http://americannews.com/25127-2/
Traceback (most recent call last):
  File "C:\Users\User\Desktop\ia2\FakeNewsNet\code\news_content_collection.py", line 49, in crawl_link_article
    article.parse()
  File "C:\Users\User\AppData\Local\Packages\PythonSoftwareFoundation.Python.3.9_qbz5n2kfra8p0\LocalCache\local-packages\Python39\site-packages\newspaper\article.py", line 191, in parse
    self.throw_if_not_downloaded_verbose()
  File "C:\Users\User\AppData\Local\Packages\PythonSoftwareFoundation.Python.3.9_qbz5n2kfra8p0\LocalCache\local-packages\Python39\site-packages\newspaper\article.py", line 531, in throw_if_not_downloaded_verbose
    raise ArticleException('Article `download()` failed with %s on URL %s' %
newspaper.article.ArticleException: Article `download()` failed with HTTPConnectionPool(host='americannews.com', port=80): Read timed out. (read timeout=7) on URL http://americannews.com/25127-2/
2021-11-24 18:54:24,919 18172 news_content_collection ERROR Exception in getting data from url http://politicsdepot.com/2018/02/28/kushner-and-wife-ivanka-trump-were-tossed-out-of-the-white-house/
Traceback (most recent call last):
  File "C:\Users\User\Desktop\ia2\FakeNewsNet\code\news_content_collection.py", line 49, in crawl_link_article
    article.parse()
  File "C:\Users\User\AppData\Local\Packages\PythonSoftwareFoundation.Python.3.9_qbz5n2kfra8p0\LocalCache\local-packages\Python39\site-packages\newspaper\article.py", line 191, in parse
    self.throw_if_not_downloaded_verbose()
  File "C:\Users\User\AppData\Local\Packages\PythonSoftwareFoundation.Python.3.9_qbz5n2kfra8p0\LocalCache\local-packages\Python39\site-packages\newspaper\article.py", line 531, in throw_if_not_downloaded_verbose
    raise ArticleException('Article `download()` failed with %s on URL %s' %
newspaper.article.ArticleException: Article `download()` failed with 404 Client Error: Not Found for url: http://politicsdepot.com/2018/02/28/kushner-and-wife-ivanka-trump-were-tossed-out-of-the-white-house/ on URL http://politicsdepot.com/2018/02/28/kushner-and-wife-ivanka-trump-were-tossed-out-of-the-white-house/
2021-11-24 18:54:38,013 18172 news_content_collection ERROR Exception in getting data from url https://www.viraltruthwire.com/obama-secretly-flees-us-leaves-stunning-evidence-behind/
Traceback (most recent call last):
  File "C:\Users\User\Desktop\ia2\FakeNewsNet\code\news_content_collection.py", line 49, in crawl_link_article
    article.parse()
  File "C:\Users\User\AppData\Local\Packages\PythonSoftwareFoundation.Python.3.9_qbz5n2kfra8p0\LocalCache\local-packages\Python39\site-packages\newspaper\article.py", line 191, in parse
    self.throw_if_not_downloaded_verbose()
  File "C:\Users\User\AppData\Local\Packages\PythonSoftwareFoundation.Python.3.9_qbz5n2kfra8p0\LocalCache\local-packages\Python39\site-packages\newspaper\article.py", line 531, in throw_if_not_downloaded_verbose
    raise ArticleException('Article `download()` failed with %s on URL %s' %
newspaper.article.ArticleException: Article `download()` failed with HTTPSConnectionPool(host='www.viraltruthwire.com', port=443): Max retries exceeded with url: /obama-secretly-flees-us-leaves-stunning-evidence-behind/ (Caused by NewConnectionError('<urllib3.connection.VerifiedHTTPSConnection object at 0x000001C9C2C79220>: Failed to establish a new connection: [Errno 11001] getaddrinfo failed')) on URL https://www.viraltruthwire.com/obama-secretly-flees-us-leaves-stunning-evidence-behind/
2021-11-24 18:54:50,031 18172 news_content_collection ERROR Exception in getting data from url http://politifeed.net/news/abc-news-joins-obama-to-ban-american-flag-lapel-pins-heres-what-you-need-to-know
Traceback (most recent call last):
  File "C:\Users\User\Desktop\ia2\FakeNewsNet\code\news_content_collection.py", line 49, in crawl_link_article
    article.parse()
  File "C:\Users\User\AppData\Local\Packages\PythonSoftwareFoundation.Python.3.9_qbz5n2kfra8p0\LocalCache\local-packages\Python39\site-packages\newspaper\article.py", line 191, in parse
    self.throw_if_not_downloaded_verbose()
  File "C:\Users\User\AppData\Local\Packages\PythonSoftwareFoundation.Python.3.9_qbz5n2kfra8p0\LocalCache\local-packages\Python39\site-packages\newspaper\article.py", line 531, in throw_if_not_downloaded_verbose
    raise ArticleException('Article `download()` failed with %s on URL %s' %
newspaper.article.ArticleException: Article `download()` failed with 404 Client Error: Not Found for url: http://politifeed.net/news/abc-news-joins-obama-to-ban-american-flag-lapel-pins-heres-what-you-need-to-know on URL http://politifeed.net/news/abc-news-joins-obama-to-ban-american-flag-lapel-pins-heres-what-you-need-to-know
2021-11-24 18:55:08,375 18172 news_content_collection ERROR Exception in getting data from url http://dailyfeed.news/flight-crew-takes-a-knee-and-walks-off-leaving-new-orleans-saints-stranded-on-runway/
Traceback (most recent call last):
  File "C:\Users\User\Desktop\ia2\FakeNewsNet\code\news_content_collection.py", line 49, in crawl_link_article
    article.parse()
  File "C:\Users\User\AppData\Local\Packages\PythonSoftwareFoundation.Python.3.9_qbz5n2kfra8p0\LocalCache\local-packages\Python39\site-packages\newspaper\article.py", line 191, in parse
    self.throw_if_not_downloaded_verbose()
  File "C:\Users\User\AppData\Local\Packages\PythonSoftwareFoundation.Python.3.9_qbz5n2kfra8p0\LocalCache\local-packages\Python39\site-packages\newspaper\article.py", line 531, in throw_if_not_downloaded_verbose
    raise ArticleException('Article `download()` failed with %s on URL %s' %
newspaper.article.ArticleException: Article `download()` failed with 404 Client Error: Not Found for url: https://cde.news/newsfeed/flight-crew-takes-a-knee-and-walks-off-leaving-new-orleans-saints-stranded-on-runway on URL http://dailyfeed.news/flight-crew-takes-a-knee-and-walks-off-leaving-new-orleans-saints-stranded-on-runway/
2021-11-24 18:55:14,598 18172 news_content_collection ERROR Exception in getting data from url what-you-missed.com/floyd-mayweather-jr-donates-a-whopping-sum-of-money-to-houston-after-hurricane/
Traceback (most recent call last):
  File "C:\Users\User\Desktop\ia2\FakeNewsNet\code\news_content_collection.py", line 25, in crawl_link_article
    article.parse()
  File "C:\Users\User\AppData\Local\Packages\PythonSoftwareFoundation.Python.3.9_qbz5n2kfra8p0\LocalCache\local-packages\Python39\site-packages\newspaper\article.py", line 191, in parse
    self.throw_if_not_downloaded_verbose()
  File "C:\Users\User\AppData\Local\Packages\PythonSoftwareFoundation.Python.3.9_qbz5n2kfra8p0\LocalCache\local-packages\Python39\site-packages\newspaper\article.py", line 531, in throw_if_not_downloaded_verbose
    raise ArticleException('Article `download()` failed with %s on URL %s' %
newspaper.article.ArticleException: Article `download()` failed with HTTPConnectionPool(host='what-you-missed.com', port=80): Max retries exceeded with url: /floyd-mayweather-jr-donates-a-whopping-sum-of-money-to-houston-after-hurricane/ (Caused by NewConnectionError('<urllib3.connection.HTTPConnection object at 0x000001C9C2C79280>: Failed to establish a new connection: [Errno 11001] getaddrinfo failed')) on URL http://what-you-missed.com/floyd-mayweather-jr-donates-a-whopping-sum-of-money-to-houston-after-hurricane/
2021-11-24 18:55:16,747 18172 news_content_collection ERROR Exception in getting data from url what-you-missed.com/floyd-mayweather-jr-donates-a-whopping-sum-of-money-to-houston-after-hurricane/
Traceback (most recent call last):
  File "C:\Users\User\Desktop\ia2\FakeNewsNet\code\news_content_collection.py", line 36, in crawl_link_article
    article.parse()
  File "C:\Users\User\AppData\Local\Packages\PythonSoftwareFoundation.Python.3.9_qbz5n2kfra8p0\LocalCache\local-packages\Python39\site-packages\newspaper\article.py", line 191, in parse
    self.throw_if_not_downloaded_verbose()
  File "C:\Users\User\AppData\Local\Packages\PythonSoftwareFoundation.Python.3.9_qbz5n2kfra8p0\LocalCache\local-packages\Python39\site-packages\newspaper\article.py", line 531, in throw_if_not_downloaded_verbose
    raise ArticleException('Article `download()` failed with %s on URL %s' %
newspaper.article.ArticleException: Article `download()` failed with HTTPSConnectionPool(host='what-you-missed.com', port=443): Max retries exceeded with url: /floyd-mayweather-jr-donates-a-whopping-sum-of-money-to-houston-after-hurricane/ (Caused by NewConnectionError('<urllib3.connection.VerifiedHTTPSConnection object at 0x000001C9C2C79280>: Failed to establish a new connection: [Errno 11001] getaddrinfo failed')) on URL https://what-you-missed.com/floyd-mayweather-jr-donates-a-whopping-sum-of-money-to-houston-after-hurricane/
2021-11-24 18:55:30,376 18172 news_content_collection ERROR Exception in getting data from url www.usacarry.com/forums/politics-and-news/63339-chuck-schumer-s-steamy-affair-high-school-cheerleader-confirmed.html
Traceback (most recent call last):
  File "C:\Users\User\Desktop\ia2\FakeNewsNet\code\news_content_collection.py", line 25, in crawl_link_article
    article.parse()
  File "C:\Users\User\AppData\Local\Packages\PythonSoftwareFoundation.Python.3.9_qbz5n2kfra8p0\LocalCache\local-packages\Python39\site-packages\newspaper\article.py", line 191, in parse
    self.throw_if_not_downloaded_verbose()
  File "C:\Users\User\AppData\Local\Packages\PythonSoftwareFoundation.Python.3.9_qbz5n2kfra8p0\LocalCache\local-packages\Python39\site-packages\newspaper\article.py", line 531, in throw_if_not_downloaded_verbose
    raise ArticleException('Article `download()` failed with %s on URL %s' %
newspaper.article.ArticleException: Article `download()` failed with 403 Client Error: Forbidden for url: https://forums.usacarry.com/politics-and-news/63339-chuck-schumer-s-steamy-affair-high-school-cheerleader-confirmed.html on URL http://www.usacarry.com/forums/politics-and-news/63339-chuck-schumer-s-steamy-affair-high-school-cheerleader-confirmed.html
2021-11-24 18:55:33,088 18172 news_content_collection ERROR Exception in getting data from url www.usacarry.com/forums/politics-and-news/63339-chuck-schumer-s-steamy-affair-high-school-cheerleader-confirmed.html
Traceback (most recent call last):
  File "C:\Users\User\Desktop\ia2\FakeNewsNet\code\news_content_collection.py", line 36, in crawl_link_article
    article.parse()
  File "C:\Users\User\AppData\Local\Packages\PythonSoftwareFoundation.Python.3.9_qbz5n2kfra8p0\LocalCache\local-packages\Python39\site-packages\newspaper\article.py", line 191, in parse
    self.throw_if_not_downloaded_verbose()
  File "C:\Users\User\AppData\Local\Packages\PythonSoftwareFoundation.Python.3.9_qbz5n2kfra8p0\LocalCache\local-packages\Python39\site-packages\newspaper\article.py", line 531, in throw_if_not_downloaded_verbose
    raise ArticleException('Article `download()` failed with %s on URL %s' %
newspaper.article.ArticleException: Article `download()` failed with 403 Client Error: Forbidden for url: https://forums.usacarry.com/politics-and-news/63339-chuck-schumer-s-steamy-affair-high-school-cheerleader-confirmed.html on URL https://www.usacarry.com/forums/politics-and-news/63339-chuck-schumer-s-steamy-affair-high-school-cheerleader-confirmed.html
2021-11-24 18:55:41,036 18172 news_content_collection ERROR Exception in getting data from url http://www.puppetstringnews.com/blog/tennessee-gop-twitter-taken-down-after-tweet-exposin-pelosi-involved-in-pedophilia
Traceback (most recent call last):
  File "C:\Users\User\Desktop\ia2\FakeNewsNet\code\news_content_collection.py", line 49, in crawl_link_article
    article.parse()
  File "C:\Users\User\AppData\Local\Packages\PythonSoftwareFoundation.Python.3.9_qbz5n2kfra8p0\LocalCache\local-packages\Python39\site-packages\newspaper\article.py", line 191, in parse
    self.throw_if_not_downloaded_verbose()
  File "C:\Users\User\AppData\Local\Packages\PythonSoftwareFoundation.Python.3.9_qbz5n2kfra8p0\LocalCache\local-packages\Python39\site-packages\newspaper\article.py", line 531, in throw_if_not_downloaded_verbose
    raise ArticleException('Article `download()` failed with %s on URL %s' %
newspaper.article.ArticleException: Article `download()` failed with 404 Client Error: Not Found for url: http://puppetstringnews.com/blog/tennessee-gop-twitter-taken-down-after-tweet-exposin-pelosi-involved-in-pedophilia on URL http://www.puppetstringnews.com/blog/tennessee-gop-twitter-taken-down-after-tweet-exposin-pelosi-involved-in-pedophilia
2021-11-24 18:55:47,578 18172 news_content_collection ERROR Exception in getting data from url http://viralactions.com/80-of-black-men-in-atlanta-are-homosexuals-study-says/
Traceback (most recent call last):
  File "C:\Users\User\Desktop\ia2\FakeNewsNet\code\news_content_collection.py", line 49, in crawl_link_article
    article.parse()
  File "C:\Users\User\AppData\Local\Packages\PythonSoftwareFoundation.Python.3.9_qbz5n2kfra8p0\LocalCache\local-packages\Python39\site-packages\newspaper\article.py", line 191, in parse
    self.throw_if_not_downloaded_verbose()
  File "C:\Users\User\AppData\Local\Packages\PythonSoftwareFoundation.Python.3.9_qbz5n2kfra8p0\LocalCache\local-packages\Python39\site-packages\newspaper\article.py", line 531, in throw_if_not_downloaded_verbose
    raise ArticleException('Article `download()` failed with %s on URL %s' %
newspaper.article.ArticleException: Article `download()` failed with 404 Client Error: Not Found for url: http://viralactions.com/80-of-black-men-in-atlanta-are-homosexuals-study-says/ on URL http://viralactions.com/80-of-black-men-in-atlanta-are-homosexuals-study-says/
2021-11-24 18:55:51,061 18172 news_content_collection ERROR Exception in getting data from url https://web.archive.org/web/20190512085410/http://viralactions.com/80-of-black-men-in-atlanta-are-homosexuals-study-says/
Traceback (most recent call last):
  File "C:\Users\User\Desktop\ia2\FakeNewsNet\code\news_content_collection.py", line 49, in crawl_link_article
    article.parse()
  File "C:\Users\User\AppData\Local\Packages\PythonSoftwareFoundation.Python.3.9_qbz5n2kfra8p0\LocalCache\local-packages\Python39\site-packages\newspaper\article.py", line 191, in parse
    self.throw_if_not_downloaded_verbose()
  File "C:\Users\User\AppData\Local\Packages\PythonSoftwareFoundation.Python.3.9_qbz5n2kfra8p0\LocalCache\local-packages\Python39\site-packages\newspaper\article.py", line 531, in throw_if_not_downloaded_verbose
    raise ArticleException('Article `download()` failed with %s on URL %s' %
newspaper.article.ArticleException: Article `download()` failed with 404 Client Error: Not Found for url: https://web.archive.org/web/20190512085410/http://viralactions.com/80-of-black-men-in-atlanta-are-homosexuals-study-says/ on URL https://web.archive.org/web/20190512085410/http://viralactions.com/80-of-black-men-in-atlanta-are-homosexuals-study-says/
2021-11-24 18:56:28,453 18172 connection ERROR Certificate did not match expected hostname: www.truthexam.com. Certificate: {'subject': ((('countryName', 'US'),), (('stateOrProvinceName', 'California'),), (('localityName', 'San Francisco'),), (('organizationName', 'Cloudflare, Inc.'),), (('commonName', '*.myshopify.com'),)), 'issuer': ((('countryName', 'US'),), (('organizationName', 'Cloudflare, Inc.'),), (('commonName', 'Cloudflare Inc ECC CA-3'),)), 'version': 3, 'serialNumber': '08D14009B8CCFD7A28D460E790084A96', 'notBefore': 'Sep 13 00:00:00 2021 GMT', 'notAfter': 'Sep 12 23:59:59 2022 GMT', 'subjectAltName': (('DNS', 'myshopify.com'), ('DNS', '*.myshopify.com')), 'OCSP': ('http://ocsp.digicert.com',), 'caIssuers': ('http://cacerts.digicert.com/CloudflareIncECCCA-3.crt',), 'crlDistributionPoints': ('http://crl3.digicert.com/CloudflareIncECCCA-3.crl', 'http://crl4.digicert.com/CloudflareIncECCCA-3.crl')}
2021-11-24 18:56:30,455 18172 news_content_collection ERROR Exception in getting data from url https://www.truthexam.com/2017/11/new-jersey-police-chief-says-black-people-no-value-executed/
Traceback (most recent call last):
  File "C:\Users\User\Desktop\ia2\FakeNewsNet\code\news_content_collection.py", line 49, in crawl_link_article
    article.parse()
  File "C:\Users\User\AppData\Local\Packages\PythonSoftwareFoundation.Python.3.9_qbz5n2kfra8p0\LocalCache\local-packages\Python39\site-packages\newspaper\article.py", line 191, in parse
    self.throw_if_not_downloaded_verbose()
  File "C:\Users\User\AppData\Local\Packages\PythonSoftwareFoundation.Python.3.9_qbz5n2kfra8p0\LocalCache\local-packages\Python39\site-packages\newspaper\article.py", line 531, in throw_if_not_downloaded_verbose
    raise ArticleException('Article `download()` failed with %s on URL %s' %
newspaper.article.ArticleException: Article `download()` failed with HTTPSConnectionPool(host='www.truthexam.com', port=443): Max retries exceeded with url: /2017/11/new-jersey-police-chief-says-black-people-no-value-executed/ (Caused by SSLError(SSLCertVerificationError("hostname 'www.truthexam.com' doesn't match either of 'myshopify.com', '*.myshopify.com'"))) on URL https://www.truthexam.com/2017/11/new-jersey-police-chief-says-black-people-no-value-executed/
2021-11-24 18:56:49,687 18172 news_content_collection ERROR Exception in getting data from url usleader.net/index.php/2017/05/11/breaking-bill-oreilly-critical-condition-attacked-tolerant-liberals/
Traceback (most recent call last):
  File "C:\Users\User\Desktop\ia2\FakeNewsNet\code\news_content_collection.py", line 25, in crawl_link_article
    article.parse()
  File "C:\Users\User\AppData\Local\Packages\PythonSoftwareFoundation.Python.3.9_qbz5n2kfra8p0\LocalCache\local-packages\Python39\site-packages\newspaper\article.py", line 191, in parse
    self.throw_if_not_downloaded_verbose()
  File "C:\Users\User\AppData\Local\Packages\PythonSoftwareFoundation.Python.3.9_qbz5n2kfra8p0\LocalCache\local-packages\Python39\site-packages\newspaper\article.py", line 531, in throw_if_not_downloaded_verbose
    raise ArticleException('Article `download()` failed with %s on URL %s' %
newspaper.article.ArticleException: Article `download()` failed with ('Connection aborted.', RemoteDisconnected('Remote end closed connection without response')) on URL http://usleader.net/index.php/2017/05/11/breaking-bill-oreilly-critical-condition-attacked-tolerant-liberals/
2021-11-24 18:56:58,888 18172 news_content_collection ERROR Exception in getting data from url usleader.net/index.php/2017/05/11/breaking-bill-oreilly-critical-condition-attacked-tolerant-liberals/
Traceback (most recent call last):
  File "C:\Users\User\Desktop\ia2\FakeNewsNet\code\news_content_collection.py", line 36, in crawl_link_article
    article.parse()
  File "C:\Users\User\AppData\Local\Packages\PythonSoftwareFoundation.Python.3.9_qbz5n2kfra8p0\LocalCache\local-packages\Python39\site-packages\newspaper\article.py", line 191, in parse
    self.throw_if_not_downloaded_verbose()
  File "C:\Users\User\AppData\Local\Packages\PythonSoftwareFoundation.Python.3.9_qbz5n2kfra8p0\LocalCache\local-packages\Python39\site-packages\newspaper\article.py", line 531, in throw_if_not_downloaded_verbose
    raise ArticleException('Article `download()` failed with %s on URL %s' %
newspaper.article.ArticleException: Article `download()` failed with HTTPSConnectionPool(host='usleader.net', port=443): Max retries exceeded with url: /index.php/2017/05/11/breaking-bill-oreilly-critical-condition-attacked-tolerant-liberals/ (Caused by ConnectTimeoutError(<urllib3.connection.VerifiedHTTPSConnection object at 0x000001C9C249F490>, 'Connection to usleader.net timed out. (connect timeout=7)')) on URL https://usleader.net/index.php/2017/05/11/breaking-bill-oreilly-critical-condition-attacked-tolerant-liberals/
2021-11-24 18:57:11,396 18172 news_content_collection ERROR Exception in getting data from url www.higherperspectives.com/powerful-note-1645303283.html
Traceback (most recent call last):
  File "C:\Users\User\Desktop\ia2\FakeNewsNet\code\news_content_collection.py", line 25, in crawl_link_article
    article.parse()
  File "C:\Users\User\AppData\Local\Packages\PythonSoftwareFoundation.Python.3.9_qbz5n2kfra8p0\LocalCache\local-packages\Python39\site-packages\newspaper\article.py", line 191, in parse
    self.throw_if_not_downloaded_verbose()
  File "C:\Users\User\AppData\Local\Packages\PythonSoftwareFoundation.Python.3.9_qbz5n2kfra8p0\LocalCache\local-packages\Python39\site-packages\newspaper\article.py", line 531, in throw_if_not_downloaded_verbose
    raise ArticleException('Article `download()` failed with %s on URL %s' %
newspaper.article.ArticleException: Article `download()` failed with 404 Client Error: Not Found for url: https://www.higherperspectives.com/powerful-note-1645303283.html on URL http://www.higherperspectives.com/powerful-note-1645303283.html
2021-11-24 18:57:13,628 18172 news_content_collection ERROR Exception in getting data from url www.higherperspectives.com/powerful-note-1645303283.html
Traceback (most recent call last):
  File "C:\Users\User\Desktop\ia2\FakeNewsNet\code\news_content_collection.py", line 36, in crawl_link_article
    article.parse()
  File "C:\Users\User\AppData\Local\Packages\PythonSoftwareFoundation.Python.3.9_qbz5n2kfra8p0\LocalCache\local-packages\Python39\site-packages\newspaper\article.py", line 191, in parse
    self.throw_if_not_downloaded_verbose()
  File "C:\Users\User\AppData\Local\Packages\PythonSoftwareFoundation.Python.3.9_qbz5n2kfra8p0\LocalCache\local-packages\Python39\site-packages\newspaper\article.py", line 531, in throw_if_not_downloaded_verbose
    raise ArticleException('Article `download()` failed with %s on URL %s' %
newspaper.article.ArticleException: Article `download()` failed with 404 Client Error: Not Found for url: https://www.higherperspectives.com/powerful-note-1645303283.html on URL https://www.higherperspectives.com/powerful-note-1645303283.html
2021-11-24 18:57:21,450 18172 news_content_collection ERROR Exception in getting data from url http://usleader.net/index.php/2017/05/05/breaking-ken-starrs-plane-just-disappeared-way-dc-testify-hillary/
Traceback (most recent call last):
  File "C:\Users\User\Desktop\ia2\FakeNewsNet\code\news_content_collection.py", line 49, in crawl_link_article
    article.parse()
  File "C:\Users\User\AppData\Local\Packages\PythonSoftwareFoundation.Python.3.9_qbz5n2kfra8p0\LocalCache\local-packages\Python39\site-packages\newspaper\article.py", line 191, in parse
    self.throw_if_not_downloaded_verbose()
  File "C:\Users\User\AppData\Local\Packages\PythonSoftwareFoundation.Python.3.9_qbz5n2kfra8p0\LocalCache\local-packages\Python39\site-packages\newspaper\article.py", line 531, in throw_if_not_downloaded_verbose
    raise ArticleException('Article `download()` failed with %s on URL %s' %
newspaper.article.ArticleException: Article `download()` failed with ('Connection aborted.', RemoteDisconnected('Remote end closed connection without response')) on URL http://usleader.net/index.php/2017/05/05/breaking-ken-starrs-plane-just-disappeared-way-dc-testify-hillary/
2021-11-24 18:57:28,760 18172 news_content_collection ERROR Exception in getting data from url https://mainerepublicemailalert.com/2017/06/24/breaking-johnny-depp-taken-into-custody-by-secret-service/
Traceback (most recent call last):
  File "C:\Users\User\Desktop\ia2\FakeNewsNet\code\news_content_collection.py", line 49, in crawl_link_article
    article.parse()
  File "C:\Users\User\AppData\Local\Packages\PythonSoftwareFoundation.Python.3.9_qbz5n2kfra8p0\LocalCache\local-packages\Python39\site-packages\newspaper\article.py", line 191, in parse
    self.throw_if_not_downloaded_verbose()
  File "C:\Users\User\AppData\Local\Packages\PythonSoftwareFoundation.Python.3.9_qbz5n2kfra8p0\LocalCache\local-packages\Python39\site-packages\newspaper\article.py", line 531, in throw_if_not_downloaded_verbose
    raise ArticleException('Article `download()` failed with %s on URL %s' %
newspaper.article.ArticleException: Article `download()` failed with 404 Client Error: Not Found for url: https://mainerepublicemailalert.com/2017/06/24/breaking-johnny-depp-taken-into-custody-by-secret-service/ on URL https://mainerepublicemailalert.com/2017/06/24/breaking-johnny-depp-taken-into-custody-by-secret-service/
2021-11-24 18:57:42,997 18172 news_content_collection ERROR Exception in getting data from url www.veterantv.com/trump-removing-marines-from-the-navy/
Traceback (most recent call last):
  File "C:\Users\User\Desktop\ia2\FakeNewsNet\code\news_content_collection.py", line 25, in crawl_link_article
    article.parse()
  File "C:\Users\User\AppData\Local\Packages\PythonSoftwareFoundation.Python.3.9_qbz5n2kfra8p0\LocalCache\local-packages\Python39\site-packages\newspaper\article.py", line 191, in parse
    self.throw_if_not_downloaded_verbose()
  File "C:\Users\User\AppData\Local\Packages\PythonSoftwareFoundation.Python.3.9_qbz5n2kfra8p0\LocalCache\local-packages\Python39\site-packages\newspaper\article.py", line 531, in throw_if_not_downloaded_verbose
    raise ArticleException('Article `download()` failed with %s on URL %s' %
newspaper.article.ArticleException: Article `download()` failed with 404 Client Error: Not Found for url: https://www.veterantv.com/trump-removing-marines-from-the-navy/ on URL http://www.veterantv.com/trump-removing-marines-from-the-navy/
2021-11-24 18:57:46,218 18172 news_content_collection ERROR Exception in getting data from url www.veterantv.com/trump-removing-marines-from-the-navy/
Traceback (most recent call last):
  File "C:\Users\User\Desktop\ia2\FakeNewsNet\code\news_content_collection.py", line 36, in crawl_link_article
    article.parse()
  File "C:\Users\User\AppData\Local\Packages\PythonSoftwareFoundation.Python.3.9_qbz5n2kfra8p0\LocalCache\local-packages\Python39\site-packages\newspaper\article.py", line 191, in parse
    self.throw_if_not_downloaded_verbose()
  File "C:\Users\User\AppData\Local\Packages\PythonSoftwareFoundation.Python.3.9_qbz5n2kfra8p0\LocalCache\local-packages\Python39\site-packages\newspaper\article.py", line 531, in throw_if_not_downloaded_verbose
    raise ArticleException('Article `download()` failed with %s on URL %s' %
newspaper.article.ArticleException: Article `download()` failed with 404 Client Error: Not Found for url: https://www.veterantv.com/trump-removing-marines-from-the-navy/ on URL https://www.veterantv.com/trump-removing-marines-from-the-navy/
2021-11-24 18:58:09,997 18172 news_content_collection ERROR Exception in getting data from url https://ourvoiceny.com/trump-vows-end-winter-heating-assistance-elderly-disabled/
Traceback (most recent call last):
  File "C:\Users\User\Desktop\ia2\FakeNewsNet\code\news_content_collection.py", line 49, in crawl_link_article
    article.parse()
  File "C:\Users\User\AppData\Local\Packages\PythonSoftwareFoundation.Python.3.9_qbz5n2kfra8p0\LocalCache\local-packages\Python39\site-packages\newspaper\article.py", line 191, in parse
    self.throw_if_not_downloaded_verbose()
  File "C:\Users\User\AppData\Local\Packages\PythonSoftwareFoundation.Python.3.9_qbz5n2kfra8p0\LocalCache\local-packages\Python39\site-packages\newspaper\article.py", line 531, in throw_if_not_downloaded_verbose
    raise ArticleException('Article `download()` failed with %s on URL %s' %
newspaper.article.ArticleException: Article `download()` failed with 404 Client Error: Not Found for url: https://www.ourvoiceny.com/trump-vows-end-winter-heating-assistance-elderly-disabled/ on URL https://ourvoiceny.com/trump-vows-end-winter-heating-assistance-elderly-disabled/
2021-11-24 18:58:17,954 18172 news_content_collection ERROR Exception in getting data from url http://freeinfomedia.com/breaking-supreme-court-issues-first-bench-warrant-ever/
Traceback (most recent call last):
  File "C:\Users\User\Desktop\ia2\FakeNewsNet\code\news_content_collection.py", line 49, in crawl_link_article
    article.parse()
  File "C:\Users\User\AppData\Local\Packages\PythonSoftwareFoundation.Python.3.9_qbz5n2kfra8p0\LocalCache\local-packages\Python39\site-packages\newspaper\article.py", line 191, in parse
    self.throw_if_not_downloaded_verbose()
  File "C:\Users\User\AppData\Local\Packages\PythonSoftwareFoundation.Python.3.9_qbz5n2kfra8p0\LocalCache\local-packages\Python39\site-packages\newspaper\article.py", line 531, in throw_if_not_downloaded_verbose
    raise ArticleException('Article `download()` failed with %s on URL %s' %
newspaper.article.ArticleException: Article `download()` failed with 500 Server Error: Internal Server Error for url: http://freeinfomedia.com/breaking-supreme-court-issues-first-bench-warrant-ever/ on URL http://freeinfomedia.com/breaking-supreme-court-issues-first-bench-warrant-ever/
2021-11-24 18:58:41,859 18172 news_content_collection ERROR Exception in getting data from url http://www.lovethispic.com/blog/44703/smoking-in-cars-with-children-is-illegal-starting--january-30%2C-2018
Traceback (most recent call last):
  File "C:\Users\User\Desktop\ia2\FakeNewsNet\code\news_content_collection.py", line 49, in crawl_link_article
    article.parse()
  File "C:\Users\User\AppData\Local\Packages\PythonSoftwareFoundation.Python.3.9_qbz5n2kfra8p0\LocalCache\local-packages\Python39\site-packages\newspaper\article.py", line 191, in parse
    self.throw_if_not_downloaded_verbose()
  File "C:\Users\User\AppData\Local\Packages\PythonSoftwareFoundation.Python.3.9_qbz5n2kfra8p0\LocalCache\local-packages\Python39\site-packages\newspaper\article.py", line 531, in throw_if_not_downloaded_verbose
    raise ArticleException('Article `download()` failed with %s on URL %s' %
newspaper.article.ArticleException: Article `download()` failed with 404 Client Error: Not Found for url: https://www.lovethispic.com/blog/44703/smoking-in-cars-with-children-is-illegal-starting--january-30%2C-2018 on URL http://www.lovethispic.com/blog/44703/smoking-in-cars-with-children-is-illegal-starting--january-30%2C-2018
2021-11-24 18:58:57,573 18172 news_content_collection ERROR Exception in getting data from url https://smartmindmag.com/nasa-has-just-confirmed-earth-has-a-new-moon/
Traceback (most recent call last):
  File "C:\Users\User\Desktop\ia2\FakeNewsNet\code\news_content_collection.py", line 49, in crawl_link_article
    article.parse()
  File "C:\Users\User\AppData\Local\Packages\PythonSoftwareFoundation.Python.3.9_qbz5n2kfra8p0\LocalCache\local-packages\Python39\site-packages\newspaper\article.py", line 191, in parse
    self.throw_if_not_downloaded_verbose()
  File "C:\Users\User\AppData\Local\Packages\PythonSoftwareFoundation.Python.3.9_qbz5n2kfra8p0\LocalCache\local-packages\Python39\site-packages\newspaper\article.py", line 531, in throw_if_not_downloaded_verbose
    raise ArticleException('Article `download()` failed with %s on URL %s' %
newspaper.article.ArticleException: Article `download()` failed with HTTPSConnectionPool(host='smartmindmag.com', port=443): Max retries exceeded with url: /nasa-has-just-confirmed-earth-has-a-new-moon/ (Caused by NewConnectionError('<urllib3.connection.VerifiedHTTPSConnection object at 0x000001C9C2C5AF70>: Failed to establish a new connection: [Errno 11002] getaddrinfo failed')) on URL https://smartmindmag.com/nasa-has-just-confirmed-earth-has-a-new-moon/
2021-11-24 18:59:35,557 18172 news_content_collection ERROR Exception in getting data from url politicass.com/fox-news-sandra-smith-everybody-see-united-airlines-passengers-behavior-not-genuine-american/
Traceback (most recent call last):
  File "C:\Users\User\Desktop\ia2\FakeNewsNet\code\news_content_collection.py", line 25, in crawl_link_article
    article.parse()
  File "C:\Users\User\AppData\Local\Packages\PythonSoftwareFoundation.Python.3.9_qbz5n2kfra8p0\LocalCache\local-packages\Python39\site-packages\newspaper\article.py", line 191, in parse
    self.throw_if_not_downloaded_verbose()
  File "C:\Users\User\AppData\Local\Packages\PythonSoftwareFoundation.Python.3.9_qbz5n2kfra8p0\LocalCache\local-packages\Python39\site-packages\newspaper\article.py", line 531, in throw_if_not_downloaded_verbose
    raise ArticleException('Article `download()` failed with %s on URL %s' %
newspaper.article.ArticleException: Article `download()` failed with HTTPConnectionPool(host='politicass.com', port=80): Max retries exceeded with url: /fox-news-sandra-smith-everybody-see-united-airlines-passengers-behavior-not-genuine-american/ (Caused by NewConnectionError('<urllib3.connection.HTTPConnection object at 0x000001C9C2C5A670>: Failed to establish a new connection: [Errno 11001] getaddrinfo failed')) on URL http://politicass.com/fox-news-sandra-smith-everybody-see-united-airlines-passengers-behavior-not-genuine-american/
2021-11-24 18:59:37,739 18172 news_content_collection ERROR Exception in getting data from url politicass.com/fox-news-sandra-smith-everybody-see-united-airlines-passengers-behavior-not-genuine-american/
Traceback (most recent call last):
  File "C:\Users\User\Desktop\ia2\FakeNewsNet\code\news_content_collection.py", line 36, in crawl_link_article
    article.parse()
  File "C:\Users\User\AppData\Local\Packages\PythonSoftwareFoundation.Python.3.9_qbz5n2kfra8p0\LocalCache\local-packages\Python39\site-packages\newspaper\article.py", line 191, in parse
    self.throw_if_not_downloaded_verbose()
  File "C:\Users\User\AppData\Local\Packages\PythonSoftwareFoundation.Python.3.9_qbz5n2kfra8p0\LocalCache\local-packages\Python39\site-packages\newspaper\article.py", line 531, in throw_if_not_downloaded_verbose
    raise ArticleException('Article `download()` failed with %s on URL %s' %
newspaper.article.ArticleException: Article `download()` failed with HTTPSConnectionPool(host='politicass.com', port=443): Max retries exceeded with url: /fox-news-sandra-smith-everybody-see-united-airlines-passengers-behavior-not-genuine-american/ (Caused by NewConnectionError('<urllib3.connection.VerifiedHTTPSConnection object at 0x000001C9C2C5A850>: Failed to establish a new connection: [Errno 11001] getaddrinfo failed')) on URL https://politicass.com/fox-news-sandra-smith-everybody-see-united-airlines-passengers-behavior-not-genuine-american/
2021-11-24 18:59:47,153 18172 news_content_collection ERROR Exception in getting data from url www.newsweek.com/donna-brazile-book-seth-rich-dnc-murder-conspiracy-702838
Traceback (most recent call last):
  File "C:\Users\User\Desktop\ia2\FakeNewsNet\code\news_content_collection.py", line 25, in crawl_link_article
    article.parse()
  File "C:\Users\User\AppData\Local\Packages\PythonSoftwareFoundation.Python.3.9_qbz5n2kfra8p0\LocalCache\local-packages\Python39\site-packages\newspaper\article.py", line 191, in parse
    self.throw_if_not_downloaded_verbose()
  File "C:\Users\User\AppData\Local\Packages\PythonSoftwareFoundation.Python.3.9_qbz5n2kfra8p0\LocalCache\local-packages\Python39\site-packages\newspaper\article.py", line 531, in throw_if_not_downloaded_verbose
    raise ArticleException('Article `download()` failed with %s on URL %s' %
newspaper.article.ArticleException: Article `download()` failed with 403 Client Error: Forbidden for url: https://www.newsweek.com/donna-brazile-book-seth-rich-dnc-murder-conspiracy-702838 on URL http://www.newsweek.com/donna-brazile-book-seth-rich-dnc-murder-conspiracy-702838
2021-11-24 18:59:49,716 18172 news_content_collection ERROR Exception in getting data from url www.newsweek.com/donna-brazile-book-seth-rich-dnc-murder-conspiracy-702838
Traceback (most recent call last):
  File "C:\Users\User\Desktop\ia2\FakeNewsNet\code\news_content_collection.py", line 36, in crawl_link_article
    article.parse()
  File "C:\Users\User\AppData\Local\Packages\PythonSoftwareFoundation.Python.3.9_qbz5n2kfra8p0\LocalCache\local-packages\Python39\site-packages\newspaper\article.py", line 191, in parse
    self.throw_if_not_downloaded_verbose()
  File "C:\Users\User\AppData\Local\Packages\PythonSoftwareFoundation.Python.3.9_qbz5n2kfra8p0\LocalCache\local-packages\Python39\site-packages\newspaper\article.py", line 531, in throw_if_not_downloaded_verbose
    raise ArticleException('Article `download()` failed with %s on URL %s' %
newspaper.article.ArticleException: Article `download()` failed with 403 Client Error: Forbidden for url: https://www.newsweek.com/donna-brazile-book-seth-rich-dnc-murder-conspiracy-702838 on URL https://www.newsweek.com/donna-brazile-book-seth-rich-dnc-murder-conspiracy-702838
2021-11-24 19:00:01,320 18172 news_content_collection ERROR Exception in getting data from url http://usanews24h.tk/index.php/2018/04/12/obama-announces-bid-to-become-un-secretary-general/
Traceback (most recent call last):
  File "C:\Users\User\Desktop\ia2\FakeNewsNet\code\news_content_collection.py", line 49, in crawl_link_article
    article.parse()
  File "C:\Users\User\AppData\Local\Packages\PythonSoftwareFoundation.Python.3.9_qbz5n2kfra8p0\LocalCache\local-packages\Python39\site-packages\newspaper\article.py", line 191, in parse
    self.throw_if_not_downloaded_verbose()
  File "C:\Users\User\AppData\Local\Packages\PythonSoftwareFoundation.Python.3.9_qbz5n2kfra8p0\LocalCache\local-packages\Python39\site-packages\newspaper\article.py", line 531, in throw_if_not_downloaded_verbose
    raise ArticleException('Article `download()` failed with %s on URL %s' %
newspaper.article.ArticleException: Article `download()` failed with HTTPConnectionPool(host='usanews24h.tk', port=80): Max retries exceeded with url: /index.php/2018/04/12/obama-announces-bid-to-become-un-secretary-general/ (Caused by NewConnectionError('<urllib3.connection.HTTPConnection object at 0x000001C9C2C702B0>: Failed to establish a new connection: [Errno 11001] getaddrinfo failed')) on URL http://usanews24h.tk/index.php/2018/04/12/obama-announces-bid-to-become-un-secretary-general/
2021-11-24 19:00:19,024 18172 news_content_collection ERROR Exception in getting data from url http://wesupportdonaldtrump.com/mexico-next-president-invasion-1-a/
Traceback (most recent call last):
  File "C:\Users\User\Desktop\ia2\FakeNewsNet\code\news_content_collection.py", line 49, in crawl_link_article
    article.parse()
  File "C:\Users\User\AppData\Local\Packages\PythonSoftwareFoundation.Python.3.9_qbz5n2kfra8p0\LocalCache\local-packages\Python39\site-packages\newspaper\article.py", line 191, in parse
    self.throw_if_not_downloaded_verbose()
  File "C:\Users\User\AppData\Local\Packages\PythonSoftwareFoundation.Python.3.9_qbz5n2kfra8p0\LocalCache\local-packages\Python39\site-packages\newspaper\article.py", line 531, in throw_if_not_downloaded_verbose
    raise ArticleException('Article `download()` failed with %s on URL %s' %
newspaper.article.ArticleException: Article `download()` failed with HTTPConnectionPool(host='wesupportdonaldtrump.com', port=80): Max retries exceeded with url: /mexico-next-president-invasion-1-a/ (Caused by NewConnectionError('<urllib3.connection.HTTPConnection object at 0x000001C9C2C8C5B0>: Failed to establish a new connection: [Errno 11001] getaddrinfo failed')) on URL http://wesupportdonaldtrump.com/mexico-next-president-invasion-1-a/
2021-11-24 19:00:36,536 18172 news_content_collection ERROR Exception in getting data from url http://www.thelifebuzz.com/nasa-announced-that-it-communicated-with-four-races-of-aliens/2/
Traceback (most recent call last):
  File "C:\Users\User\Desktop\ia2\FakeNewsNet\code\news_content_collection.py", line 49, in crawl_link_article
    article.parse()
  File "C:\Users\User\AppData\Local\Packages\PythonSoftwareFoundation.Python.3.9_qbz5n2kfra8p0\LocalCache\local-packages\Python39\site-packages\newspaper\article.py", line 191, in parse
    self.throw_if_not_downloaded_verbose()
  File "C:\Users\User\AppData\Local\Packages\PythonSoftwareFoundation.Python.3.9_qbz5n2kfra8p0\LocalCache\local-packages\Python39\site-packages\newspaper\article.py", line 531, in throw_if_not_downloaded_verbose
    raise ArticleException('Article `download()` failed with %s on URL %s' %
newspaper.article.ArticleException: Article `download()` failed with HTTPConnectionPool(host='www.thelifebuzz.com', port=80): Max retries exceeded with url: /nasa-announced-that-it-communicated-with-four-races-of-aliens/2/ (Caused by NewConnectionError('<urllib3.connection.HTTPConnection object at 0x000001C9C2C8C250>: Failed to establish a new connection: [Errno 11002] getaddrinfo failed')) on URL http://www.thelifebuzz.com/nasa-announced-that-it-communicated-with-four-races-of-aliens/2/
2021-11-24 19:01:04,169 18172 news_content_collection ERROR Exception in getting data from url https://yournewswire.com/cnn-ratings-plunge-30-percent/
Traceback (most recent call last):
  File "C:\Users\User\Desktop\ia2\FakeNewsNet\code\news_content_collection.py", line 49, in crawl_link_article
    article.parse()
  File "C:\Users\User\AppData\Local\Packages\PythonSoftwareFoundation.Python.3.9_qbz5n2kfra8p0\LocalCache\local-packages\Python39\site-packages\newspaper\article.py", line 191, in parse
    self.throw_if_not_downloaded_verbose()
  File "C:\Users\User\AppData\Local\Packages\PythonSoftwareFoundation.Python.3.9_qbz5n2kfra8p0\LocalCache\local-packages\Python39\site-packages\newspaper\article.py", line 531, in throw_if_not_downloaded_verbose
    raise ArticleException('Article `download()` failed with %s on URL %s' %
newspaper.article.ArticleException: Article `download()` failed with 404 Client Error: Not Found for url: https://yournewswire.com/cnn-ratings-plunge-30-percent/ on URL https://yournewswire.com/cnn-ratings-plunge-30-percent/
2021-11-24 19:01:11,019 18172 news_content_collection ERROR Exception in getting data from url http://usa24info.com/index.php/2017/11/09/report-kim-jong-un-killed-trumps-overnight-black-op-attack-north-korea/
Traceback (most recent call last):
  File "C:\Users\User\Desktop\ia2\FakeNewsNet\code\news_content_collection.py", line 49, in crawl_link_article
    article.parse()
  File "C:\Users\User\AppData\Local\Packages\PythonSoftwareFoundation.Python.3.9_qbz5n2kfra8p0\LocalCache\local-packages\Python39\site-packages\newspaper\article.py", line 191, in parse
    self.throw_if_not_downloaded_verbose()
  File "C:\Users\User\AppData\Local\Packages\PythonSoftwareFoundation.Python.3.9_qbz5n2kfra8p0\LocalCache\local-packages\Python39\site-packages\newspaper\article.py", line 531, in throw_if_not_downloaded_verbose
    raise ArticleException('Article `download()` failed with %s on URL %s' %
newspaper.article.ArticleException: Article `download()` failed with HTTPConnectionPool(host='usa24info.com', port=80): Max retries exceeded with url: /index.php/2017/11/09/report-kim-jong-un-killed-trumps-overnight-black-op-attack-north-korea/ (Caused by NewConnectionError('<urllib3.connection.HTTPConnection object at 0x000001C9C2C79F10>: Failed to establish a new connection: [Errno 11001] getaddrinfo failed')) on URL http://usa24info.com/index.php/2017/11/09/report-kim-jong-un-killed-trumps-overnight-black-op-attack-north-korea/
2021-11-24 19:01:31,138 18172 news_content_collection ERROR Exception in getting data from url https://the-fringe.com/thread-civil_war_erupts_in_sweden_as_irate_swedes_burn_nine_muslim_refugee_centers_to_the_ground
Traceback (most recent call last):
  File "C:\Users\User\Desktop\ia2\FakeNewsNet\code\news_content_collection.py", line 49, in crawl_link_article
    article.parse()
  File "C:\Users\User\AppData\Local\Packages\PythonSoftwareFoundation.Python.3.9_qbz5n2kfra8p0\LocalCache\local-packages\Python39\site-packages\newspaper\article.py", line 191, in parse
    self.throw_if_not_downloaded_verbose()
  File "C:\Users\User\AppData\Local\Packages\PythonSoftwareFoundation.Python.3.9_qbz5n2kfra8p0\LocalCache\local-packages\Python39\site-packages\newspaper\article.py", line 531, in throw_if_not_downloaded_verbose
    raise ArticleException('Article `download()` failed with %s on URL %s' %
newspaper.article.ArticleException: Article `download()` failed with HTTPSConnectionPool(host='the-fringe.com', port=443): Max retries exceeded with url: /thread-civil_war_erupts_in_sweden_as_irate_swedes_burn_nine_muslim_refugee_centers_to_the_ground (Caused by NewConnectionError('<urllib3.connection.VerifiedHTTPSConnection object at 0x000001C9C2C7BA00>: Failed to establish a new connection: [WinError 10061] No connection could be made because the target machine actively refused it')) on URL https://the-fringe.com/thread-civil_war_erupts_in_sweden_as_irate_swedes_burn_nine_muslim_refugee_centers_to_the_ground
2021-11-24 19:01:35,915 18172 news_content_collection ERROR Exception in getting data from url http://www.alison-jackson.co.uk/mental-images/5fj9vvsfwlksdjptig08plvhni8nkx
Traceback (most recent call last):
  File "C:\Users\User\Desktop\ia2\FakeNewsNet\code\news_content_collection.py", line 49, in crawl_link_article
    article.parse()
  File "C:\Users\User\AppData\Local\Packages\PythonSoftwareFoundation.Python.3.9_qbz5n2kfra8p0\LocalCache\local-packages\Python39\site-packages\newspaper\article.py", line 191, in parse
    self.throw_if_not_downloaded_verbose()
  File "C:\Users\User\AppData\Local\Packages\PythonSoftwareFoundation.Python.3.9_qbz5n2kfra8p0\LocalCache\local-packages\Python39\site-packages\newspaper\article.py", line 531, in throw_if_not_downloaded_verbose
    raise ArticleException('Article `download()` failed with %s on URL %s' %
newspaper.article.ArticleException: Article `download()` failed with 404 Client Error: Not Found for url: https://www.alison-jackson.co.uk/mental-images/5fj9vvsfwlksdjptig08plvhni8nkx on URL http://www.alison-jackson.co.uk/mental-images/5fj9vvsfwlksdjptig08plvhni8nkx
2021-11-24 19:01:44,059 18172 news_content_collection ERROR Exception in getting data from url http://twentyeightmay.pw/kurt-russel-just-showed-overpaid-celebs-its-time-to-shut-up-about-trump-hits-them-where-it-hurts/
Traceback (most recent call last):
  File "C:\Users\User\Desktop\ia2\FakeNewsNet\code\news_content_collection.py", line 49, in crawl_link_article
    article.parse()
  File "C:\Users\User\AppData\Local\Packages\PythonSoftwareFoundation.Python.3.9_qbz5n2kfra8p0\LocalCache\local-packages\Python39\site-packages\newspaper\article.py", line 191, in parse
    self.throw_if_not_downloaded_verbose()
  File "C:\Users\User\AppData\Local\Packages\PythonSoftwareFoundation.Python.3.9_qbz5n2kfra8p0\LocalCache\local-packages\Python39\site-packages\newspaper\article.py", line 531, in throw_if_not_downloaded_verbose
    raise ArticleException('Article `download()` failed with %s on URL %s' %
newspaper.article.ArticleException: Article `download()` failed with HTTPConnectionPool(host='twentyeightmay.pw', port=80): Max retries exceeded with url: /kurt-russel-just-showed-overpaid-celebs-its-time-to-shut-up-about-trump-hits-them-where-it-hurts/ (Caused by NewConnectionError('<urllib3.connection.HTTPConnection object at 0x000001C9C2C8C3D0>: Failed to establish a new connection: [Errno 11001] getaddrinfo failed')) on URL http://twentyeightmay.pw/kurt-russel-just-showed-overpaid-celebs-its-time-to-shut-up-about-trump-hits-them-where-it-hurts/
2021-11-24 19:02:05,215 18172 news_content_collection ERROR Exception in getting data from url https://yournewswire.com/anthony-bourdain-killed-clinton-operatives/
Traceback (most recent call last):
  File "C:\Users\User\Desktop\ia2\FakeNewsNet\code\news_content_collection.py", line 49, in crawl_link_article
    article.parse()
  File "C:\Users\User\AppData\Local\Packages\PythonSoftwareFoundation.Python.3.9_qbz5n2kfra8p0\LocalCache\local-packages\Python39\site-packages\newspaper\article.py", line 191, in parse
    self.throw_if_not_downloaded_verbose()
  File "C:\Users\User\AppData\Local\Packages\PythonSoftwareFoundation.Python.3.9_qbz5n2kfra8p0\LocalCache\local-packages\Python39\site-packages\newspaper\article.py", line 531, in throw_if_not_downloaded_verbose
    raise ArticleException('Article `download()` failed with %s on URL %s' %
newspaper.article.ArticleException: Article `download()` failed with 404 Client Error: Not Found for url: https://yournewswire.com/anthony-bourdain-killed-clinton-operatives/ on URL https://yournewswire.com/anthony-bourdain-killed-clinton-operatives/
2021-11-24 19:02:09,407 18172 news_content_collection ERROR Exception in fetching article form URL : 
Traceback (most recent call last):
  File "C:\Users\User\Desktop\ia2\FakeNewsNet\code\news_content_collection.py", line 19, in crawl_link_article
    if url[0] == '/':
IndexError: string index out of range
2021-11-24 19:02:13,454 18172 news_content_collection ERROR Exception in getting data from url https://web.archive.org/web/20180808123333/http://http:///
Traceback (most recent call last):
  File "C:\Users\User\Desktop\ia2\FakeNewsNet\code\news_content_collection.py", line 49, in crawl_link_article
    article.parse()
  File "C:\Users\User\AppData\Local\Packages\PythonSoftwareFoundation.Python.3.9_qbz5n2kfra8p0\LocalCache\local-packages\Python39\site-packages\newspaper\article.py", line 191, in parse
    self.throw_if_not_downloaded_verbose()
  File "C:\Users\User\AppData\Local\Packages\PythonSoftwareFoundation.Python.3.9_qbz5n2kfra8p0\LocalCache\local-packages\Python39\site-packages\newspaper\article.py", line 531, in throw_if_not_downloaded_verbose
    raise ArticleException('Article `download()` failed with %s on URL %s' %
newspaper.article.ArticleException: Article `download()` failed with 400 Client Error: Bad Request for url: https://web.archive.org/web/20191006182526/http://.../ on URL https://web.archive.org/web/20180808123333/http://http:///
2021-11-24 19:02:16,672 18172 news_content_collection ERROR Exception in getting data from url http://24trueinfoamerica.com/breaking-60-people-just-found-dead-in-ohio
Traceback (most recent call last):
  File "C:\Users\User\Desktop\ia2\FakeNewsNet\code\news_content_collection.py", line 49, in crawl_link_article
    article.parse()
  File "C:\Users\User\AppData\Local\Packages\PythonSoftwareFoundation.Python.3.9_qbz5n2kfra8p0\LocalCache\local-packages\Python39\site-packages\newspaper\article.py", line 191, in parse
    self.throw_if_not_downloaded_verbose()
  File "C:\Users\User\AppData\Local\Packages\PythonSoftwareFoundation.Python.3.9_qbz5n2kfra8p0\LocalCache\local-packages\Python39\site-packages\newspaper\article.py", line 531, in throw_if_not_downloaded_verbose
    raise ArticleException('Article `download()` failed with %s on URL %s' %
newspaper.article.ArticleException: Article `download()` failed with ('Connection aborted.', RemoteDisconnected('Remote end closed connection without response')) on URL http://24trueinfoamerica.com/breaking-60-people-just-found-dead-in-ohio
2021-11-24 19:02:36,728 18172 news_content_collection ERROR Exception in getting data from url http://www.cvikas.com/2018/05/22/usa-mysterious-nazi-submarine-from-wwii-discovered-in-great-lakes/
Traceback (most recent call last):
  File "C:\Users\User\Desktop\ia2\FakeNewsNet\code\news_content_collection.py", line 49, in crawl_link_article
    article.parse()
  File "C:\Users\User\AppData\Local\Packages\PythonSoftwareFoundation.Python.3.9_qbz5n2kfra8p0\LocalCache\local-packages\Python39\site-packages\newspaper\article.py", line 191, in parse
    self.throw_if_not_downloaded_verbose()
  File "C:\Users\User\AppData\Local\Packages\PythonSoftwareFoundation.Python.3.9_qbz5n2kfra8p0\LocalCache\local-packages\Python39\site-packages\newspaper\article.py", line 531, in throw_if_not_downloaded_verbose
    raise ArticleException('Article `download()` failed with %s on URL %s' %
newspaper.article.ArticleException: Article `download()` failed with ('Connection aborted.', BadStatusLine('HTTP/1.1 401.1 Unauthorized\r\n')) on URL http://www.cvikas.com/2018/05/22/usa-mysterious-nazi-submarine-from-wwii-discovered-in-great-lakes/
2021-11-24 19:02:48,624 18172 news_content_collection ERROR Exception in getting data from url https://yournewswire.com/irma-destroy-new-york-city/
Traceback (most recent call last):
  File "C:\Users\User\Desktop\ia2\FakeNewsNet\code\news_content_collection.py", line 49, in crawl_link_article
    article.parse()
  File "C:\Users\User\AppData\Local\Packages\PythonSoftwareFoundation.Python.3.9_qbz5n2kfra8p0\LocalCache\local-packages\Python39\site-packages\newspaper\article.py", line 191, in parse
    self.throw_if_not_downloaded_verbose()
  File "C:\Users\User\AppData\Local\Packages\PythonSoftwareFoundation.Python.3.9_qbz5n2kfra8p0\LocalCache\local-packages\Python39\site-packages\newspaper\article.py", line 531, in throw_if_not_downloaded_verbose
    raise ArticleException('Article `download()` failed with %s on URL %s' %
newspaper.article.ArticleException: Article `download()` failed with 404 Client Error: Not Found for url: https://yournewswire.com/irma-destroy-new-york-city/ on URL https://yournewswire.com/irma-destroy-new-york-city/
2021-11-24 19:03:10,829 18172 news_content_collection ERROR Exception in getting data from url http://www.patriotnetwork.one/2018/04/27/breaking-czech-republic-arms-citizens-you-can-now-shoot-terrorists-on-sight/
Traceback (most recent call last):
  File "C:\Users\User\Desktop\ia2\FakeNewsNet\code\news_content_collection.py", line 49, in crawl_link_article
    article.parse()
  File "C:\Users\User\AppData\Local\Packages\PythonSoftwareFoundation.Python.3.9_qbz5n2kfra8p0\LocalCache\local-packages\Python39\site-packages\newspaper\article.py", line 191, in parse
    self.throw_if_not_downloaded_verbose()
  File "C:\Users\User\AppData\Local\Packages\PythonSoftwareFoundation.Python.3.9_qbz5n2kfra8p0\LocalCache\local-packages\Python39\site-packages\newspaper\article.py", line 531, in throw_if_not_downloaded_verbose
    raise ArticleException('Article `download()` failed with %s on URL %s' %
newspaper.article.ArticleException: Article `download()` failed with HTTPConnectionPool(host='www.patriotnetwork.one', port=80): Max retries exceeded with url: /2018/04/27/breaking-czech-republic-arms-citizens-you-can-now-shoot-terrorists-on-sight/ (Caused by NewConnectionError('<urllib3.connection.HTTPConnection object at 0x000001C9C2C799D0>: Failed to establish a new connection: [Errno 11001] getaddrinfo failed')) on URL http://www.patriotnetwork.one/2018/04/27/breaking-czech-republic-arms-citizens-you-can-now-shoot-terrorists-on-sight/
2021-11-24 19:03:39,835 18172 news_content_collection ERROR Exception in getting data from url http://conservative7.com/2017/10/10/breaking-black-hockey-player-fired-raising-fist-national-anthem/
Traceback (most recent call last):
  File "C:\Users\User\Desktop\ia2\FakeNewsNet\code\news_content_collection.py", line 49, in crawl_link_article
    article.parse()
  File "C:\Users\User\AppData\Local\Packages\PythonSoftwareFoundation.Python.3.9_qbz5n2kfra8p0\LocalCache\local-packages\Python39\site-packages\newspaper\article.py", line 191, in parse
    self.throw_if_not_downloaded_verbose()
  File "C:\Users\User\AppData\Local\Packages\PythonSoftwareFoundation.Python.3.9_qbz5n2kfra8p0\LocalCache\local-packages\Python39\site-packages\newspaper\article.py", line 531, in throw_if_not_downloaded_verbose
    raise ArticleException('Article `download()` failed with %s on URL %s' %
newspaper.article.ArticleException: Article `download()` failed with HTTPConnectionPool(host='conservative7.com', port=80): Max retries exceeded with url: /2017/10/10/breaking-black-hockey-player-fired-raising-fist-national-anthem/ (Caused by ConnectTimeoutError(<urllib3.connection.HTTPConnection object at 0x000001C9C2C5AC40>, 'Connection to conservative7.com timed out. (connect timeout=7)')) on URL http://conservative7.com/2017/10/10/breaking-black-hockey-player-fired-raising-fist-national-anthem/
2021-11-24 19:03:49,241 18172 news_content_collection ERROR Exception in getting data from url http://forfreedomworld.com/2017/08/20/breaking-rosa-parks-daughter-praises-trumps-response-to-charlottesville/
Traceback (most recent call last):
  File "C:\Users\User\Desktop\ia2\FakeNewsNet\code\news_content_collection.py", line 49, in crawl_link_article
    article.parse()
  File "C:\Users\User\AppData\Local\Packages\PythonSoftwareFoundation.Python.3.9_qbz5n2kfra8p0\LocalCache\local-packages\Python39\site-packages\newspaper\article.py", line 191, in parse
    self.throw_if_not_downloaded_verbose()
  File "C:\Users\User\AppData\Local\Packages\PythonSoftwareFoundation.Python.3.9_qbz5n2kfra8p0\LocalCache\local-packages\Python39\site-packages\newspaper\article.py", line 531, in throw_if_not_downloaded_verbose
    raise ArticleException('Article `download()` failed with %s on URL %s' %
newspaper.article.ArticleException: Article `download()` failed with HTTPConnectionPool(host='forfreedomworld.com', port=80): Max retries exceeded with url: /2017/08/20/breaking-rosa-parks-daughter-praises-trumps-response-to-charlottesville/ (Caused by NewConnectionError('<urllib3.connection.HTTPConnection object at 0x000001C9C2C74700>: Failed to establish a new connection: [Errno 11001] getaddrinfo failed')) on URL http://forfreedomworld.com/2017/08/20/breaking-rosa-parks-daughter-praises-trumps-response-to-charlottesville/
2021-11-24 19:04:03,037 18172 news_content_collection ERROR Exception in getting data from url http://usbreakingnews.net/bombshell-obama-paid-fbi-informant-over-1-million-to-do-it-to-trump-even-after-the-election/
Traceback (most recent call last):
  File "C:\Users\User\Desktop\ia2\FakeNewsNet\code\news_content_collection.py", line 49, in crawl_link_article
    article.parse()
  File "C:\Users\User\AppData\Local\Packages\PythonSoftwareFoundation.Python.3.9_qbz5n2kfra8p0\LocalCache\local-packages\Python39\site-packages\newspaper\article.py", line 191, in parse
    self.throw_if_not_downloaded_verbose()
  File "C:\Users\User\AppData\Local\Packages\PythonSoftwareFoundation.Python.3.9_qbz5n2kfra8p0\LocalCache\local-packages\Python39\site-packages\newspaper\article.py", line 531, in throw_if_not_downloaded_verbose
    raise ArticleException('Article `download()` failed with %s on URL %s' %
newspaper.article.ArticleException: Article `download()` failed with 404 Client Error: Not Found for url: https://usbreakingnews.net/bombshell-obama-paid-fbi-informant-over-1-million-to-do-it-to-trump-even-after-the-election/ on URL http://usbreakingnews.net/bombshell-obama-paid-fbi-informant-over-1-million-to-do-it-to-trump-even-after-the-election/
2021-11-24 19:04:34,116 18172 news_content_collection ERROR Exception in getting data from url http://houstonpost.co/2018/06/26/red-hen-owner-just-issued-sick-threat-to-sarah-sanders-after-biz-was-destroyed-by-booting-her/
Traceback (most recent call last):
  File "C:\Users\User\Desktop\ia2\FakeNewsNet\code\news_content_collection.py", line 49, in crawl_link_article
    article.parse()
  File "C:\Users\User\AppData\Local\Packages\PythonSoftwareFoundation.Python.3.9_qbz5n2kfra8p0\LocalCache\local-packages\Python39\site-packages\newspaper\article.py", line 191, in parse
    self.throw_if_not_downloaded_verbose()
  File "C:\Users\User\AppData\Local\Packages\PythonSoftwareFoundation.Python.3.9_qbz5n2kfra8p0\LocalCache\local-packages\Python39\site-packages\newspaper\article.py", line 531, in throw_if_not_downloaded_verbose
    raise ArticleException('Article `download()` failed with %s on URL %s' %
newspaper.article.ArticleException: Article `download()` failed with HTTPConnectionPool(host='houstonpost.co', port=80): Max retries exceeded with url: /2018/06/26/red-hen-owner-just-issued-sick-threat-to-sarah-sanders-after-biz-was-destroyed-by-booting-her/ (Caused by NewConnectionError('<urllib3.connection.HTTPConnection object at 0x000001C9C2C8C760>: Failed to establish a new connection: [Errno 11001] getaddrinfo failed')) on URL http://houstonpost.co/2018/06/26/red-hen-owner-just-issued-sick-threat-to-sarah-sanders-after-biz-was-destroyed-by-booting-her/
2021-11-24 19:05:24,866 18172 news_content_collection ERROR Exception in getting data from url http://therightists.com/lady-gaga-reveals-plan-to-cover-her-face-again-until-trump-gets-fired-from-office-and-i-feel-free-once-more/
Traceback (most recent call last):
  File "C:\Users\User\Desktop\ia2\FakeNewsNet\code\news_content_collection.py", line 49, in crawl_link_article
    article.parse()
  File "C:\Users\User\AppData\Local\Packages\PythonSoftwareFoundation.Python.3.9_qbz5n2kfra8p0\LocalCache\local-packages\Python39\site-packages\newspaper\article.py", line 191, in parse
    self.throw_if_not_downloaded_verbose()
  File "C:\Users\User\AppData\Local\Packages\PythonSoftwareFoundation.Python.3.9_qbz5n2kfra8p0\LocalCache\local-packages\Python39\site-packages\newspaper\article.py", line 531, in throw_if_not_downloaded_verbose
    raise ArticleException('Article `download()` failed with %s on URL %s' %
newspaper.article.ArticleException: Article `download()` failed with 404 Client Error: Not Found for url: https://therightists.com/lady-gaga-reveals-plan-to-cover-her-face-again-until-trump-gets-fired-from-office-and-i-feel-free-once-more/ on URL http://therightists.com/lady-gaga-reveals-plan-to-cover-her-face-again-until-trump-gets-fired-from-office-and-i-feel-free-once-more/
2021-11-24 19:05:36,906 18172 news_content_collection ERROR Exception in getting data from url http://dailyfeed.news/san-juan-city-council-votes-unanimously-to-impeach-trump-hating-mayor/
Traceback (most recent call last):
  File "C:\Users\User\Desktop\ia2\FakeNewsNet\code\news_content_collection.py", line 49, in crawl_link_article
    article.parse()
  File "C:\Users\User\AppData\Local\Packages\PythonSoftwareFoundation.Python.3.9_qbz5n2kfra8p0\LocalCache\local-packages\Python39\site-packages\newspaper\article.py", line 191, in parse
    self.throw_if_not_downloaded_verbose()
  File "C:\Users\User\AppData\Local\Packages\PythonSoftwareFoundation.Python.3.9_qbz5n2kfra8p0\LocalCache\local-packages\Python39\site-packages\newspaper\article.py", line 531, in throw_if_not_downloaded_verbose
    raise ArticleException('Article `download()` failed with %s on URL %s' %
newspaper.article.ArticleException: Article `download()` failed with 404 Client Error: Not Found for url: https://cde.news/newsfeed/san-juan-city-council-votes-unanimously-to-impeach-trump-hating-mayor on URL http://dailyfeed.news/san-juan-city-council-votes-unanimously-to-impeach-trump-hating-mayor/
2021-11-24 19:06:00,578 18172 news_content_collection ERROR Exception in getting data from url https://www.helloforos.com/t/miss-universe-guayana-2016-arrestada-con-2kilos-en-london-airport/231910
Traceback (most recent call last):
  File "C:\Users\User\Desktop\ia2\FakeNewsNet\code\news_content_collection.py", line 49, in crawl_link_article
    article.parse()
  File "C:\Users\User\AppData\Local\Packages\PythonSoftwareFoundation.Python.3.9_qbz5n2kfra8p0\LocalCache\local-packages\Python39\site-packages\newspaper\article.py", line 191, in parse
    self.throw_if_not_downloaded_verbose()
  File "C:\Users\User\AppData\Local\Packages\PythonSoftwareFoundation.Python.3.9_qbz5n2kfra8p0\LocalCache\local-packages\Python39\site-packages\newspaper\article.py", line 531, in throw_if_not_downloaded_verbose
    raise ArticleException('Article `download()` failed with %s on URL %s' %
newspaper.article.ArticleException: Article `download()` failed with HTTPSConnectionPool(host='www.helloforos.com', port=443): Max retries exceeded with url: /t/miss-universe-guayana-2016-arrestada-con-2kilos-en-london-airport/231910 (Caused by NewConnectionError('<urllib3.connection.VerifiedHTTPSConnection object at 0x000001C9C2C79EE0>: Failed to establish a new connection: [Errno 11001] getaddrinfo failed')) on URL https://www.helloforos.com/t/miss-universe-guayana-2016-arrestada-con-2kilos-en-london-airport/231910
2021-11-24 19:06:22,947 18172 news_content_collection ERROR Exception in fetching article form URL : 
Traceback (most recent call last):
  File "C:\Users\User\Desktop\ia2\FakeNewsNet\code\news_content_collection.py", line 19, in crawl_link_article
    if url[0] == '/':
IndexError: string index out of range
2021-11-24 19:06:26,877 18172 news_content_collection ERROR Exception in getting data from url https://web.archive.org/web/20180808123333/http://http:///
Traceback (most recent call last):
  File "C:\Users\User\Desktop\ia2\FakeNewsNet\code\news_content_collection.py", line 49, in crawl_link_article
    article.parse()
  File "C:\Users\User\AppData\Local\Packages\PythonSoftwareFoundation.Python.3.9_qbz5n2kfra8p0\LocalCache\local-packages\Python39\site-packages\newspaper\article.py", line 191, in parse
    self.throw_if_not_downloaded_verbose()
  File "C:\Users\User\AppData\Local\Packages\PythonSoftwareFoundation.Python.3.9_qbz5n2kfra8p0\LocalCache\local-packages\Python39\site-packages\newspaper\article.py", line 531, in throw_if_not_downloaded_verbose
    raise ArticleException('Article `download()` failed with %s on URL %s' %
newspaper.article.ArticleException: Article `download()` failed with 400 Client Error: Bad Request for url: https://web.archive.org/web/20191006182526/http://.../ on URL https://web.archive.org/web/20180808123333/http://http:///
2021-11-24 19:06:29,191 18172 news_content_collection ERROR Exception in getting data from url https://dailyworldupdate.us/2018/05/18/breaking-santa-fe-killer-confesses-his-love-for-obama/
Traceback (most recent call last):
  File "C:\Users\User\Desktop\ia2\FakeNewsNet\code\news_content_collection.py", line 49, in crawl_link_article
    article.parse()
  File "C:\Users\User\AppData\Local\Packages\PythonSoftwareFoundation.Python.3.9_qbz5n2kfra8p0\LocalCache\local-packages\Python39\site-packages\newspaper\article.py", line 191, in parse
    self.throw_if_not_downloaded_verbose()
  File "C:\Users\User\AppData\Local\Packages\PythonSoftwareFoundation.Python.3.9_qbz5n2kfra8p0\LocalCache\local-packages\Python39\site-packages\newspaper\article.py", line 531, in throw_if_not_downloaded_verbose
    raise ArticleException('Article `download()` failed with %s on URL %s' %
newspaper.article.ArticleException: Article `download()` failed with ('Connection aborted.', ConnectionResetError(10054, 'An existing connection was forcibly closed by the remote host', None, 10054, None)) on URL https://dailyworldupdate.us/2018/05/18/breaking-santa-fe-killer-confesses-his-love-for-obama/
2021-11-24 19:06:50,235 18172 news_content_collection ERROR Exception in getting data from url http://politicono.com/pence-michelle-obama-vulgar-first-lady-weve-ever/
Traceback (most recent call last):
  File "C:\Users\User\Desktop\ia2\FakeNewsNet\code\news_content_collection.py", line 49, in crawl_link_article
    article.parse()
  File "C:\Users\User\AppData\Local\Packages\PythonSoftwareFoundation.Python.3.9_qbz5n2kfra8p0\LocalCache\local-packages\Python39\site-packages\newspaper\article.py", line 191, in parse
    self.throw_if_not_downloaded_verbose()
  File "C:\Users\User\AppData\Local\Packages\PythonSoftwareFoundation.Python.3.9_qbz5n2kfra8p0\LocalCache\local-packages\Python39\site-packages\newspaper\article.py", line 531, in throw_if_not_downloaded_verbose
    raise ArticleException('Article `download()` failed with %s on URL %s' %
newspaper.article.ArticleException: Article `download()` failed with HTTPConnectionPool(host='politicono.com', port=80): Read timed out. (read timeout=7) on URL http://politicono.com/pence-michelle-obama-vulgar-first-lady-weve-ever/
2021-11-24 19:07:02,753 18172 news_content_collection ERROR Exception in getting data from url https://proconservativenews.com/shaquille-oneal-says-trump-is-possibly-the-best-president-of-the-president-of-all-times-ever-he-is-not-afraid-to/
Traceback (most recent call last):
  File "C:\Users\User\Desktop\ia2\FakeNewsNet\code\news_content_collection.py", line 49, in crawl_link_article
    article.parse()
  File "C:\Users\User\AppData\Local\Packages\PythonSoftwareFoundation.Python.3.9_qbz5n2kfra8p0\LocalCache\local-packages\Python39\site-packages\newspaper\article.py", line 191, in parse
    self.throw_if_not_downloaded_verbose()
  File "C:\Users\User\AppData\Local\Packages\PythonSoftwareFoundation.Python.3.9_qbz5n2kfra8p0\LocalCache\local-packages\Python39\site-packages\newspaper\article.py", line 531, in throw_if_not_downloaded_verbose
    raise ArticleException('Article `download()` failed with %s on URL %s' %
newspaper.article.ArticleException: Article `download()` failed with HTTPSConnectionPool(host='proconservativenews.com', port=443): Max retries exceeded with url: /shaquille-oneal-says-trump-is-possibly-the-best-president-of-the-president-of-all-times-ever-he-is-not-afraid-to/ (Caused by NewConnectionError('<urllib3.connection.VerifiedHTTPSConnection object at 0x000001C9C2C769D0>: Failed to establish a new connection: [Errno 11001] getaddrinfo failed')) on URL https://proconservativenews.com/shaquille-oneal-says-trump-is-possibly-the-best-president-of-the-president-of-all-times-ever-he-is-not-afraid-to/
2021-11-24 19:07:16,061 18172 news_content_collection ERROR Exception in getting data from url http://redstatewave.com/article.asp?id=128635
Traceback (most recent call last):
  File "C:\Users\User\Desktop\ia2\FakeNewsNet\code\news_content_collection.py", line 49, in crawl_link_article
    article.parse()
  File "C:\Users\User\AppData\Local\Packages\PythonSoftwareFoundation.Python.3.9_qbz5n2kfra8p0\LocalCache\local-packages\Python39\site-packages\newspaper\article.py", line 191, in parse
    self.throw_if_not_downloaded_verbose()
  File "C:\Users\User\AppData\Local\Packages\PythonSoftwareFoundation.Python.3.9_qbz5n2kfra8p0\LocalCache\local-packages\Python39\site-packages\newspaper\article.py", line 531, in throw_if_not_downloaded_verbose
    raise ArticleException('Article `download()` failed with %s on URL %s' %
newspaper.article.ArticleException: Article `download()` failed with 404 Client Error: Not Found for url: http://redstatewave.com/article.asp?id=128635 on URL http://redstatewave.com/article.asp?id=128635
2021-11-24 19:08:05,636 18172 news_content_collection ERROR Exception in getting data from url https://www.inspiringday.com/prince_william_may_not_attend_royal_wedding_leaving_prince_harry_without_a_best_man
Traceback (most recent call last):
  File "C:\Users\User\Desktop\ia2\FakeNewsNet\code\news_content_collection.py", line 49, in crawl_link_article
    article.parse()
  File "C:\Users\User\AppData\Local\Packages\PythonSoftwareFoundation.Python.3.9_qbz5n2kfra8p0\LocalCache\local-packages\Python39\site-packages\newspaper\article.py", line 191, in parse
    self.throw_if_not_downloaded_verbose()
  File "C:\Users\User\AppData\Local\Packages\PythonSoftwareFoundation.Python.3.9_qbz5n2kfra8p0\LocalCache\local-packages\Python39\site-packages\newspaper\article.py", line 531, in throw_if_not_downloaded_verbose
    raise ArticleException('Article `download()` failed with %s on URL %s' %
newspaper.article.ArticleException: Article `download()` failed with HTTPSConnectionPool(host='www.inspiringday.com', port=443): Max retries exceeded with url: /prince_william_may_not_attend_royal_wedding_leaving_prince_harry_without_a_best_man (Caused by ConnectTimeoutError(<urllib3.connection.VerifiedHTTPSConnection object at 0x000001C9C2C76790>, 'Connection to www.inspiringday.com timed out. (connect timeout=7)')) on URL https://www.inspiringday.com/prince_william_may_not_attend_royal_wedding_leaving_prince_harry_without_a_best_man
2021-11-24 19:08:18,896 18172 news_content_collection ERROR Exception in getting data from url https://www.ecfr.gov/cgi-bin/text-idx?gp=&SID=b5df8668c5d53fb99d5c5fd1e20c0ab0&mc=true&tpl=/ecfrbrowse/Title05/5tab_02.tpl
Traceback (most recent call last):
  File "C:\Users\User\Desktop\ia2\FakeNewsNet\code\news_content_collection.py", line 49, in crawl_link_article
    article.parse()
  File "C:\Users\User\AppData\Local\Packages\PythonSoftwareFoundation.Python.3.9_qbz5n2kfra8p0\LocalCache\local-packages\Python39\site-packages\newspaper\article.py", line 191, in parse
    self.throw_if_not_downloaded_verbose()
  File "C:\Users\User\AppData\Local\Packages\PythonSoftwareFoundation.Python.3.9_qbz5n2kfra8p0\LocalCache\local-packages\Python39\site-packages\newspaper\article.py", line 531, in throw_if_not_downloaded_verbose
    raise ArticleException('Article `download()` failed with %s on URL %s' %
newspaper.article.ArticleException: Article `download()` failed with 403 Client Error: Forbidden for url: https://www.ecfr.gov/cgi-bin/text-idx?gp=&SID=b5df8668c5d53fb99d5c5fd1e20c0ab0&mc=true&tpl=/ecfrbrowse/Title05/5tab_02.tpl on URL https://www.ecfr.gov/cgi-bin/text-idx?gp=&SID=b5df8668c5d53fb99d5c5fd1e20c0ab0&mc=true&tpl=/ecfrbrowse/Title05/5tab_02.tpl
2021-11-24 19:09:00,684 18172 news_content_collection ERROR Exception in getting data from url http://newsuptoday.com/bombshell-internet-sleuths-just-found-smoking-gun-dems-planning-violence-charlottesville/
Traceback (most recent call last):
  File "C:\Users\User\Desktop\ia2\FakeNewsNet\code\news_content_collection.py", line 49, in crawl_link_article
    article.parse()
  File "C:\Users\User\AppData\Local\Packages\PythonSoftwareFoundation.Python.3.9_qbz5n2kfra8p0\LocalCache\local-packages\Python39\site-packages\newspaper\article.py", line 191, in parse
    self.throw_if_not_downloaded_verbose()
  File "C:\Users\User\AppData\Local\Packages\PythonSoftwareFoundation.Python.3.9_qbz5n2kfra8p0\LocalCache\local-packages\Python39\site-packages\newspaper\article.py", line 531, in throw_if_not_downloaded_verbose
    raise ArticleException('Article `download()` failed with %s on URL %s' %
newspaper.article.ArticleException: Article `download()` failed with 404 Client Error: Not Found for url: http://newsuptoday.com/bombshell-internet-sleuths-just-found-smoking-gun-dems-planning-violence-charlottesville/ on URL http://newsuptoday.com/bombshell-internet-sleuths-just-found-smoking-gun-dems-planning-violence-charlottesville/
2021-11-24 19:09:20,531 18172 news_content_collection ERROR Exception in getting data from url http://info.nct.news/2017/12/30/breaking-fbi-just-raided-the-white-house-high-ranking-officials-thrown-out/
Traceback (most recent call last):
  File "C:\Users\User\Desktop\ia2\FakeNewsNet\code\news_content_collection.py", line 49, in crawl_link_article
    article.parse()
  File "C:\Users\User\AppData\Local\Packages\PythonSoftwareFoundation.Python.3.9_qbz5n2kfra8p0\LocalCache\local-packages\Python39\site-packages\newspaper\article.py", line 191, in parse
    self.throw_if_not_downloaded_verbose()
  File "C:\Users\User\AppData\Local\Packages\PythonSoftwareFoundation.Python.3.9_qbz5n2kfra8p0\LocalCache\local-packages\Python39\site-packages\newspaper\article.py", line 531, in throw_if_not_downloaded_verbose
    raise ArticleException('Article `download()` failed with %s on URL %s' %
newspaper.article.ArticleException: Article `download()` failed with HTTPConnectionPool(host='info.nct.news', port=80): Read timed out. (read timeout=7) on URL http://info.nct.news/2017/12/30/breaking-fbi-just-raided-the-white-house-high-ranking-officials-thrown-out/
2021-11-24 19:09:41,934 18172 news_content_collection ERROR Exception in getting data from url www.newsweek.com/obama-not-trump-may-be-invited-royal-wedding-prince-harry-and-meghan-markle-722899
Traceback (most recent call last):
  File "C:\Users\User\Desktop\ia2\FakeNewsNet\code\news_content_collection.py", line 25, in crawl_link_article
    article.parse()
  File "C:\Users\User\AppData\Local\Packages\PythonSoftwareFoundation.Python.3.9_qbz5n2kfra8p0\LocalCache\local-packages\Python39\site-packages\newspaper\article.py", line 191, in parse
    self.throw_if_not_downloaded_verbose()
  File "C:\Users\User\AppData\Local\Packages\PythonSoftwareFoundation.Python.3.9_qbz5n2kfra8p0\LocalCache\local-packages\Python39\site-packages\newspaper\article.py", line 531, in throw_if_not_downloaded_verbose
    raise ArticleException('Article `download()` failed with %s on URL %s' %
newspaper.article.ArticleException: Article `download()` failed with 403 Client Error: Forbidden for url: https://www.newsweek.com/obama-not-trump-may-be-invited-royal-wedding-prince-harry-and-meghan-markle-722899 on URL http://www.newsweek.com/obama-not-trump-may-be-invited-royal-wedding-prince-harry-and-meghan-markle-722899
2021-11-24 19:09:44,504 18172 news_content_collection ERROR Exception in getting data from url www.newsweek.com/obama-not-trump-may-be-invited-royal-wedding-prince-harry-and-meghan-markle-722899
Traceback (most recent call last):
  File "C:\Users\User\Desktop\ia2\FakeNewsNet\code\news_content_collection.py", line 36, in crawl_link_article
    article.parse()
  File "C:\Users\User\AppData\Local\Packages\PythonSoftwareFoundation.Python.3.9_qbz5n2kfra8p0\LocalCache\local-packages\Python39\site-packages\newspaper\article.py", line 191, in parse
    self.throw_if_not_downloaded_verbose()
  File "C:\Users\User\AppData\Local\Packages\PythonSoftwareFoundation.Python.3.9_qbz5n2kfra8p0\LocalCache\local-packages\Python39\site-packages\newspaper\article.py", line 531, in throw_if_not_downloaded_verbose
    raise ArticleException('Article `download()` failed with %s on URL %s' %
newspaper.article.ArticleException: Article `download()` failed with 403 Client Error: Forbidden for url: https://www.newsweek.com/obama-not-trump-may-be-invited-royal-wedding-prince-harry-and-meghan-markle-722899 on URL https://www.newsweek.com/obama-not-trump-may-be-invited-royal-wedding-prince-harry-and-meghan-markle-722899
2021-11-24 19:09:59,079 18172 news_content_collection ERROR Exception in getting data from url http://www.whathappensintheusa.com/trey-gowdy-breaks-his-silence-after-2-of-his-investigators-are-found-tortured-and-killed/
Traceback (most recent call last):
  File "C:\Users\User\Desktop\ia2\FakeNewsNet\code\news_content_collection.py", line 49, in crawl_link_article
    article.parse()
  File "C:\Users\User\AppData\Local\Packages\PythonSoftwareFoundation.Python.3.9_qbz5n2kfra8p0\LocalCache\local-packages\Python39\site-packages\newspaper\article.py", line 191, in parse
    self.throw_if_not_downloaded_verbose()
  File "C:\Users\User\AppData\Local\Packages\PythonSoftwareFoundation.Python.3.9_qbz5n2kfra8p0\LocalCache\local-packages\Python39\site-packages\newspaper\article.py", line 531, in throw_if_not_downloaded_verbose
    raise ArticleException('Article `download()` failed with %s on URL %s' %
newspaper.article.ArticleException: Article `download()` failed with HTTPConnectionPool(host='www.whathappensintheusa.com', port=80): Max retries exceeded with url: /trey-gowdy-breaks-his-silence-after-2-of-his-investigators-are-found-tortured-and-killed/ (Caused by NewConnectionError('<urllib3.connection.HTTPConnection object at 0x000001C9C2C76490>: Failed to establish a new connection: [Errno 11001] getaddrinfo failed')) on URL http://www.whathappensintheusa.com/trey-gowdy-breaks-his-silence-after-2-of-his-investigators-are-found-tortured-and-killed/
2021-11-24 19:10:30,253 18172 news_content_collection ERROR Exception in fetching article form URL : 
Traceback (most recent call last):
  File "C:\Users\User\Desktop\ia2\FakeNewsNet\code\news_content_collection.py", line 19, in crawl_link_article
    if url[0] == '/':
IndexError: string index out of range
2021-11-24 19:10:34,444 18172 news_content_collection ERROR Exception in getting data from url https://web.archive.org/web/20180808123333/http://http:///
Traceback (most recent call last):
  File "C:\Users\User\Desktop\ia2\FakeNewsNet\code\news_content_collection.py", line 49, in crawl_link_article
    article.parse()
  File "C:\Users\User\AppData\Local\Packages\PythonSoftwareFoundation.Python.3.9_qbz5n2kfra8p0\LocalCache\local-packages\Python39\site-packages\newspaper\article.py", line 191, in parse
    self.throw_if_not_downloaded_verbose()
  File "C:\Users\User\AppData\Local\Packages\PythonSoftwareFoundation.Python.3.9_qbz5n2kfra8p0\LocalCache\local-packages\Python39\site-packages\newspaper\article.py", line 531, in throw_if_not_downloaded_verbose
    raise ArticleException('Article `download()` failed with %s on URL %s' %
newspaper.article.ArticleException: Article `download()` failed with 400 Client Error: Bad Request for url: https://web.archive.org/web/20191006182526/http://.../ on URL https://web.archive.org/web/20180808123333/http://http:///
2021-11-24 19:10:45,500 18172 news_content_collection ERROR Exception in getting data from url http://www.americatb.com/2018/03/29/breaking-trump-just-ended-welfare-for-one-huge-group-for-5-years-let-the-riots-erupt/
Traceback (most recent call last):
  File "C:\Users\User\Desktop\ia2\FakeNewsNet\code\news_content_collection.py", line 49, in crawl_link_article
    article.parse()
  File "C:\Users\User\AppData\Local\Packages\PythonSoftwareFoundation.Python.3.9_qbz5n2kfra8p0\LocalCache\local-packages\Python39\site-packages\newspaper\article.py", line 191, in parse
    self.throw_if_not_downloaded_verbose()
  File "C:\Users\User\AppData\Local\Packages\PythonSoftwareFoundation.Python.3.9_qbz5n2kfra8p0\LocalCache\local-packages\Python39\site-packages\newspaper\article.py", line 531, in throw_if_not_downloaded_verbose
    raise ArticleException('Article `download()` failed with %s on URL %s' %
newspaper.article.ArticleException: Article `download()` failed with HTTPConnectionPool(host='www.americatb.com', port=80): Max retries exceeded with url: /2018/03/29/breaking-trump-just-ended-welfare-for-one-huge-group-for-5-years-let-the-riots-erupt/ (Caused by NewConnectionError('<urllib3.connection.HTTPConnection object at 0x000001C9C2C76220>: Failed to establish a new connection: [Errno 11001] getaddrinfo failed')) on URL http://www.americatb.com/2018/03/29/breaking-trump-just-ended-welfare-for-one-huge-group-for-5-years-let-the-riots-erupt/
2021-11-24 19:10:56,995 18172 news_content_collection ERROR Exception in getting data from url http://yournewswire.com/melania-trump-isis-barron-obama/
Traceback (most recent call last):
  File "C:\Users\User\Desktop\ia2\FakeNewsNet\code\news_content_collection.py", line 49, in crawl_link_article
    article.parse()
  File "C:\Users\User\AppData\Local\Packages\PythonSoftwareFoundation.Python.3.9_qbz5n2kfra8p0\LocalCache\local-packages\Python39\site-packages\newspaper\article.py", line 191, in parse
    self.throw_if_not_downloaded_verbose()
  File "C:\Users\User\AppData\Local\Packages\PythonSoftwareFoundation.Python.3.9_qbz5n2kfra8p0\LocalCache\local-packages\Python39\site-packages\newspaper\article.py", line 531, in throw_if_not_downloaded_verbose
    raise ArticleException('Article `download()` failed with %s on URL %s' %
newspaper.article.ArticleException: Article `download()` failed with 404 Client Error: Not Found for url: http://yournewswire.com/melania-trump-isis-barron-obama/ on URL http://yournewswire.com/melania-trump-isis-barron-obama/
2021-11-24 19:11:31,185 18172 news_content_collection ERROR Exception in getting data from url yournewswire.com/smallville-star-sold-children-rothschilds-clintons/
Traceback (most recent call last):
  File "C:\Users\User\Desktop\ia2\FakeNewsNet\code\news_content_collection.py", line 25, in crawl_link_article
    article.parse()
  File "C:\Users\User\AppData\Local\Packages\PythonSoftwareFoundation.Python.3.9_qbz5n2kfra8p0\LocalCache\local-packages\Python39\site-packages\newspaper\article.py", line 191, in parse
    self.throw_if_not_downloaded_verbose()
  File "C:\Users\User\AppData\Local\Packages\PythonSoftwareFoundation.Python.3.9_qbz5n2kfra8p0\LocalCache\local-packages\Python39\site-packages\newspaper\article.py", line 531, in throw_if_not_downloaded_verbose
    raise ArticleException('Article `download()` failed with %s on URL %s' %
newspaper.article.ArticleException: Article `download()` failed with 404 Client Error: Not Found for url: http://yournewswire.com/smallville-star-sold-children-rothschilds-clintons/ on URL http://yournewswire.com/smallville-star-sold-children-rothschilds-clintons/
2021-11-24 19:11:33,610 18172 news_content_collection ERROR Exception in getting data from url yournewswire.com/smallville-star-sold-children-rothschilds-clintons/
Traceback (most recent call last):
  File "C:\Users\User\Desktop\ia2\FakeNewsNet\code\news_content_collection.py", line 36, in crawl_link_article
    article.parse()
  File "C:\Users\User\AppData\Local\Packages\PythonSoftwareFoundation.Python.3.9_qbz5n2kfra8p0\LocalCache\local-packages\Python39\site-packages\newspaper\article.py", line 191, in parse
    self.throw_if_not_downloaded_verbose()
  File "C:\Users\User\AppData\Local\Packages\PythonSoftwareFoundation.Python.3.9_qbz5n2kfra8p0\LocalCache\local-packages\Python39\site-packages\newspaper\article.py", line 531, in throw_if_not_downloaded_verbose
    raise ArticleException('Article `download()` failed with %s on URL %s' %
newspaper.article.ArticleException: Article `download()` failed with 404 Client Error: Not Found for url: https://yournewswire.com/smallville-star-sold-children-rothschilds-clintons/ on URL https://yournewswire.com/smallville-star-sold-children-rothschilds-clintons/
2021-11-24 19:11:41,086 18172 news_content_collection ERROR Exception in getting data from url https://conservativepost.com/maxine-waters-is-getting-criminally-charged/
Traceback (most recent call last):
  File "C:\Users\User\Desktop\ia2\FakeNewsNet\code\news_content_collection.py", line 49, in crawl_link_article
    article.parse()
  File "C:\Users\User\AppData\Local\Packages\PythonSoftwareFoundation.Python.3.9_qbz5n2kfra8p0\LocalCache\local-packages\Python39\site-packages\newspaper\article.py", line 191, in parse
    self.throw_if_not_downloaded_verbose()
  File "C:\Users\User\AppData\Local\Packages\PythonSoftwareFoundation.Python.3.9_qbz5n2kfra8p0\LocalCache\local-packages\Python39\site-packages\newspaper\article.py", line 531, in throw_if_not_downloaded_verbose
    raise ArticleException('Article `download()` failed with %s on URL %s' %
newspaper.article.ArticleException: Article `download()` failed with 404 Client Error: Not Found for url: https://conservativepost.com/maxine-waters-is-getting-criminally-charged/ on URL https://conservativepost.com/maxine-waters-is-getting-criminally-charged/
2021-11-24 19:12:17,170 18172 news_content_collection ERROR Exception in getting data from url http://news.groopspeak.com/breaking-federal-judge-grants-permission-to-subpoena-trump/
Traceback (most recent call last):
  File "C:\Users\User\Desktop\ia2\FakeNewsNet\code\news_content_collection.py", line 49, in crawl_link_article
    article.parse()
  File "C:\Users\User\AppData\Local\Packages\PythonSoftwareFoundation.Python.3.9_qbz5n2kfra8p0\LocalCache\local-packages\Python39\site-packages\newspaper\article.py", line 191, in parse
    self.throw_if_not_downloaded_verbose()
  File "C:\Users\User\AppData\Local\Packages\PythonSoftwareFoundation.Python.3.9_qbz5n2kfra8p0\LocalCache\local-packages\Python39\site-packages\newspaper\article.py", line 531, in throw_if_not_downloaded_verbose
    raise ArticleException('Article `download()` failed with %s on URL %s' %
newspaper.article.ArticleException: Article `download()` failed with HTTPConnectionPool(host='news.groopspeak.com', port=80): Read timed out. (read timeout=7) on URL http://news.groopspeak.com/breaking-federal-judge-grants-permission-to-subpoena-trump/
2021-11-24 19:12:24,752 18172 news_content_collection ERROR Exception in fetching article form URL : 
Traceback (most recent call last):
  File "C:\Users\User\Desktop\ia2\FakeNewsNet\code\news_content_collection.py", line 19, in crawl_link_article
    if url[0] == '/':
IndexError: string index out of range
2021-11-24 19:12:28,537 18172 news_content_collection ERROR Exception in getting data from url https://web.archive.org/web/20180808123333/http://http:///
Traceback (most recent call last):
  File "C:\Users\User\Desktop\ia2\FakeNewsNet\code\news_content_collection.py", line 49, in crawl_link_article
    article.parse()
  File "C:\Users\User\AppData\Local\Packages\PythonSoftwareFoundation.Python.3.9_qbz5n2kfra8p0\LocalCache\local-packages\Python39\site-packages\newspaper\article.py", line 191, in parse
    self.throw_if_not_downloaded_verbose()
  File "C:\Users\User\AppData\Local\Packages\PythonSoftwareFoundation.Python.3.9_qbz5n2kfra8p0\LocalCache\local-packages\Python39\site-packages\newspaper\article.py", line 531, in throw_if_not_downloaded_verbose
    raise ArticleException('Article `download()` failed with %s on URL %s' %
newspaper.article.ArticleException: Article `download()` failed with 400 Client Error: Bad Request for url: https://web.archive.org/web/20191006182526/http://.../ on URL https://web.archive.org/web/20180808123333/http://http:///
2021-11-24 19:12:33,732 18172 news_content_collection ERROR Exception in getting data from url https://www.infowars.com/pier-39-terrorist-was-an-anti-trump-antifa-supporter/
Traceback (most recent call last):
  File "C:\Users\User\Desktop\ia2\FakeNewsNet\code\news_content_collection.py", line 49, in crawl_link_article
    article.parse()
  File "C:\Users\User\AppData\Local\Packages\PythonSoftwareFoundation.Python.3.9_qbz5n2kfra8p0\LocalCache\local-packages\Python39\site-packages\newspaper\article.py", line 191, in parse
    self.throw_if_not_downloaded_verbose()
  File "C:\Users\User\AppData\Local\Packages\PythonSoftwareFoundation.Python.3.9_qbz5n2kfra8p0\LocalCache\local-packages\Python39\site-packages\newspaper\article.py", line 531, in throw_if_not_downloaded_verbose
    raise ArticleException('Article `download()` failed with %s on URL %s' %
newspaper.article.ArticleException: Article `download()` failed with 404 Client Error: Not Found for url: https://www.infowars.com/pier-39-terrorist-was-an-anti-trump-antifa-supporter/ on URL https://www.infowars.com/pier-39-terrorist-was-an-anti-trump-antifa-supporter/
2021-11-24 19:12:47,064 18172 news_content_collection ERROR Exception in getting data from url usanewscentral.com/bill-clintons-hitman-confesses-on-his-deathbed-source-hannity/
Traceback (most recent call last):
  File "C:\Users\User\Desktop\ia2\FakeNewsNet\code\news_content_collection.py", line 25, in crawl_link_article
    article.parse()
  File "C:\Users\User\AppData\Local\Packages\PythonSoftwareFoundation.Python.3.9_qbz5n2kfra8p0\LocalCache\local-packages\Python39\site-packages\newspaper\article.py", line 191, in parse
    self.throw_if_not_downloaded_verbose()
  File "C:\Users\User\AppData\Local\Packages\PythonSoftwareFoundation.Python.3.9_qbz5n2kfra8p0\LocalCache\local-packages\Python39\site-packages\newspaper\article.py", line 531, in throw_if_not_downloaded_verbose
    raise ArticleException('Article `download()` failed with %s on URL %s' %
newspaper.article.ArticleException: Article `download()` failed with HTTPConnectionPool(host='usanewscentral.com', port=80): Max retries exceeded with url: /bill-clintons-hitman-confesses-on-his-deathbed-source-hannity/ (Caused by ConnectTimeoutError(<urllib3.connection.HTTPConnection object at 0x000001C9C2CA32B0>, 'Connection to usanewscentral.com timed out. (connect timeout=7)')) on URL http://usanewscentral.com/bill-clintons-hitman-confesses-on-his-deathbed-source-hannity/
2021-11-24 19:12:57,251 18172 news_content_collection ERROR Exception in getting data from url usanewscentral.com/bill-clintons-hitman-confesses-on-his-deathbed-source-hannity/
Traceback (most recent call last):
  File "C:\Users\User\Desktop\ia2\FakeNewsNet\code\news_content_collection.py", line 36, in crawl_link_article
    article.parse()
  File "C:\Users\User\AppData\Local\Packages\PythonSoftwareFoundation.Python.3.9_qbz5n2kfra8p0\LocalCache\local-packages\Python39\site-packages\newspaper\article.py", line 191, in parse
    self.throw_if_not_downloaded_verbose()
  File "C:\Users\User\AppData\Local\Packages\PythonSoftwareFoundation.Python.3.9_qbz5n2kfra8p0\LocalCache\local-packages\Python39\site-packages\newspaper\article.py", line 531, in throw_if_not_downloaded_verbose
    raise ArticleException('Article `download()` failed with %s on URL %s' %
newspaper.article.ArticleException: Article `download()` failed with HTTPSConnectionPool(host='usanewscentral.com', port=443): Max retries exceeded with url: /bill-clintons-hitman-confesses-on-his-deathbed-source-hannity/ (Caused by ConnectTimeoutError(<urllib3.connection.VerifiedHTTPSConnection object at 0x000001C9C2C74EB0>, 'Connection to usanewscentral.com timed out. (connect timeout=7)')) on URL https://usanewscentral.com/bill-clintons-hitman-confesses-on-his-deathbed-source-hannity/
2021-11-24 19:12:58,365 18172 news_content_collection ERROR Exception in getting data from url https://web.archive.org/web/20180121041126/http://usanewscentral.com:80/bill-clintons-hitman-confesses-on-his-deathbed-source-hannity
Traceback (most recent call last):
  File "C:\Users\User\Desktop\ia2\FakeNewsNet\code\news_content_collection.py", line 47, in crawl_link_article
    article.download()
  File "C:\Users\User\AppData\Local\Packages\PythonSoftwareFoundation.Python.3.9_qbz5n2kfra8p0\LocalCache\local-packages\Python39\site-packages\newspaper\article.py", line 170, in download
    html = network.get_html_2XX_only(self.url, self.config)
  File "C:\Users\User\AppData\Local\Packages\PythonSoftwareFoundation.Python.3.9_qbz5n2kfra8p0\LocalCache\local-packages\Python39\site-packages\newspaper\network.py", line 62, in get_html_2XX_only
    response = requests.get(
  File "C:\Users\User\AppData\Local\Packages\PythonSoftwareFoundation.Python.3.9_qbz5n2kfra8p0\LocalCache\local-packages\Python39\site-packages\requests\api.py", line 75, in get
    return request('get', url, params=params, **kwargs)
  File "C:\Users\User\AppData\Local\Packages\PythonSoftwareFoundation.Python.3.9_qbz5n2kfra8p0\LocalCache\local-packages\Python39\site-packages\requests\api.py", line 60, in request
    return session.request(method=method, url=url, **kwargs)
  File "C:\Users\User\AppData\Local\Packages\PythonSoftwareFoundation.Python.3.9_qbz5n2kfra8p0\LocalCache\local-packages\Python39\site-packages\requests\sessions.py", line 533, in request
    resp = self.send(prep, **send_kwargs)
  File "C:\Users\User\AppData\Local\Packages\PythonSoftwareFoundation.Python.3.9_qbz5n2kfra8p0\LocalCache\local-packages\Python39\site-packages\requests\sessions.py", line 646, in send
    r = adapter.send(request, **kwargs)
  File "C:\Users\User\AppData\Local\Packages\PythonSoftwareFoundation.Python.3.9_qbz5n2kfra8p0\LocalCache\local-packages\Python39\site-packages\requests\adapters.py", line 439, in send
    resp = conn.urlopen(
  File "C:\Users\User\AppData\Local\Packages\PythonSoftwareFoundation.Python.3.9_qbz5n2kfra8p0\LocalCache\local-packages\Python39\site-packages\urllib3\connectionpool.py", line 597, in urlopen
    httplib_response = self._make_request(conn, method, url,
  File "C:\Users\User\AppData\Local\Packages\PythonSoftwareFoundation.Python.3.9_qbz5n2kfra8p0\LocalCache\local-packages\Python39\site-packages\urllib3\connectionpool.py", line 343, in _make_request
    self._validate_conn(conn)
  File "C:\Users\User\AppData\Local\Packages\PythonSoftwareFoundation.Python.3.9_qbz5n2kfra8p0\LocalCache\local-packages\Python39\site-packages\urllib3\connectionpool.py", line 839, in _validate_conn
    conn.connect()
  File "C:\Users\User\AppData\Local\Packages\PythonSoftwareFoundation.Python.3.9_qbz5n2kfra8p0\LocalCache\local-packages\Python39\site-packages\urllib3\connection.py", line 337, in connect
    self.sock = ssl_wrap_socket(
  File "C:\Users\User\AppData\Local\Packages\PythonSoftwareFoundation.Python.3.9_qbz5n2kfra8p0\LocalCache\local-packages\Python39\site-packages\urllib3\util\ssl_.py", line 344, in ssl_wrap_socket
    return context.wrap_socket(sock, server_hostname=server_hostname)
  File "C:\Program Files\WindowsApps\PythonSoftwareFoundation.Python.3.9_3.9.2544.0_x64__qbz5n2kfra8p0\lib\ssl.py", line 500, in wrap_socket
    return self.sslsocket_class._create(
  File "C:\Program Files\WindowsApps\PythonSoftwareFoundation.Python.3.9_3.9.2544.0_x64__qbz5n2kfra8p0\lib\ssl.py", line 1040, in _create
    self.do_handshake()
  File "C:\Program Files\WindowsApps\PythonSoftwareFoundation.Python.3.9_3.9.2544.0_x64__qbz5n2kfra8p0\lib\ssl.py", line 1309, in do_handshake
    self._sslobj.do_handshake()
KeyboardInterrupt
2021-11-24 19:12:59,441 18172 news_content_collection ERROR Exception in getting data from url http://www.newscats.org/?p=11110
Traceback (most recent call last):
  File "C:\Users\User\Desktop\ia2\FakeNewsNet\code\news_content_collection.py", line 47, in crawl_link_article
    article.download()
  File "C:\Users\User\AppData\Local\Packages\PythonSoftwareFoundation.Python.3.9_qbz5n2kfra8p0\LocalCache\local-packages\Python39\site-packages\newspaper\article.py", line 170, in download
    html = network.get_html_2XX_only(self.url, self.config)
  File "C:\Users\User\AppData\Local\Packages\PythonSoftwareFoundation.Python.3.9_qbz5n2kfra8p0\LocalCache\local-packages\Python39\site-packages\newspaper\network.py", line 62, in get_html_2XX_only
    response = requests.get(
  File "C:\Users\User\AppData\Local\Packages\PythonSoftwareFoundation.Python.3.9_qbz5n2kfra8p0\LocalCache\local-packages\Python39\site-packages\requests\api.py", line 75, in get
    return request('get', url, params=params, **kwargs)
  File "C:\Users\User\AppData\Local\Packages\PythonSoftwareFoundation.Python.3.9_qbz5n2kfra8p0\LocalCache\local-packages\Python39\site-packages\requests\api.py", line 60, in request
    return session.request(method=method, url=url, **kwargs)
  File "C:\Users\User\AppData\Local\Packages\PythonSoftwareFoundation.Python.3.9_qbz5n2kfra8p0\LocalCache\local-packages\Python39\site-packages\requests\sessions.py", line 533, in request
    resp = self.send(prep, **send_kwargs)
  File "C:\Users\User\AppData\Local\Packages\PythonSoftwareFoundation.Python.3.9_qbz5n2kfra8p0\LocalCache\local-packages\Python39\site-packages\requests\sessions.py", line 668, in send
    history = [resp for resp in gen] if allow_redirects else []
  File "C:\Users\User\AppData\Local\Packages\PythonSoftwareFoundation.Python.3.9_qbz5n2kfra8p0\LocalCache\local-packages\Python39\site-packages\requests\sessions.py", line 668, in <listcomp>
    history = [resp for resp in gen] if allow_redirects else []
  File "C:\Users\User\AppData\Local\Packages\PythonSoftwareFoundation.Python.3.9_qbz5n2kfra8p0\LocalCache\local-packages\Python39\site-packages\requests\sessions.py", line 239, in resolve_redirects
    resp = self.send(
  File "C:\Users\User\AppData\Local\Packages\PythonSoftwareFoundation.Python.3.9_qbz5n2kfra8p0\LocalCache\local-packages\Python39\site-packages\requests\sessions.py", line 646, in send
    r = adapter.send(request, **kwargs)
  File "C:\Users\User\AppData\Local\Packages\PythonSoftwareFoundation.Python.3.9_qbz5n2kfra8p0\LocalCache\local-packages\Python39\site-packages\requests\adapters.py", line 439, in send
    resp = conn.urlopen(
  File "C:\Users\User\AppData\Local\Packages\PythonSoftwareFoundation.Python.3.9_qbz5n2kfra8p0\LocalCache\local-packages\Python39\site-packages\urllib3\connectionpool.py", line 597, in urlopen
    httplib_response = self._make_request(conn, method, url,
  File "C:\Users\User\AppData\Local\Packages\PythonSoftwareFoundation.Python.3.9_qbz5n2kfra8p0\LocalCache\local-packages\Python39\site-packages\urllib3\connectionpool.py", line 343, in _make_request
    self._validate_conn(conn)
  File "C:\Users\User\AppData\Local\Packages\PythonSoftwareFoundation.Python.3.9_qbz5n2kfra8p0\LocalCache\local-packages\Python39\site-packages\urllib3\connectionpool.py", line 839, in _validate_conn
    conn.connect()
  File "C:\Users\User\AppData\Local\Packages\PythonSoftwareFoundation.Python.3.9_qbz5n2kfra8p0\LocalCache\local-packages\Python39\site-packages\urllib3\connection.py", line 301, in connect
    conn = self._new_conn()
  File "C:\Users\User\AppData\Local\Packages\PythonSoftwareFoundation.Python.3.9_qbz5n2kfra8p0\LocalCache\local-packages\Python39\site-packages\urllib3\connection.py", line 158, in _new_conn
    conn = connection.create_connection(
  File "C:\Users\User\AppData\Local\Packages\PythonSoftwareFoundation.Python.3.9_qbz5n2kfra8p0\LocalCache\local-packages\Python39\site-packages\urllib3\util\connection.py", line 57, in create_connection
    for res in socket.getaddrinfo(host, port, family, socket.SOCK_STREAM):
  File "C:\Program Files\WindowsApps\PythonSoftwareFoundation.Python.3.9_3.9.2544.0_x64__qbz5n2kfra8p0\lib\socket.py", line 954, in getaddrinfo
    for res in _socket.getaddrinfo(host, port, family, type, proto, flags):
KeyboardInterrupt
2021-11-24 19:13:00,797 18172 news_content_collection ERROR Exception in getting data from url https://web.archive.org/web/20200321102707/https://www.newscats.org/?p=11110
Traceback (most recent call last):
  File "C:\Users\User\AppData\Local\Packages\PythonSoftwareFoundation.Python.3.9_qbz5n2kfra8p0\LocalCache\local-packages\Python39\site-packages\urllib3\connectionpool.py", line 377, in _make_request
    httplib_response = conn.getresponse(buffering=True)
TypeError: getresponse() got an unexpected keyword argument 'buffering'

During handling of the above exception, another exception occurred:

Traceback (most recent call last):
  File "C:\Users\User\Desktop\ia2\FakeNewsNet\code\news_content_collection.py", line 47, in crawl_link_article
    article.download()
  File "C:\Users\User\AppData\Local\Packages\PythonSoftwareFoundation.Python.3.9_qbz5n2kfra8p0\LocalCache\local-packages\Python39\site-packages\newspaper\article.py", line 170, in download
    html = network.get_html_2XX_only(self.url, self.config)
  File "C:\Users\User\AppData\Local\Packages\PythonSoftwareFoundation.Python.3.9_qbz5n2kfra8p0\LocalCache\local-packages\Python39\site-packages\newspaper\network.py", line 62, in get_html_2XX_only
    response = requests.get(
  File "C:\Users\User\AppData\Local\Packages\PythonSoftwareFoundation.Python.3.9_qbz5n2kfra8p0\LocalCache\local-packages\Python39\site-packages\requests\api.py", line 75, in get
    return request('get', url, params=params, **kwargs)
  File "C:\Users\User\AppData\Local\Packages\PythonSoftwareFoundation.Python.3.9_qbz5n2kfra8p0\LocalCache\local-packages\Python39\site-packages\requests\api.py", line 60, in request
    return session.request(method=method, url=url, **kwargs)
  File "C:\Users\User\AppData\Local\Packages\PythonSoftwareFoundation.Python.3.9_qbz5n2kfra8p0\LocalCache\local-packages\Python39\site-packages\requests\sessions.py", line 533, in request
    resp = self.send(prep, **send_kwargs)
  File "C:\Users\User\AppData\Local\Packages\PythonSoftwareFoundation.Python.3.9_qbz5n2kfra8p0\LocalCache\local-packages\Python39\site-packages\requests\sessions.py", line 646, in send
    r = adapter.send(request, **kwargs)
  File "C:\Users\User\AppData\Local\Packages\PythonSoftwareFoundation.Python.3.9_qbz5n2kfra8p0\LocalCache\local-packages\Python39\site-packages\requests\adapters.py", line 439, in send
    resp = conn.urlopen(
  File "C:\Users\User\AppData\Local\Packages\PythonSoftwareFoundation.Python.3.9_qbz5n2kfra8p0\LocalCache\local-packages\Python39\site-packages\urllib3\connectionpool.py", line 597, in urlopen
    httplib_response = self._make_request(conn, method, url,
  File "C:\Users\User\AppData\Local\Packages\PythonSoftwareFoundation.Python.3.9_qbz5n2kfra8p0\LocalCache\local-packages\Python39\site-packages\urllib3\connectionpool.py", line 380, in _make_request
    httplib_response = conn.getresponse()
  File "C:\Program Files\WindowsApps\PythonSoftwareFoundation.Python.3.9_3.9.2544.0_x64__qbz5n2kfra8p0\lib\http\client.py", line 1377, in getresponse
    response.begin()
  File "C:\Program Files\WindowsApps\PythonSoftwareFoundation.Python.3.9_3.9.2544.0_x64__qbz5n2kfra8p0\lib\http\client.py", line 320, in begin
    version, status, reason = self._read_status()
  File "C:\Program Files\WindowsApps\PythonSoftwareFoundation.Python.3.9_3.9.2544.0_x64__qbz5n2kfra8p0\lib\http\client.py", line 281, in _read_status
    line = str(self.fp.readline(_MAXLINE + 1), "iso-8859-1")
  File "C:\Program Files\WindowsApps\PythonSoftwareFoundation.Python.3.9_3.9.2544.0_x64__qbz5n2kfra8p0\lib\socket.py", line 704, in readinto
    return self._sock.recv_into(b)
  File "C:\Program Files\WindowsApps\PythonSoftwareFoundation.Python.3.9_3.9.2544.0_x64__qbz5n2kfra8p0\lib\ssl.py", line 1241, in recv_into
    return self.read(nbytes, buffer)
  File "C:\Program Files\WindowsApps\PythonSoftwareFoundation.Python.3.9_3.9.2544.0_x64__qbz5n2kfra8p0\lib\ssl.py", line 1099, in read
    return self._sslobj.read(len, buffer)
KeyboardInterrupt
2021-11-24 19:13:01,901 18172 news_content_collection ERROR Exception in getting data from url http://wrpm33.com/celebrity/what-adam-sandler-is-saying-about-mormons-6/
Traceback (most recent call last):
  File "C:\Users\User\Desktop\ia2\FakeNewsNet\code\news_content_collection.py", line 48, in crawl_link_article
    time.sleep(2)
KeyboardInterrupt
