2021-11-17 16:59:30,868 19276 news_content_collection ERROR Exception in getting data from url speedtalk.com/forum/viewtopic.php?t=51650
Traceback (most recent call last):
  File "C:\Users\User\Desktop\ia2\FakeNewsNet\code\news_content_collection.py", line 25, in crawl_link_article
    article.parse()
  File "C:\Users\User\AppData\Local\Packages\PythonSoftwareFoundation.Python.3.9_qbz5n2kfra8p0\LocalCache\local-packages\Python39\site-packages\newspaper\article.py", line 191, in parse
    self.throw_if_not_downloaded_verbose()
  File "C:\Users\User\AppData\Local\Packages\PythonSoftwareFoundation.Python.3.9_qbz5n2kfra8p0\LocalCache\local-packages\Python39\site-packages\newspaper\article.py", line 531, in throw_if_not_downloaded_verbose
    raise ArticleException('Article `download()` failed with %s on URL %s' %
newspaper.article.ArticleException: Article `download()` failed with 404 Client Error: Not Found for url: https://www.speed-talk.com/forum/viewtopic.php?t=51650 on URL http://speedtalk.com/forum/viewtopic.php?t=51650
2021-11-17 16:59:35,903 19276 news_content_collection ERROR Exception in getting data from url speedtalk.com/forum/viewtopic.php?t=51650
Traceback (most recent call last):
  File "C:\Users\User\Desktop\ia2\FakeNewsNet\code\news_content_collection.py", line 36, in crawl_link_article
    article.parse()
  File "C:\Users\User\AppData\Local\Packages\PythonSoftwareFoundation.Python.3.9_qbz5n2kfra8p0\LocalCache\local-packages\Python39\site-packages\newspaper\article.py", line 191, in parse
    self.throw_if_not_downloaded_verbose()
  File "C:\Users\User\AppData\Local\Packages\PythonSoftwareFoundation.Python.3.9_qbz5n2kfra8p0\LocalCache\local-packages\Python39\site-packages\newspaper\article.py", line 531, in throw_if_not_downloaded_verbose
    raise ArticleException('Article `download()` failed with %s on URL %s' %
newspaper.article.ArticleException: Article `download()` failed with 404 Client Error: Not Found for url: https://www.speed-talk.com/forum/viewtopic.php?t=51650 on URL https://speedtalk.com/forum/viewtopic.php?t=51650
2021-11-17 16:59:38,614 19276 news_content_collection ERROR Exception in getting data from url politics2020.info/index.php/2018/03/13/court-orders-obama-to-pay-400-million-in-restitution/
Traceback (most recent call last):
  File "C:\Users\User\Desktop\ia2\FakeNewsNet\code\news_content_collection.py", line 25, in crawl_link_article
    article.parse()
  File "C:\Users\User\AppData\Local\Packages\PythonSoftwareFoundation.Python.3.9_qbz5n2kfra8p0\LocalCache\local-packages\Python39\site-packages\newspaper\article.py", line 191, in parse
    self.throw_if_not_downloaded_verbose()
  File "C:\Users\User\AppData\Local\Packages\PythonSoftwareFoundation.Python.3.9_qbz5n2kfra8p0\LocalCache\local-packages\Python39\site-packages\newspaper\article.py", line 531, in throw_if_not_downloaded_verbose
    raise ArticleException('Article `download()` failed with %s on URL %s' %
newspaper.article.ArticleException: Article `download()` failed with HTTPConnectionPool(host='politics2020.info', port=80): Max retries exceeded with url: /index.php/2018/03/13/court-orders-obama-to-pay-400-million-in-restitution/ (Caused by NewConnectionError('<urllib3.connection.HTTPConnection object at 0x000002038B3E7FD0>: Failed to establish a new connection: [Errno 11001] getaddrinfo failed')) on URL http://politics2020.info/index.php/2018/03/13/court-orders-obama-to-pay-400-million-in-restitution/
2021-11-17 16:59:40,650 19276 news_content_collection ERROR Exception in getting data from url politics2020.info/index.php/2018/03/13/court-orders-obama-to-pay-400-million-in-restitution/
Traceback (most recent call last):
  File "C:\Users\User\Desktop\ia2\FakeNewsNet\code\news_content_collection.py", line 36, in crawl_link_article
    article.parse()
  File "C:\Users\User\AppData\Local\Packages\PythonSoftwareFoundation.Python.3.9_qbz5n2kfra8p0\LocalCache\local-packages\Python39\site-packages\newspaper\article.py", line 191, in parse
    self.throw_if_not_downloaded_verbose()
  File "C:\Users\User\AppData\Local\Packages\PythonSoftwareFoundation.Python.3.9_qbz5n2kfra8p0\LocalCache\local-packages\Python39\site-packages\newspaper\article.py", line 531, in throw_if_not_downloaded_verbose
    raise ArticleException('Article `download()` failed with %s on URL %s' %
newspaper.article.ArticleException: Article `download()` failed with HTTPSConnectionPool(host='politics2020.info', port=443): Max retries exceeded with url: /index.php/2018/03/13/court-orders-obama-to-pay-400-million-in-restitution/ (Caused by NewConnectionError('<urllib3.connection.VerifiedHTTPSConnection object at 0x000002038B3E7130>: Failed to establish a new connection: [Errno 11001] getaddrinfo failed')) on URL https://politics2020.info/index.php/2018/03/13/court-orders-obama-to-pay-400-million-in-restitution/
2021-11-17 16:59:43,479 19276 news_content_collection ERROR Exception in getting data from url https://web.archive.org/web/20180831124854/http://politics2020.info/index.php/2018/03/13/court-orders-obama-to-pay-400-million-in-restitution/
Traceback (most recent call last):
  File "C:\Users\User\Desktop\ia2\FakeNewsNet\code\news_content_collection.py", line 48, in crawl_link_article
    time.sleep(2)
KeyboardInterrupt
2021-11-17 16:59:45,774 19276 news_content_collection ERROR Exception in getting data from url www.nscdscamps.org/blog/category/parenting/467344/update-second-roy-moore-accuser-works-for-michelle-obama-right-now-departed
Traceback (most recent call last):
  File "C:\Users\User\AppData\Local\Packages\PythonSoftwareFoundation.Python.3.9_qbz5n2kfra8p0\LocalCache\local-packages\Python39\site-packages\urllib3\connectionpool.py", line 377, in _make_request
    httplib_response = conn.getresponse(buffering=True)
TypeError: getresponse() got an unexpected keyword argument 'buffering'

During handling of the above exception, another exception occurred:

Traceback (most recent call last):
  File "C:\Users\User\Desktop\ia2\FakeNewsNet\code\news_content_collection.py", line 23, in crawl_link_article
    article.download()
  File "C:\Users\User\AppData\Local\Packages\PythonSoftwareFoundation.Python.3.9_qbz5n2kfra8p0\LocalCache\local-packages\Python39\site-packages\newspaper\article.py", line 170, in download
    html = network.get_html_2XX_only(self.url, self.config)
  File "C:\Users\User\AppData\Local\Packages\PythonSoftwareFoundation.Python.3.9_qbz5n2kfra8p0\LocalCache\local-packages\Python39\site-packages\newspaper\network.py", line 62, in get_html_2XX_only
    response = requests.get(
  File "C:\Users\User\AppData\Local\Packages\PythonSoftwareFoundation.Python.3.9_qbz5n2kfra8p0\LocalCache\local-packages\Python39\site-packages\requests\api.py", line 75, in get
    return request('get', url, params=params, **kwargs)
  File "C:\Users\User\AppData\Local\Packages\PythonSoftwareFoundation.Python.3.9_qbz5n2kfra8p0\LocalCache\local-packages\Python39\site-packages\requests\api.py", line 60, in request
    return session.request(method=method, url=url, **kwargs)
  File "C:\Users\User\AppData\Local\Packages\PythonSoftwareFoundation.Python.3.9_qbz5n2kfra8p0\LocalCache\local-packages\Python39\site-packages\requests\sessions.py", line 533, in request
    resp = self.send(prep, **send_kwargs)
  File "C:\Users\User\AppData\Local\Packages\PythonSoftwareFoundation.Python.3.9_qbz5n2kfra8p0\LocalCache\local-packages\Python39\site-packages\requests\sessions.py", line 668, in send
    history = [resp for resp in gen] if allow_redirects else []
  File "C:\Users\User\AppData\Local\Packages\PythonSoftwareFoundation.Python.3.9_qbz5n2kfra8p0\LocalCache\local-packages\Python39\site-packages\requests\sessions.py", line 668, in <listcomp>
    history = [resp for resp in gen] if allow_redirects else []
  File "C:\Users\User\AppData\Local\Packages\PythonSoftwareFoundation.Python.3.9_qbz5n2kfra8p0\LocalCache\local-packages\Python39\site-packages\requests\sessions.py", line 239, in resolve_redirects
    resp = self.send(
  File "C:\Users\User\AppData\Local\Packages\PythonSoftwareFoundation.Python.3.9_qbz5n2kfra8p0\LocalCache\local-packages\Python39\site-packages\requests\sessions.py", line 646, in send
    r = adapter.send(request, **kwargs)
  File "C:\Users\User\AppData\Local\Packages\PythonSoftwareFoundation.Python.3.9_qbz5n2kfra8p0\LocalCache\local-packages\Python39\site-packages\requests\adapters.py", line 439, in send
    resp = conn.urlopen(
  File "C:\Users\User\AppData\Local\Packages\PythonSoftwareFoundation.Python.3.9_qbz5n2kfra8p0\LocalCache\local-packages\Python39\site-packages\urllib3\connectionpool.py", line 597, in urlopen
    httplib_response = self._make_request(conn, method, url,
  File "C:\Users\User\AppData\Local\Packages\PythonSoftwareFoundation.Python.3.9_qbz5n2kfra8p0\LocalCache\local-packages\Python39\site-packages\urllib3\connectionpool.py", line 380, in _make_request
    httplib_response = conn.getresponse()
  File "C:\Program Files\WindowsApps\PythonSoftwareFoundation.Python.3.9_3.9.2032.0_x64__qbz5n2kfra8p0\lib\http\client.py", line 1371, in getresponse
    response.begin()
  File "C:\Program Files\WindowsApps\PythonSoftwareFoundation.Python.3.9_3.9.2032.0_x64__qbz5n2kfra8p0\lib\http\client.py", line 319, in begin
    version, status, reason = self._read_status()
  File "C:\Program Files\WindowsApps\PythonSoftwareFoundation.Python.3.9_3.9.2032.0_x64__qbz5n2kfra8p0\lib\http\client.py", line 280, in _read_status
    line = str(self.fp.readline(_MAXLINE + 1), "iso-8859-1")
  File "C:\Program Files\WindowsApps\PythonSoftwareFoundation.Python.3.9_3.9.2032.0_x64__qbz5n2kfra8p0\lib\socket.py", line 704, in readinto
    return self._sock.recv_into(b)
  File "C:\Program Files\WindowsApps\PythonSoftwareFoundation.Python.3.9_3.9.2032.0_x64__qbz5n2kfra8p0\lib\ssl.py", line 1241, in recv_into
    return self.read(nbytes, buffer)
  File "C:\Program Files\WindowsApps\PythonSoftwareFoundation.Python.3.9_3.9.2032.0_x64__qbz5n2kfra8p0\lib\ssl.py", line 1099, in read
    return self._sslobj.read(len, buffer)
KeyboardInterrupt
2021-11-17 16:59:47,977 19276 news_content_collection ERROR Exception in getting data from url www.nscdscamps.org/blog/category/parenting/467344/update-second-roy-moore-accuser-works-for-michelle-obama-right-now-departed
Traceback (most recent call last):
  File "C:\Users\User\AppData\Local\Packages\PythonSoftwareFoundation.Python.3.9_qbz5n2kfra8p0\LocalCache\local-packages\Python39\site-packages\urllib3\connectionpool.py", line 377, in _make_request
    httplib_response = conn.getresponse(buffering=True)
TypeError: getresponse() got an unexpected keyword argument 'buffering'

During handling of the above exception, another exception occurred:

Traceback (most recent call last):
  File "C:\Users\User\Desktop\ia2\FakeNewsNet\code\news_content_collection.py", line 34, in crawl_link_article
    article.download()
  File "C:\Users\User\AppData\Local\Packages\PythonSoftwareFoundation.Python.3.9_qbz5n2kfra8p0\LocalCache\local-packages\Python39\site-packages\newspaper\article.py", line 170, in download
    html = network.get_html_2XX_only(self.url, self.config)
  File "C:\Users\User\AppData\Local\Packages\PythonSoftwareFoundation.Python.3.9_qbz5n2kfra8p0\LocalCache\local-packages\Python39\site-packages\newspaper\network.py", line 62, in get_html_2XX_only
    response = requests.get(
  File "C:\Users\User\AppData\Local\Packages\PythonSoftwareFoundation.Python.3.9_qbz5n2kfra8p0\LocalCache\local-packages\Python39\site-packages\requests\api.py", line 75, in get
    return request('get', url, params=params, **kwargs)
  File "C:\Users\User\AppData\Local\Packages\PythonSoftwareFoundation.Python.3.9_qbz5n2kfra8p0\LocalCache\local-packages\Python39\site-packages\requests\api.py", line 60, in request
    return session.request(method=method, url=url, **kwargs)
  File "C:\Users\User\AppData\Local\Packages\PythonSoftwareFoundation.Python.3.9_qbz5n2kfra8p0\LocalCache\local-packages\Python39\site-packages\requests\sessions.py", line 533, in request
    resp = self.send(prep, **send_kwargs)
  File "C:\Users\User\AppData\Local\Packages\PythonSoftwareFoundation.Python.3.9_qbz5n2kfra8p0\LocalCache\local-packages\Python39\site-packages\requests\sessions.py", line 668, in send
    history = [resp for resp in gen] if allow_redirects else []
  File "C:\Users\User\AppData\Local\Packages\PythonSoftwareFoundation.Python.3.9_qbz5n2kfra8p0\LocalCache\local-packages\Python39\site-packages\requests\sessions.py", line 668, in <listcomp>
    history = [resp for resp in gen] if allow_redirects else []
  File "C:\Users\User\AppData\Local\Packages\PythonSoftwareFoundation.Python.3.9_qbz5n2kfra8p0\LocalCache\local-packages\Python39\site-packages\requests\sessions.py", line 239, in resolve_redirects
    resp = self.send(
  File "C:\Users\User\AppData\Local\Packages\PythonSoftwareFoundation.Python.3.9_qbz5n2kfra8p0\LocalCache\local-packages\Python39\site-packages\requests\sessions.py", line 646, in send
    r = adapter.send(request, **kwargs)
  File "C:\Users\User\AppData\Local\Packages\PythonSoftwareFoundation.Python.3.9_qbz5n2kfra8p0\LocalCache\local-packages\Python39\site-packages\requests\adapters.py", line 439, in send
    resp = conn.urlopen(
  File "C:\Users\User\AppData\Local\Packages\PythonSoftwareFoundation.Python.3.9_qbz5n2kfra8p0\LocalCache\local-packages\Python39\site-packages\urllib3\connectionpool.py", line 597, in urlopen
    httplib_response = self._make_request(conn, method, url,
  File "C:\Users\User\AppData\Local\Packages\PythonSoftwareFoundation.Python.3.9_qbz5n2kfra8p0\LocalCache\local-packages\Python39\site-packages\urllib3\connectionpool.py", line 380, in _make_request
    httplib_response = conn.getresponse()
  File "C:\Program Files\WindowsApps\PythonSoftwareFoundation.Python.3.9_3.9.2032.0_x64__qbz5n2kfra8p0\lib\http\client.py", line 1371, in getresponse
    response.begin()
  File "C:\Program Files\WindowsApps\PythonSoftwareFoundation.Python.3.9_3.9.2032.0_x64__qbz5n2kfra8p0\lib\http\client.py", line 319, in begin
    version, status, reason = self._read_status()
  File "C:\Program Files\WindowsApps\PythonSoftwareFoundation.Python.3.9_3.9.2032.0_x64__qbz5n2kfra8p0\lib\http\client.py", line 280, in _read_status
    line = str(self.fp.readline(_MAXLINE + 1), "iso-8859-1")
  File "C:\Program Files\WindowsApps\PythonSoftwareFoundation.Python.3.9_3.9.2032.0_x64__qbz5n2kfra8p0\lib\socket.py", line 704, in readinto
    return self._sock.recv_into(b)
  File "C:\Program Files\WindowsApps\PythonSoftwareFoundation.Python.3.9_3.9.2032.0_x64__qbz5n2kfra8p0\lib\ssl.py", line 1241, in recv_into
    return self.read(nbytes, buffer)
  File "C:\Program Files\WindowsApps\PythonSoftwareFoundation.Python.3.9_3.9.2032.0_x64__qbz5n2kfra8p0\lib\ssl.py", line 1099, in read
    return self._sslobj.read(len, buffer)
KeyboardInterrupt
