2021-11-24 19:13:38,881 12820 news_content_collection ERROR Exception in getting data from url speedtalk.com/forum/viewtopic.php?t=51650
Traceback (most recent call last):
  File "C:\Users\User\Desktop\ia2\FakeNewsNet\code\news_content_collection.py", line 25, in crawl_link_article
    article.parse()
  File "C:\Users\User\AppData\Local\Packages\PythonSoftwareFoundation.Python.3.9_qbz5n2kfra8p0\LocalCache\local-packages\Python39\site-packages\newspaper\article.py", line 191, in parse
    self.throw_if_not_downloaded_verbose()
  File "C:\Users\User\AppData\Local\Packages\PythonSoftwareFoundation.Python.3.9_qbz5n2kfra8p0\LocalCache\local-packages\Python39\site-packages\newspaper\article.py", line 531, in throw_if_not_downloaded_verbose
    raise ArticleException('Article `download()` failed with %s on URL %s' %
newspaper.article.ArticleException: Article `download()` failed with 404 Client Error: Not Found for url: https://www.speed-talk.com/forum/viewtopic.php?t=51650 on URL http://speedtalk.com/forum/viewtopic.php?t=51650
2021-11-24 19:13:44,801 12820 news_content_collection ERROR Exception in getting data from url speedtalk.com/forum/viewtopic.php?t=51650
Traceback (most recent call last):
  File "C:\Users\User\Desktop\ia2\FakeNewsNet\code\news_content_collection.py", line 36, in crawl_link_article
    article.parse()
  File "C:\Users\User\AppData\Local\Packages\PythonSoftwareFoundation.Python.3.9_qbz5n2kfra8p0\LocalCache\local-packages\Python39\site-packages\newspaper\article.py", line 191, in parse
    self.throw_if_not_downloaded_verbose()
  File "C:\Users\User\AppData\Local\Packages\PythonSoftwareFoundation.Python.3.9_qbz5n2kfra8p0\LocalCache\local-packages\Python39\site-packages\newspaper\article.py", line 531, in throw_if_not_downloaded_verbose
    raise ArticleException('Article `download()` failed with %s on URL %s' %
newspaper.article.ArticleException: Article `download()` failed with 404 Client Error: Not Found for url: https://www.speed-talk.com/forum/viewtopic.php?t=51650 on URL https://speedtalk.com/forum/viewtopic.php?t=51650
2021-11-24 19:13:47,497 12820 news_content_collection ERROR Exception in getting data from url politics2020.info/index.php/2018/03/13/court-orders-obama-to-pay-400-million-in-restitution/
Traceback (most recent call last):
  File "C:\Users\User\Desktop\ia2\FakeNewsNet\code\news_content_collection.py", line 25, in crawl_link_article
    article.parse()
  File "C:\Users\User\AppData\Local\Packages\PythonSoftwareFoundation.Python.3.9_qbz5n2kfra8p0\LocalCache\local-packages\Python39\site-packages\newspaper\article.py", line 191, in parse
    self.throw_if_not_downloaded_verbose()
  File "C:\Users\User\AppData\Local\Packages\PythonSoftwareFoundation.Python.3.9_qbz5n2kfra8p0\LocalCache\local-packages\Python39\site-packages\newspaper\article.py", line 531, in throw_if_not_downloaded_verbose
    raise ArticleException('Article `download()` failed with %s on URL %s' %
newspaper.article.ArticleException: Article `download()` failed with HTTPConnectionPool(host='politics2020.info', port=80): Max retries exceeded with url: /index.php/2018/03/13/court-orders-obama-to-pay-400-million-in-restitution/ (Caused by NewConnectionError('<urllib3.connection.HTTPConnection object at 0x000001DB5D72EEE0>: Failed to establish a new connection: [Errno 11001] getaddrinfo failed')) on URL http://politics2020.info/index.php/2018/03/13/court-orders-obama-to-pay-400-million-in-restitution/
2021-11-24 19:13:49,531 12820 news_content_collection ERROR Exception in getting data from url politics2020.info/index.php/2018/03/13/court-orders-obama-to-pay-400-million-in-restitution/
Traceback (most recent call last):
  File "C:\Users\User\Desktop\ia2\FakeNewsNet\code\news_content_collection.py", line 36, in crawl_link_article
    article.parse()
  File "C:\Users\User\AppData\Local\Packages\PythonSoftwareFoundation.Python.3.9_qbz5n2kfra8p0\LocalCache\local-packages\Python39\site-packages\newspaper\article.py", line 191, in parse
    self.throw_if_not_downloaded_verbose()
  File "C:\Users\User\AppData\Local\Packages\PythonSoftwareFoundation.Python.3.9_qbz5n2kfra8p0\LocalCache\local-packages\Python39\site-packages\newspaper\article.py", line 531, in throw_if_not_downloaded_verbose
    raise ArticleException('Article `download()` failed with %s on URL %s' %
newspaper.article.ArticleException: Article `download()` failed with HTTPSConnectionPool(host='politics2020.info', port=443): Max retries exceeded with url: /index.php/2018/03/13/court-orders-obama-to-pay-400-million-in-restitution/ (Caused by NewConnectionError('<urllib3.connection.VerifiedHTTPSConnection object at 0x000001DB5D72E0D0>: Failed to establish a new connection: [Errno 11001] getaddrinfo failed')) on URL https://politics2020.info/index.php/2018/03/13/court-orders-obama-to-pay-400-million-in-restitution/
2021-11-24 19:14:28,585 12820 news_content_collection ERROR Exception in getting data from url http://yournewswire.com/youngest-leader-george-soros/
Traceback (most recent call last):
  File "C:\Users\User\Desktop\ia2\FakeNewsNet\code\news_content_collection.py", line 49, in crawl_link_article
    article.parse()
  File "C:\Users\User\AppData\Local\Packages\PythonSoftwareFoundation.Python.3.9_qbz5n2kfra8p0\LocalCache\local-packages\Python39\site-packages\newspaper\article.py", line 191, in parse
    self.throw_if_not_downloaded_verbose()
  File "C:\Users\User\AppData\Local\Packages\PythonSoftwareFoundation.Python.3.9_qbz5n2kfra8p0\LocalCache\local-packages\Python39\site-packages\newspaper\article.py", line 531, in throw_if_not_downloaded_verbose
    raise ArticleException('Article `download()` failed with %s on URL %s' %
newspaper.article.ArticleException: Article `download()` failed with 404 Client Error: Not Found for url: http://yournewswire.com/youngest-leader-george-soros/ on URL http://yournewswire.com/youngest-leader-george-soros/
2021-11-24 19:14:40,835 12820 news_content_collection ERROR Exception in getting data from url http://dailyfeed.news/barack-obama-tweets-sick-attack-on-john-mccain-says-he-should-have-died/
Traceback (most recent call last):
  File "C:\Users\User\Desktop\ia2\FakeNewsNet\code\news_content_collection.py", line 49, in crawl_link_article
    article.parse()
  File "C:\Users\User\AppData\Local\Packages\PythonSoftwareFoundation.Python.3.9_qbz5n2kfra8p0\LocalCache\local-packages\Python39\site-packages\newspaper\article.py", line 191, in parse
    self.throw_if_not_downloaded_verbose()
  File "C:\Users\User\AppData\Local\Packages\PythonSoftwareFoundation.Python.3.9_qbz5n2kfra8p0\LocalCache\local-packages\Python39\site-packages\newspaper\article.py", line 531, in throw_if_not_downloaded_verbose
    raise ArticleException('Article `download()` failed with %s on URL %s' %
newspaper.article.ArticleException: Article `download()` failed with 404 Client Error: Not Found for url: https://cde.news/newsfeed/barack-obama-tweets-sick-attack-on-john-mccain-says-he-should-have-died on URL http://dailyfeed.news/barack-obama-tweets-sick-attack-on-john-mccain-says-he-should-have-died/
2021-11-24 19:14:58,002 12820 news_content_collection ERROR Exception in getting data from url http://therightists.com/gretchen-carlson-the-2nd-amendment-was-written-before-guns-were-invented/
Traceback (most recent call last):
  File "C:\Users\User\Desktop\ia2\FakeNewsNet\code\news_content_collection.py", line 49, in crawl_link_article
    article.parse()
  File "C:\Users\User\AppData\Local\Packages\PythonSoftwareFoundation.Python.3.9_qbz5n2kfra8p0\LocalCache\local-packages\Python39\site-packages\newspaper\article.py", line 191, in parse
    self.throw_if_not_downloaded_verbose()
  File "C:\Users\User\AppData\Local\Packages\PythonSoftwareFoundation.Python.3.9_qbz5n2kfra8p0\LocalCache\local-packages\Python39\site-packages\newspaper\article.py", line 531, in throw_if_not_downloaded_verbose
    raise ArticleException('Article `download()` failed with %s on URL %s' %
newspaper.article.ArticleException: Article `download()` failed with 404 Client Error: Not Found for url: https://therightists.com/gretchen-carlson-the-2nd-amendment-was-written-before-guns-were-invented/ on URL http://therightists.com/gretchen-carlson-the-2nd-amendment-was-written-before-guns-were-invented/
2021-11-24 19:15:05,003 12820 news_content_collection ERROR Exception in getting data from url http://yournewswire.com/pope-francis-jesus-metaphorical/
Traceback (most recent call last):
  File "C:\Users\User\Desktop\ia2\FakeNewsNet\code\news_content_collection.py", line 49, in crawl_link_article
    article.parse()
  File "C:\Users\User\AppData\Local\Packages\PythonSoftwareFoundation.Python.3.9_qbz5n2kfra8p0\LocalCache\local-packages\Python39\site-packages\newspaper\article.py", line 191, in parse
    self.throw_if_not_downloaded_verbose()
  File "C:\Users\User\AppData\Local\Packages\PythonSoftwareFoundation.Python.3.9_qbz5n2kfra8p0\LocalCache\local-packages\Python39\site-packages\newspaper\article.py", line 531, in throw_if_not_downloaded_verbose
    raise ArticleException('Article `download()` failed with %s on URL %s' %
newspaper.article.ArticleException: Article `download()` failed with 404 Client Error: Not Found for url: http://yournewswire.com/pope-francis-jesus-metaphorical/ on URL http://yournewswire.com/pope-francis-jesus-metaphorical/
2021-11-24 19:15:25,781 12820 news_content_collection ERROR Exception in getting data from url http://nrtonline.info/breaking-nancy-pelosi-to-resign-after-new-revelations/
Traceback (most recent call last):
  File "C:\Users\User\Desktop\ia2\FakeNewsNet\code\news_content_collection.py", line 49, in crawl_link_article
    article.parse()
  File "C:\Users\User\AppData\Local\Packages\PythonSoftwareFoundation.Python.3.9_qbz5n2kfra8p0\LocalCache\local-packages\Python39\site-packages\newspaper\article.py", line 191, in parse
    self.throw_if_not_downloaded_verbose()
  File "C:\Users\User\AppData\Local\Packages\PythonSoftwareFoundation.Python.3.9_qbz5n2kfra8p0\LocalCache\local-packages\Python39\site-packages\newspaper\article.py", line 531, in throw_if_not_downloaded_verbose
    raise ArticleException('Article `download()` failed with %s on URL %s' %
newspaper.article.ArticleException: Article `download()` failed with HTTPConnectionPool(host='nrtonline.info', port=80): Max retries exceeded with url: /breaking-nancy-pelosi-to-resign-after-new-revelations/ (Caused by NewConnectionError('<urllib3.connection.HTTPConnection object at 0x000001DB5D31F1C0>: Failed to establish a new connection: [Errno 11001] getaddrinfo failed')) on URL http://nrtonline.info/breaking-nancy-pelosi-to-resign-after-new-revelations/
2021-11-24 19:15:37,718 12820 news_content_collection ERROR Exception in getting data from url usaconservativereport.com/2017/08/breaking-leaked-picture-obama-dragged-judge-handcuffs-wiretapping-trump/
Traceback (most recent call last):
  File "C:\Users\User\Desktop\ia2\FakeNewsNet\code\news_content_collection.py", line 25, in crawl_link_article
    article.parse()
  File "C:\Users\User\AppData\Local\Packages\PythonSoftwareFoundation.Python.3.9_qbz5n2kfra8p0\LocalCache\local-packages\Python39\site-packages\newspaper\article.py", line 191, in parse
    self.throw_if_not_downloaded_verbose()
  File "C:\Users\User\AppData\Local\Packages\PythonSoftwareFoundation.Python.3.9_qbz5n2kfra8p0\LocalCache\local-packages\Python39\site-packages\newspaper\article.py", line 531, in throw_if_not_downloaded_verbose
    raise ArticleException('Article `download()` failed with %s on URL %s' %
newspaper.article.ArticleException: Article `download()` failed with HTTPConnectionPool(host='usaconservativereport.com', port=80): Max retries exceeded with url: /2017/08/breaking-leaked-picture-obama-dragged-judge-handcuffs-wiretapping-trump/ (Caused by NewConnectionError('<urllib3.connection.HTTPConnection object at 0x000001DB5D3D7400>: Failed to establish a new connection: [Errno 11001] getaddrinfo failed')) on URL http://usaconservativereport.com/2017/08/breaking-leaked-picture-obama-dragged-judge-handcuffs-wiretapping-trump/
2021-11-24 19:15:39,936 12820 news_content_collection ERROR Exception in getting data from url usaconservativereport.com/2017/08/breaking-leaked-picture-obama-dragged-judge-handcuffs-wiretapping-trump/
Traceback (most recent call last):
  File "C:\Users\User\Desktop\ia2\FakeNewsNet\code\news_content_collection.py", line 36, in crawl_link_article
    article.parse()
  File "C:\Users\User\AppData\Local\Packages\PythonSoftwareFoundation.Python.3.9_qbz5n2kfra8p0\LocalCache\local-packages\Python39\site-packages\newspaper\article.py", line 191, in parse
    self.throw_if_not_downloaded_verbose()
  File "C:\Users\User\AppData\Local\Packages\PythonSoftwareFoundation.Python.3.9_qbz5n2kfra8p0\LocalCache\local-packages\Python39\site-packages\newspaper\article.py", line 531, in throw_if_not_downloaded_verbose
    raise ArticleException('Article `download()` failed with %s on URL %s' %
newspaper.article.ArticleException: Article `download()` failed with HTTPSConnectionPool(host='usaconservativereport.com', port=443): Max retries exceeded with url: /2017/08/breaking-leaked-picture-obama-dragged-judge-handcuffs-wiretapping-trump/ (Caused by NewConnectionError('<urllib3.connection.VerifiedHTTPSConnection object at 0x000001DB5D3D7340>: Failed to establish a new connection: [Errno 11001] getaddrinfo failed')) on URL https://usaconservativereport.com/2017/08/breaking-leaked-picture-obama-dragged-judge-handcuffs-wiretapping-trump/
2021-11-24 19:15:47,808 12820 news_content_collection ERROR Exception in getting data from url https://www.puppetstringnews.com/blog/clinton-campaign-official-arrested-by-fbi-on-child-rapetrafficking-charges
Traceback (most recent call last):
  File "C:\Users\User\Desktop\ia2\FakeNewsNet\code\news_content_collection.py", line 49, in crawl_link_article
    article.parse()
  File "C:\Users\User\AppData\Local\Packages\PythonSoftwareFoundation.Python.3.9_qbz5n2kfra8p0\LocalCache\local-packages\Python39\site-packages\newspaper\article.py", line 191, in parse
    self.throw_if_not_downloaded_verbose()
  File "C:\Users\User\AppData\Local\Packages\PythonSoftwareFoundation.Python.3.9_qbz5n2kfra8p0\LocalCache\local-packages\Python39\site-packages\newspaper\article.py", line 531, in throw_if_not_downloaded_verbose
    raise ArticleException('Article `download()` failed with %s on URL %s' %
newspaper.article.ArticleException: Article `download()` failed with 404 Client Error: Not Found for url: https://puppetstringnews.com/blog/clinton-campaign-official-arrested-by-fbi-on-child-rapetrafficking-charges on URL https://www.puppetstringnews.com/blog/clinton-campaign-official-arrested-by-fbi-on-child-rapetrafficking-charges
2021-11-24 19:15:54,282 12820 news_content_collection ERROR Exception in getting data from url donaldtrainews.blogspot.com/2017/11/breaking-rosa-parks-granddaughter-slams.html
Traceback (most recent call last):
  File "C:\Users\User\Desktop\ia2\FakeNewsNet\code\news_content_collection.py", line 25, in crawl_link_article
    article.parse()
  File "C:\Users\User\AppData\Local\Packages\PythonSoftwareFoundation.Python.3.9_qbz5n2kfra8p0\LocalCache\local-packages\Python39\site-packages\newspaper\article.py", line 191, in parse
    self.throw_if_not_downloaded_verbose()
  File "C:\Users\User\AppData\Local\Packages\PythonSoftwareFoundation.Python.3.9_qbz5n2kfra8p0\LocalCache\local-packages\Python39\site-packages\newspaper\article.py", line 531, in throw_if_not_downloaded_verbose
    raise ArticleException('Article `download()` failed with %s on URL %s' %
newspaper.article.ArticleException: Article `download()` failed with 404 Client Error: Not Found for url: http://donaldtrainews.blogspot.com/2017/11/breaking-rosa-parks-granddaughter-slams.html on URL http://donaldtrainews.blogspot.com/2017/11/breaking-rosa-parks-granddaughter-slams.html
2021-11-24 19:15:57,471 12820 news_content_collection ERROR Exception in getting data from url donaldtrainews.blogspot.com/2017/11/breaking-rosa-parks-granddaughter-slams.html
Traceback (most recent call last):
  File "C:\Users\User\Desktop\ia2\FakeNewsNet\code\news_content_collection.py", line 36, in crawl_link_article
    article.parse()
  File "C:\Users\User\AppData\Local\Packages\PythonSoftwareFoundation.Python.3.9_qbz5n2kfra8p0\LocalCache\local-packages\Python39\site-packages\newspaper\article.py", line 191, in parse
    self.throw_if_not_downloaded_verbose()
  File "C:\Users\User\AppData\Local\Packages\PythonSoftwareFoundation.Python.3.9_qbz5n2kfra8p0\LocalCache\local-packages\Python39\site-packages\newspaper\article.py", line 531, in throw_if_not_downloaded_verbose
    raise ArticleException('Article `download()` failed with %s on URL %s' %
newspaper.article.ArticleException: Article `download()` failed with 404 Client Error: Not Found for url: https://donaldtrainews.blogspot.com/2017/11/breaking-rosa-parks-granddaughter-slams.html on URL https://donaldtrainews.blogspot.com/2017/11/breaking-rosa-parks-granddaughter-slams.html
2021-11-24 19:16:18,243 12820 news_content_collection ERROR Exception in getting data from url http://yournewswire.com/clinton-email-we-must-destroy-syria-for-israel/
Traceback (most recent call last):
  File "C:\Users\User\Desktop\ia2\FakeNewsNet\code\news_content_collection.py", line 49, in crawl_link_article
    article.parse()
  File "C:\Users\User\AppData\Local\Packages\PythonSoftwareFoundation.Python.3.9_qbz5n2kfra8p0\LocalCache\local-packages\Python39\site-packages\newspaper\article.py", line 191, in parse
    self.throw_if_not_downloaded_verbose()
  File "C:\Users\User\AppData\Local\Packages\PythonSoftwareFoundation.Python.3.9_qbz5n2kfra8p0\LocalCache\local-packages\Python39\site-packages\newspaper\article.py", line 531, in throw_if_not_downloaded_verbose
    raise ArticleException('Article `download()` failed with %s on URL %s' %
newspaper.article.ArticleException: Article `download()` failed with 404 Client Error: Not Found for url: http://yournewswire.com/clinton-email-we-must-destroy-syria-for-israel/ on URL http://yournewswire.com/clinton-email-we-must-destroy-syria-for-israel/
2021-11-24 19:16:24,832 12820 news_content_collection ERROR Exception in getting data from url https://quickening-spirit.com/fareed-zakaria-calls-for-jihad-rape-of-white-women/
Traceback (most recent call last):
  File "C:\Users\User\Desktop\ia2\FakeNewsNet\code\news_content_collection.py", line 49, in crawl_link_article
    article.parse()
  File "C:\Users\User\AppData\Local\Packages\PythonSoftwareFoundation.Python.3.9_qbz5n2kfra8p0\LocalCache\local-packages\Python39\site-packages\newspaper\article.py", line 191, in parse
    self.throw_if_not_downloaded_verbose()
  File "C:\Users\User\AppData\Local\Packages\PythonSoftwareFoundation.Python.3.9_qbz5n2kfra8p0\LocalCache\local-packages\Python39\site-packages\newspaper\article.py", line 531, in throw_if_not_downloaded_verbose
    raise ArticleException('Article `download()` failed with %s on URL %s' %
newspaper.article.ArticleException: Article `download()` failed with HTTPSConnectionPool(host='quickening-spirit.com', port=443): Max retries exceeded with url: /fareed-zakaria-calls-for-jihad-rape-of-white-women/ (Caused by SSLError(SSLCertVerificationError(1, '[SSL: CERTIFICATE_VERIFY_FAILED] certificate verify failed: self signed certificate in certificate chain (_ssl.c:1129)'))) on URL https://quickening-spirit.com/fareed-zakaria-calls-for-jihad-rape-of-white-women/
2021-11-24 19:16:32,349 12820 news_content_collection ERROR Exception in getting data from url www.newsweek.com/president-donald-trump-kim-jong-un-nobel-peace-prize-north-korea-south-korea-905146
Traceback (most recent call last):
  File "C:\Users\User\Desktop\ia2\FakeNewsNet\code\news_content_collection.py", line 25, in crawl_link_article
    article.parse()
  File "C:\Users\User\AppData\Local\Packages\PythonSoftwareFoundation.Python.3.9_qbz5n2kfra8p0\LocalCache\local-packages\Python39\site-packages\newspaper\article.py", line 191, in parse
    self.throw_if_not_downloaded_verbose()
  File "C:\Users\User\AppData\Local\Packages\PythonSoftwareFoundation.Python.3.9_qbz5n2kfra8p0\LocalCache\local-packages\Python39\site-packages\newspaper\article.py", line 531, in throw_if_not_downloaded_verbose
    raise ArticleException('Article `download()` failed with %s on URL %s' %
newspaper.article.ArticleException: Article `download()` failed with 403 Client Error: Forbidden for url: https://www.newsweek.com/president-donald-trump-kim-jong-un-nobel-peace-prize-north-korea-south-korea-905146 on URL http://www.newsweek.com/president-donald-trump-kim-jong-un-nobel-peace-prize-north-korea-south-korea-905146
2021-11-24 19:16:34,907 12820 news_content_collection ERROR Exception in getting data from url www.newsweek.com/president-donald-trump-kim-jong-un-nobel-peace-prize-north-korea-south-korea-905146
Traceback (most recent call last):
  File "C:\Users\User\Desktop\ia2\FakeNewsNet\code\news_content_collection.py", line 36, in crawl_link_article
    article.parse()
  File "C:\Users\User\AppData\Local\Packages\PythonSoftwareFoundation.Python.3.9_qbz5n2kfra8p0\LocalCache\local-packages\Python39\site-packages\newspaper\article.py", line 191, in parse
    self.throw_if_not_downloaded_verbose()
  File "C:\Users\User\AppData\Local\Packages\PythonSoftwareFoundation.Python.3.9_qbz5n2kfra8p0\LocalCache\local-packages\Python39\site-packages\newspaper\article.py", line 531, in throw_if_not_downloaded_verbose
    raise ArticleException('Article `download()` failed with %s on URL %s' %
newspaper.article.ArticleException: Article `download()` failed with 403 Client Error: Forbidden for url: https://www.newsweek.com/president-donald-trump-kim-jong-un-nobel-peace-prize-north-korea-south-korea-905146 on URL https://www.newsweek.com/president-donald-trump-kim-jong-un-nobel-peace-prize-north-korea-south-korea-905146
2021-11-24 19:16:42,475 12820 news_content_collection ERROR Exception in getting data from url www.usacarry.com/forums/politics-and-news/62789-update-hillary-clinton-leaves-country-mueller-indictment-announced.html
Traceback (most recent call last):
  File "C:\Users\User\Desktop\ia2\FakeNewsNet\code\news_content_collection.py", line 25, in crawl_link_article
    article.parse()
  File "C:\Users\User\AppData\Local\Packages\PythonSoftwareFoundation.Python.3.9_qbz5n2kfra8p0\LocalCache\local-packages\Python39\site-packages\newspaper\article.py", line 191, in parse
    self.throw_if_not_downloaded_verbose()
  File "C:\Users\User\AppData\Local\Packages\PythonSoftwareFoundation.Python.3.9_qbz5n2kfra8p0\LocalCache\local-packages\Python39\site-packages\newspaper\article.py", line 531, in throw_if_not_downloaded_verbose
    raise ArticleException('Article `download()` failed with %s on URL %s' %
newspaper.article.ArticleException: Article `download()` failed with 403 Client Error: Forbidden for url: https://forums.usacarry.com/politics-and-news/62789-update-hillary-clinton-leaves-country-mueller-indictment-announced.html on URL http://www.usacarry.com/forums/politics-and-news/62789-update-hillary-clinton-leaves-country-mueller-indictment-announced.html
2021-11-24 19:16:45,193 12820 news_content_collection ERROR Exception in getting data from url www.usacarry.com/forums/politics-and-news/62789-update-hillary-clinton-leaves-country-mueller-indictment-announced.html
Traceback (most recent call last):
  File "C:\Users\User\Desktop\ia2\FakeNewsNet\code\news_content_collection.py", line 36, in crawl_link_article
    article.parse()
  File "C:\Users\User\AppData\Local\Packages\PythonSoftwareFoundation.Python.3.9_qbz5n2kfra8p0\LocalCache\local-packages\Python39\site-packages\newspaper\article.py", line 191, in parse
    self.throw_if_not_downloaded_verbose()
  File "C:\Users\User\AppData\Local\Packages\PythonSoftwareFoundation.Python.3.9_qbz5n2kfra8p0\LocalCache\local-packages\Python39\site-packages\newspaper\article.py", line 531, in throw_if_not_downloaded_verbose
    raise ArticleException('Article `download()` failed with %s on URL %s' %
newspaper.article.ArticleException: Article `download()` failed with 403 Client Error: Forbidden for url: https://forums.usacarry.com/politics-and-news/62789-update-hillary-clinton-leaves-country-mueller-indictment-announced.html on URL https://www.usacarry.com/forums/politics-and-news/62789-update-hillary-clinton-leaves-country-mueller-indictment-announced.html
2021-11-24 19:17:01,688 12820 news_content_collection ERROR Exception in getting data from url www.smoaky.com/forum/index.php?/topic/161489-barrels-removed-from-clinton-property-contain-parts-from-3-missing-women/
Traceback (most recent call last):
  File "C:\Users\User\Desktop\ia2\FakeNewsNet\code\news_content_collection.py", line 25, in crawl_link_article
    article.parse()
  File "C:\Users\User\AppData\Local\Packages\PythonSoftwareFoundation.Python.3.9_qbz5n2kfra8p0\LocalCache\local-packages\Python39\site-packages\newspaper\article.py", line 191, in parse
    self.throw_if_not_downloaded_verbose()
  File "C:\Users\User\AppData\Local\Packages\PythonSoftwareFoundation.Python.3.9_qbz5n2kfra8p0\LocalCache\local-packages\Python39\site-packages\newspaper\article.py", line 531, in throw_if_not_downloaded_verbose
    raise ArticleException('Article `download()` failed with %s on URL %s' %
newspaper.article.ArticleException: Article `download()` failed with 403 Client Error: Forbidden for url: http://www.smoaky.com/forum/index.php?/topic/161489-barrels-removed-from-clinton-property-contain-parts-from-3-missing-women/ on URL http://www.smoaky.com/forum/index.php?/topic/161489-barrels-removed-from-clinton-property-contain-parts-from-3-missing-women/
2021-11-24 19:17:03,953 12820 news_content_collection ERROR Exception in getting data from url www.smoaky.com/forum/index.php?/topic/161489-barrels-removed-from-clinton-property-contain-parts-from-3-missing-women/
Traceback (most recent call last):
  File "C:\Users\User\Desktop\ia2\FakeNewsNet\code\news_content_collection.py", line 36, in crawl_link_article
    article.parse()
  File "C:\Users\User\AppData\Local\Packages\PythonSoftwareFoundation.Python.3.9_qbz5n2kfra8p0\LocalCache\local-packages\Python39\site-packages\newspaper\article.py", line 191, in parse
    self.throw_if_not_downloaded_verbose()
  File "C:\Users\User\AppData\Local\Packages\PythonSoftwareFoundation.Python.3.9_qbz5n2kfra8p0\LocalCache\local-packages\Python39\site-packages\newspaper\article.py", line 531, in throw_if_not_downloaded_verbose
    raise ArticleException('Article `download()` failed with %s on URL %s' %
newspaper.article.ArticleException: Article `download()` failed with 403 Client Error: Forbidden for url: https://www.smoaky.com/forum/index.php?/topic/161489-barrels-removed-from-clinton-property-contain-parts-from-3-missing-women/ on URL https://www.smoaky.com/forum/index.php?/topic/161489-barrels-removed-from-clinton-property-contain-parts-from-3-missing-women/
2021-11-24 19:17:07,507 12820 news_content_collection ERROR Exception in getting data from url http://londonwebnews.com/2017/06/01/liberal-women-hate-me-because-of-my-striking-beauty-and-intellect-says-kellyanne-conway/
Traceback (most recent call last):
  File "C:\Users\User\Desktop\ia2\FakeNewsNet\code\news_content_collection.py", line 49, in crawl_link_article
    article.parse()
  File "C:\Users\User\AppData\Local\Packages\PythonSoftwareFoundation.Python.3.9_qbz5n2kfra8p0\LocalCache\local-packages\Python39\site-packages\newspaper\article.py", line 191, in parse
    self.throw_if_not_downloaded_verbose()
  File "C:\Users\User\AppData\Local\Packages\PythonSoftwareFoundation.Python.3.9_qbz5n2kfra8p0\LocalCache\local-packages\Python39\site-packages\newspaper\article.py", line 531, in throw_if_not_downloaded_verbose
    raise ArticleException('Article `download()` failed with %s on URL %s' %
newspaper.article.ArticleException: Article `download()` failed with 404 Client Error: Not Found for url: http://londonwebnews.com/2017/06/01/liberal-women-hate-me-because-of-my-striking-beauty-and-intellect-says-kellyanne-conway/ on URL http://londonwebnews.com/2017/06/01/liberal-women-hate-me-because-of-my-striking-beauty-and-intellect-says-kellyanne-conway/
2021-11-24 19:17:41,731 12820 news_content_collection ERROR Exception in getting data from url https://yournewswire.com/broward-county-sheriff-fired/
Traceback (most recent call last):
  File "C:\Users\User\Desktop\ia2\FakeNewsNet\code\news_content_collection.py", line 49, in crawl_link_article
    article.parse()
  File "C:\Users\User\AppData\Local\Packages\PythonSoftwareFoundation.Python.3.9_qbz5n2kfra8p0\LocalCache\local-packages\Python39\site-packages\newspaper\article.py", line 191, in parse
    self.throw_if_not_downloaded_verbose()
  File "C:\Users\User\AppData\Local\Packages\PythonSoftwareFoundation.Python.3.9_qbz5n2kfra8p0\LocalCache\local-packages\Python39\site-packages\newspaper\article.py", line 531, in throw_if_not_downloaded_verbose
    raise ArticleException('Article `download()` failed with %s on URL %s' %
newspaper.article.ArticleException: Article `download()` failed with 404 Client Error: Not Found for url: https://yournewswire.com/broward-county-sheriff-fired/ on URL https://yournewswire.com/broward-county-sheriff-fired/
2021-11-24 19:17:57,488 12820 news_content_collection ERROR Exception in getting data from url http://www.newslo.com/price-better-budget-cancer-patients-die-quickly/
Traceback (most recent call last):
  File "C:\Users\User\Desktop\ia2\FakeNewsNet\code\news_content_collection.py", line 49, in crawl_link_article
    article.parse()
  File "C:\Users\User\AppData\Local\Packages\PythonSoftwareFoundation.Python.3.9_qbz5n2kfra8p0\LocalCache\local-packages\Python39\site-packages\newspaper\article.py", line 191, in parse
    self.throw_if_not_downloaded_verbose()
  File "C:\Users\User\AppData\Local\Packages\PythonSoftwareFoundation.Python.3.9_qbz5n2kfra8p0\LocalCache\local-packages\Python39\site-packages\newspaper\article.py", line 531, in throw_if_not_downloaded_verbose
    raise ArticleException('Article `download()` failed with %s on URL %s' %
newspaper.article.ArticleException: Article `download()` failed with HTTPSConnectionPool(host='newslo.com', port=443): Read timed out. (read timeout=7) on URL http://www.newslo.com/price-better-budget-cancer-patients-die-quickly/
2021-11-24 19:18:04,046 12820 news_content_collection ERROR Exception in getting data from url https://sentinelksmo.org/breaking-greitens-accuser-admits-photo-session-may-dream/
Traceback (most recent call last):
  File "C:\Users\User\Desktop\ia2\FakeNewsNet\code\news_content_collection.py", line 49, in crawl_link_article
    article.parse()
  File "C:\Users\User\AppData\Local\Packages\PythonSoftwareFoundation.Python.3.9_qbz5n2kfra8p0\LocalCache\local-packages\Python39\site-packages\newspaper\article.py", line 191, in parse
    self.throw_if_not_downloaded_verbose()
  File "C:\Users\User\AppData\Local\Packages\PythonSoftwareFoundation.Python.3.9_qbz5n2kfra8p0\LocalCache\local-packages\Python39\site-packages\newspaper\article.py", line 531, in throw_if_not_downloaded_verbose
    raise ArticleException('Article `download()` failed with %s on URL %s' %
newspaper.article.ArticleException: Article `download()` failed with ('Connection aborted.', ConnectionResetError(10054, 'An existing connection was forcibly closed by the remote host', None, 10054, None)) on URL https://sentinelksmo.org/breaking-greitens-accuser-admits-photo-session-may-dream/
2021-11-24 19:18:14,170 12820 news_content_collection ERROR Exception in getting data from url www.christforums.org/topic/4569-pope-francis-to-followers-%E2%80%9Ckoran-and-holy-bible-are-the-same%E2%80%9D/
Traceback (most recent call last):
  File "C:\Users\User\Desktop\ia2\FakeNewsNet\code\news_content_collection.py", line 25, in crawl_link_article
    article.parse()
  File "C:\Users\User\AppData\Local\Packages\PythonSoftwareFoundation.Python.3.9_qbz5n2kfra8p0\LocalCache\local-packages\Python39\site-packages\newspaper\article.py", line 191, in parse
    self.throw_if_not_downloaded_verbose()
  File "C:\Users\User\AppData\Local\Packages\PythonSoftwareFoundation.Python.3.9_qbz5n2kfra8p0\LocalCache\local-packages\Python39\site-packages\newspaper\article.py", line 531, in throw_if_not_downloaded_verbose
    raise ArticleException('Article `download()` failed with %s on URL %s' %
newspaper.article.ArticleException: Article `download()` failed with 404 Client Error: Not Found for url: http://www.christforums.org/topic/4569-pope-francis-to-followers-%E2%80%9Ckoran-and-holy-bible-are-the-same%E2%80%9D/ on URL http://www.christforums.org/topic/4569-pope-francis-to-followers-%E2%80%9Ckoran-and-holy-bible-are-the-same%E2%80%9D/
2021-11-24 19:18:16,816 12820 news_content_collection ERROR Exception in getting data from url www.christforums.org/topic/4569-pope-francis-to-followers-%E2%80%9Ckoran-and-holy-bible-are-the-same%E2%80%9D/
Traceback (most recent call last):
  File "C:\Users\User\Desktop\ia2\FakeNewsNet\code\news_content_collection.py", line 36, in crawl_link_article
    article.parse()
  File "C:\Users\User\AppData\Local\Packages\PythonSoftwareFoundation.Python.3.9_qbz5n2kfra8p0\LocalCache\local-packages\Python39\site-packages\newspaper\article.py", line 191, in parse
    self.throw_if_not_downloaded_verbose()
  File "C:\Users\User\AppData\Local\Packages\PythonSoftwareFoundation.Python.3.9_qbz5n2kfra8p0\LocalCache\local-packages\Python39\site-packages\newspaper\article.py", line 531, in throw_if_not_downloaded_verbose
    raise ArticleException('Article `download()` failed with %s on URL %s' %
newspaper.article.ArticleException: Article `download()` failed with HTTPSConnectionPool(host='www.christforums.org', port=443): Max retries exceeded with url: /topic/4569-pope-francis-to-followers-%E2%80%9Ckoran-and-holy-bible-are-the-same%E2%80%9D/ (Caused by SSLError(SSLCertVerificationError(1, '[SSL: CERTIFICATE_VERIFY_FAILED] certificate verify failed: self signed certificate (_ssl.c:1129)'))) on URL https://www.christforums.org/topic/4569-pope-francis-to-followers-%E2%80%9Ckoran-and-holy-bible-are-the-same%E2%80%9D/
2021-11-24 19:18:24,265 12820 news_content_collection ERROR Exception in getting data from url http://mysteriousearth.club/2018/04/08/cia-release-documents-of-moon-moon-has-more-than-250-million-citizens/
Traceback (most recent call last):
  File "C:\Users\User\Desktop\ia2\FakeNewsNet\code\news_content_collection.py", line 49, in crawl_link_article
    article.parse()
  File "C:\Users\User\AppData\Local\Packages\PythonSoftwareFoundation.Python.3.9_qbz5n2kfra8p0\LocalCache\local-packages\Python39\site-packages\newspaper\article.py", line 191, in parse
    self.throw_if_not_downloaded_verbose()
  File "C:\Users\User\AppData\Local\Packages\PythonSoftwareFoundation.Python.3.9_qbz5n2kfra8p0\LocalCache\local-packages\Python39\site-packages\newspaper\article.py", line 531, in throw_if_not_downloaded_verbose
    raise ArticleException('Article `download()` failed with %s on URL %s' %
newspaper.article.ArticleException: Article `download()` failed with 404 Client Error: Not Found for url: https://mysteriousearth.club/2018/04/08/cia-release-documents-of-moon-moon-has-more-than-250-million-citizens/ on URL http://mysteriousearth.club/2018/04/08/cia-release-documents-of-moon-moon-has-more-than-250-million-citizens/
2021-11-24 19:18:34,970 12820 news_content_collection ERROR Exception in getting data from url https://exclusive103.com/2018/04/30/thousands-killed-as-israel-drops-tactical-nuclear-bomb-on-syria/
Traceback (most recent call last):
  File "C:\Users\User\Desktop\ia2\FakeNewsNet\code\news_content_collection.py", line 49, in crawl_link_article
    article.parse()
  File "C:\Users\User\AppData\Local\Packages\PythonSoftwareFoundation.Python.3.9_qbz5n2kfra8p0\LocalCache\local-packages\Python39\site-packages\newspaper\article.py", line 191, in parse
    self.throw_if_not_downloaded_verbose()
  File "C:\Users\User\AppData\Local\Packages\PythonSoftwareFoundation.Python.3.9_qbz5n2kfra8p0\LocalCache\local-packages\Python39\site-packages\newspaper\article.py", line 531, in throw_if_not_downloaded_verbose
    raise ArticleException('Article `download()` failed with %s on URL %s' %
newspaper.article.ArticleException: Article `download()` failed with HTTPSConnectionPool(host='exclusive103.com', port=443): Max retries exceeded with url: /2018/04/30/thousands-killed-as-israel-drops-tactical-nuclear-bomb-on-syria/ (Caused by NewConnectionError('<urllib3.connection.VerifiedHTTPSConnection object at 0x000001DB5D3E0910>: Failed to establish a new connection: [Errno 11001] getaddrinfo failed')) on URL https://exclusive103.com/2018/04/30/thousands-killed-as-israel-drops-tactical-nuclear-bomb-on-syria/
2021-11-24 19:18:51,392 12820 news_content_collection ERROR Exception in getting data from url sportfella.com/breaking-fox-sports-cancels-nfl-broadcasts-players-respect-flag/
Traceback (most recent call last):
  File "C:\Users\User\Desktop\ia2\FakeNewsNet\code\news_content_collection.py", line 25, in crawl_link_article
    article.parse()
  File "C:\Users\User\AppData\Local\Packages\PythonSoftwareFoundation.Python.3.9_qbz5n2kfra8p0\LocalCache\local-packages\Python39\site-packages\newspaper\article.py", line 191, in parse
    self.throw_if_not_downloaded_verbose()
  File "C:\Users\User\AppData\Local\Packages\PythonSoftwareFoundation.Python.3.9_qbz5n2kfra8p0\LocalCache\local-packages\Python39\site-packages\newspaper\article.py", line 531, in throw_if_not_downloaded_verbose
    raise ArticleException('Article `download()` failed with %s on URL %s' %
newspaper.article.ArticleException: Article `download()` failed with HTTPConnectionPool(host='sportfella.com', port=80): Read timed out. (read timeout=7) on URL http://sportfella.com/breaking-fox-sports-cancels-nfl-broadcasts-players-respect-flag/
2021-11-24 19:19:14,717 12820 news_content_collection ERROR Exception in getting data from url sportfella.com/breaking-fox-sports-cancels-nfl-broadcasts-players-respect-flag/
Traceback (most recent call last):
  File "C:\Users\User\Desktop\ia2\FakeNewsNet\code\news_content_collection.py", line 36, in crawl_link_article
    article.parse()
  File "C:\Users\User\AppData\Local\Packages\PythonSoftwareFoundation.Python.3.9_qbz5n2kfra8p0\LocalCache\local-packages\Python39\site-packages\newspaper\article.py", line 191, in parse
    self.throw_if_not_downloaded_verbose()
  File "C:\Users\User\AppData\Local\Packages\PythonSoftwareFoundation.Python.3.9_qbz5n2kfra8p0\LocalCache\local-packages\Python39\site-packages\newspaper\article.py", line 531, in throw_if_not_downloaded_verbose
    raise ArticleException('Article `download()` failed with %s on URL %s' %
newspaper.article.ArticleException: Article `download()` failed with HTTPSConnectionPool(host='sportfella.com', port=443): Max retries exceeded with url: /breaking-fox-sports-cancels-nfl-broadcasts-players-respect-flag/ (Caused by ConnectTimeoutError(<urllib3.connection.VerifiedHTTPSConnection object at 0x000001DB5D3EDFD0>, 'Connection to sportfella.com timed out. (connect timeout=7)')) on URL https://sportfella.com/breaking-fox-sports-cancels-nfl-broadcasts-players-respect-flag/
2021-11-24 19:19:53,397 12820 news_content_collection ERROR Exception in getting data from url www.pirate4x4.com/forum/general-chit-chat/2543657-dea-just-raided-united-states-senator.html
Traceback (most recent call last):
  File "C:\Users\User\Desktop\ia2\FakeNewsNet\code\news_content_collection.py", line 25, in crawl_link_article
    article.parse()
  File "C:\Users\User\AppData\Local\Packages\PythonSoftwareFoundation.Python.3.9_qbz5n2kfra8p0\LocalCache\local-packages\Python39\site-packages\newspaper\article.py", line 191, in parse
    self.throw_if_not_downloaded_verbose()
  File "C:\Users\User\AppData\Local\Packages\PythonSoftwareFoundation.Python.3.9_qbz5n2kfra8p0\LocalCache\local-packages\Python39\site-packages\newspaper\article.py", line 531, in throw_if_not_downloaded_verbose
    raise ArticleException('Article `download()` failed with %s on URL %s' %
newspaper.article.ArticleException: Article `download()` failed with 503 Server Error: Service Temporarily Unavailable for url: https://www.pirate4x4.com/login/ on URL http://www.pirate4x4.com/forum/general-chit-chat/2543657-dea-just-raided-united-states-senator.html
2021-11-24 19:19:56,315 12820 news_content_collection ERROR Exception in getting data from url www.pirate4x4.com/forum/general-chit-chat/2543657-dea-just-raided-united-states-senator.html
Traceback (most recent call last):
  File "C:\Users\User\Desktop\ia2\FakeNewsNet\code\news_content_collection.py", line 36, in crawl_link_article
    article.parse()
  File "C:\Users\User\AppData\Local\Packages\PythonSoftwareFoundation.Python.3.9_qbz5n2kfra8p0\LocalCache\local-packages\Python39\site-packages\newspaper\article.py", line 191, in parse
    self.throw_if_not_downloaded_verbose()
  File "C:\Users\User\AppData\Local\Packages\PythonSoftwareFoundation.Python.3.9_qbz5n2kfra8p0\LocalCache\local-packages\Python39\site-packages\newspaper\article.py", line 531, in throw_if_not_downloaded_verbose
    raise ArticleException('Article `download()` failed with %s on URL %s' %
newspaper.article.ArticleException: Article `download()` failed with 503 Server Error: Service Temporarily Unavailable for url: https://www.pirate4x4.com/login/ on URL https://www.pirate4x4.com/forum/general-chit-chat/2543657-dea-just-raided-united-states-senator.html
2021-11-24 19:20:06,036 12820 news_content_collection ERROR Exception in getting data from url https://dailyworldupdate.us/2018/04/29/cnn-shocks-america-fires-journalist-who-made-fun-of-sarah-sanders-face/
Traceback (most recent call last):
  File "C:\Users\User\Desktop\ia2\FakeNewsNet\code\news_content_collection.py", line 49, in crawl_link_article
    article.parse()
  File "C:\Users\User\AppData\Local\Packages\PythonSoftwareFoundation.Python.3.9_qbz5n2kfra8p0\LocalCache\local-packages\Python39\site-packages\newspaper\article.py", line 191, in parse
    self.throw_if_not_downloaded_verbose()
  File "C:\Users\User\AppData\Local\Packages\PythonSoftwareFoundation.Python.3.9_qbz5n2kfra8p0\LocalCache\local-packages\Python39\site-packages\newspaper\article.py", line 531, in throw_if_not_downloaded_verbose
    raise ArticleException('Article `download()` failed with %s on URL %s' %
newspaper.article.ArticleException: Article `download()` failed with ('Connection aborted.', ConnectionResetError(10054, 'An existing connection was forcibly closed by the remote host', None, 10054, None)) on URL https://dailyworldupdate.us/2018/04/29/cnn-shocks-america-fires-journalist-who-made-fun-of-sarah-sanders-face/
2021-11-24 19:20:22,643 12820 news_content_collection ERROR Exception in getting data from url http://flashnewss.club/trumps-dhs-secretary-confirms-they-are-preparing-to-arrest-sanctuary-city-leaders/
Traceback (most recent call last):
  File "C:\Users\User\Desktop\ia2\FakeNewsNet\code\news_content_collection.py", line 49, in crawl_link_article
    article.parse()
  File "C:\Users\User\AppData\Local\Packages\PythonSoftwareFoundation.Python.3.9_qbz5n2kfra8p0\LocalCache\local-packages\Python39\site-packages\newspaper\article.py", line 191, in parse
    self.throw_if_not_downloaded_verbose()
  File "C:\Users\User\AppData\Local\Packages\PythonSoftwareFoundation.Python.3.9_qbz5n2kfra8p0\LocalCache\local-packages\Python39\site-packages\newspaper\article.py", line 531, in throw_if_not_downloaded_verbose
    raise ArticleException('Article `download()` failed with %s on URL %s' %
newspaper.article.ArticleException: Article `download()` failed with HTTPConnectionPool(host='flashnewss.club', port=80): Max retries exceeded with url: /trumps-dhs-secretary-confirms-they-are-preparing-to-arrest-sanctuary-city-leaders/ (Caused by NewConnectionError('<urllib3.connection.HTTPConnection object at 0x000001DB5D31F850>: Failed to establish a new connection: [Errno 11002] getaddrinfo failed')) on URL http://flashnewss.club/trumps-dhs-secretary-confirms-they-are-preparing-to-arrest-sanctuary-city-leaders/
2021-11-24 19:20:32,630 12820 news_content_collection ERROR Exception in getting data from url http://eveningw.com/california-democrat-maxine-waters-charged-3-counts-support/
Traceback (most recent call last):
  File "C:\Users\User\Desktop\ia2\FakeNewsNet\code\news_content_collection.py", line 49, in crawl_link_article
    article.parse()
  File "C:\Users\User\AppData\Local\Packages\PythonSoftwareFoundation.Python.3.9_qbz5n2kfra8p0\LocalCache\local-packages\Python39\site-packages\newspaper\article.py", line 191, in parse
    self.throw_if_not_downloaded_verbose()
  File "C:\Users\User\AppData\Local\Packages\PythonSoftwareFoundation.Python.3.9_qbz5n2kfra8p0\LocalCache\local-packages\Python39\site-packages\newspaper\article.py", line 531, in throw_if_not_downloaded_verbose
    raise ArticleException('Article `download()` failed with %s on URL %s' %
newspaper.article.ArticleException: Article `download()` failed with HTTPConnectionPool(host='eveningw.com', port=80): Max retries exceeded with url: /california-democrat-maxine-waters-charged-3-counts-support/ (Caused by NewConnectionError('<urllib3.connection.HTTPConnection object at 0x000001DB5D746BE0>: Failed to establish a new connection: [Errno 11001] getaddrinfo failed')) on URL http://eveningw.com/california-democrat-maxine-waters-charged-3-counts-support/
2021-11-24 19:20:35,222 12820 news_content_collection ERROR Exception in getting data from url http://nrtonline.info/breaking-british-intelligence-seizes-clinton-foundation-warehouse-400-million-in-cash/
Traceback (most recent call last):
  File "C:\Users\User\Desktop\ia2\FakeNewsNet\code\news_content_collection.py", line 49, in crawl_link_article
    article.parse()
  File "C:\Users\User\AppData\Local\Packages\PythonSoftwareFoundation.Python.3.9_qbz5n2kfra8p0\LocalCache\local-packages\Python39\site-packages\newspaper\article.py", line 191, in parse
    self.throw_if_not_downloaded_verbose()
  File "C:\Users\User\AppData\Local\Packages\PythonSoftwareFoundation.Python.3.9_qbz5n2kfra8p0\LocalCache\local-packages\Python39\site-packages\newspaper\article.py", line 531, in throw_if_not_downloaded_verbose
    raise ArticleException('Article `download()` failed with %s on URL %s' %
newspaper.article.ArticleException: Article `download()` failed with HTTPConnectionPool(host='nrtonline.info', port=80): Max retries exceeded with url: /breaking-british-intelligence-seizes-clinton-foundation-warehouse-400-million-in-cash/ (Caused by NewConnectionError('<urllib3.connection.HTTPConnection object at 0x000001DB5D7465B0>: Failed to establish a new connection: [Errno 11001] getaddrinfo failed')) on URL http://nrtonline.info/breaking-british-intelligence-seizes-clinton-foundation-warehouse-400-million-in-cash/
2021-11-24 19:20:48,086 12820 news_content_collection ERROR Exception in getting data from url http://hotgazette.com/rudy-giuliani/official-rudy-giuliani-officially-resigns-trumps-legal-team-on-its-last-leg/
Traceback (most recent call last):
  File "C:\Users\User\Desktop\ia2\FakeNewsNet\code\news_content_collection.py", line 49, in crawl_link_article
    article.parse()
  File "C:\Users\User\AppData\Local\Packages\PythonSoftwareFoundation.Python.3.9_qbz5n2kfra8p0\LocalCache\local-packages\Python39\site-packages\newspaper\article.py", line 191, in parse
    self.throw_if_not_downloaded_verbose()
  File "C:\Users\User\AppData\Local\Packages\PythonSoftwareFoundation.Python.3.9_qbz5n2kfra8p0\LocalCache\local-packages\Python39\site-packages\newspaper\article.py", line 531, in throw_if_not_downloaded_verbose
    raise ArticleException('Article `download()` failed with %s on URL %s' %
newspaper.article.ArticleException: Article `download()` failed with 404 Client Error: Not Found for url: http://hotgazette.com/rudy-giuliani/official-rudy-giuliani-officially-resigns-trumps-legal-team-on-its-last-leg/ on URL http://hotgazette.com/rudy-giuliani/official-rudy-giuliani-officially-resigns-trumps-legal-team-on-its-last-leg/
2021-11-24 19:21:00,222 12820 news_content_collection ERROR Exception in getting data from url https://www.nyfoxnews.co/michelle-obama-just-received-life-shattering-news-from-the-doctor/
Traceback (most recent call last):
  File "C:\Users\User\Desktop\ia2\FakeNewsNet\code\news_content_collection.py", line 49, in crawl_link_article
    article.parse()
  File "C:\Users\User\AppData\Local\Packages\PythonSoftwareFoundation.Python.3.9_qbz5n2kfra8p0\LocalCache\local-packages\Python39\site-packages\newspaper\article.py", line 191, in parse
    self.throw_if_not_downloaded_verbose()
  File "C:\Users\User\AppData\Local\Packages\PythonSoftwareFoundation.Python.3.9_qbz5n2kfra8p0\LocalCache\local-packages\Python39\site-packages\newspaper\article.py", line 531, in throw_if_not_downloaded_verbose
    raise ArticleException('Article `download()` failed with %s on URL %s' %
newspaper.article.ArticleException: Article `download()` failed with HTTPSConnectionPool(host='www.nyfoxnews.co', port=443): Max retries exceeded with url: /michelle-obama-just-received-life-shattering-news-from-the-doctor/ (Caused by NewConnectionError('<urllib3.connection.VerifiedHTTPSConnection object at 0x000001DB5D31F8E0>: Failed to establish a new connection: [WinError 10061] No connection could be made because the target machine actively refused it')) on URL https://www.nyfoxnews.co/michelle-obama-just-received-life-shattering-news-from-the-doctor/
2021-11-24 19:21:10,919 12820 news_content_collection ERROR Exception in getting data from url https://yournewswire.com/tens-of-thousands-of-scientists-declare-climate-change-a-hoax/
Traceback (most recent call last):
  File "C:\Users\User\Desktop\ia2\FakeNewsNet\code\news_content_collection.py", line 49, in crawl_link_article
    article.parse()
  File "C:\Users\User\AppData\Local\Packages\PythonSoftwareFoundation.Python.3.9_qbz5n2kfra8p0\LocalCache\local-packages\Python39\site-packages\newspaper\article.py", line 191, in parse
    self.throw_if_not_downloaded_verbose()
  File "C:\Users\User\AppData\Local\Packages\PythonSoftwareFoundation.Python.3.9_qbz5n2kfra8p0\LocalCache\local-packages\Python39\site-packages\newspaper\article.py", line 531, in throw_if_not_downloaded_verbose
    raise ArticleException('Article `download()` failed with %s on URL %s' %
newspaper.article.ArticleException: Article `download()` failed with 404 Client Error: Not Found for url: https://yournewswire.com/tens-of-thousands-of-scientists-declare-climate-change-a-hoax/ on URL https://yournewswire.com/tens-of-thousands-of-scientists-declare-climate-change-a-hoax/
2021-11-24 19:21:33,249 12820 news_content_collection ERROR Exception in getting data from url https://yournewswire.com/lisa-page-squeals-dnc-server-not-hacked-russia/
Traceback (most recent call last):
  File "C:\Users\User\Desktop\ia2\FakeNewsNet\code\news_content_collection.py", line 49, in crawl_link_article
    article.parse()
  File "C:\Users\User\AppData\Local\Packages\PythonSoftwareFoundation.Python.3.9_qbz5n2kfra8p0\LocalCache\local-packages\Python39\site-packages\newspaper\article.py", line 191, in parse
    self.throw_if_not_downloaded_verbose()
  File "C:\Users\User\AppData\Local\Packages\PythonSoftwareFoundation.Python.3.9_qbz5n2kfra8p0\LocalCache\local-packages\Python39\site-packages\newspaper\article.py", line 531, in throw_if_not_downloaded_verbose
    raise ArticleException('Article `download()` failed with %s on URL %s' %
newspaper.article.ArticleException: Article `download()` failed with 404 Client Error: Not Found for url: https://yournewswire.com/lisa-page-squeals-dnc-server-not-hacked-russia/ on URL https://yournewswire.com/lisa-page-squeals-dnc-server-not-hacked-russia/
2021-11-24 19:21:43,985 12820 news_content_collection ERROR Exception in getting data from url http://www.newsdonaldtrumps.com/robert-redford-says-michelle-and-barack-obama-should-get-five-years-in-prison/
Traceback (most recent call last):
  File "C:\Users\User\Desktop\ia2\FakeNewsNet\code\news_content_collection.py", line 49, in crawl_link_article
    article.parse()
  File "C:\Users\User\AppData\Local\Packages\PythonSoftwareFoundation.Python.3.9_qbz5n2kfra8p0\LocalCache\local-packages\Python39\site-packages\newspaper\article.py", line 191, in parse
    self.throw_if_not_downloaded_verbose()
  File "C:\Users\User\AppData\Local\Packages\PythonSoftwareFoundation.Python.3.9_qbz5n2kfra8p0\LocalCache\local-packages\Python39\site-packages\newspaper\article.py", line 531, in throw_if_not_downloaded_verbose
    raise ArticleException('Article `download()` failed with %s on URL %s' %
newspaper.article.ArticleException: Article `download()` failed with HTTPConnectionPool(host='www.newsdonaldtrumps.com', port=80): Max retries exceeded with url: /robert-redford-says-michelle-and-barack-obama-should-get-five-years-in-prison/ (Caused by NewConnectionError('<urllib3.connection.HTTPConnection object at 0x000001DB5D3E06D0>: Failed to establish a new connection: [Errno 11001] getaddrinfo failed')) on URL http://www.newsdonaldtrumps.com/robert-redford-says-michelle-and-barack-obama-should-get-five-years-in-prison/
2021-11-24 19:21:57,259 12820 news_content_collection ERROR Exception in getting data from url https://yournewswire.com/puerto-rico-mayor-fraud-disaster/
Traceback (most recent call last):
  File "C:\Users\User\Desktop\ia2\FakeNewsNet\code\news_content_collection.py", line 49, in crawl_link_article
    article.parse()
  File "C:\Users\User\AppData\Local\Packages\PythonSoftwareFoundation.Python.3.9_qbz5n2kfra8p0\LocalCache\local-packages\Python39\site-packages\newspaper\article.py", line 191, in parse
    self.throw_if_not_downloaded_verbose()
  File "C:\Users\User\AppData\Local\Packages\PythonSoftwareFoundation.Python.3.9_qbz5n2kfra8p0\LocalCache\local-packages\Python39\site-packages\newspaper\article.py", line 531, in throw_if_not_downloaded_verbose
    raise ArticleException('Article `download()` failed with %s on URL %s' %
newspaper.article.ArticleException: Article `download()` failed with 404 Client Error: Not Found for url: https://yournewswire.com/puerto-rico-mayor-fraud-disaster/ on URL https://yournewswire.com/puerto-rico-mayor-fraud-disaster/
2021-11-24 19:22:24,945 12820 news_content_collection ERROR Exception in getting data from url https://www.chicagosuntimes.live/queen-elizabeth-says-muslim-refugees-are-dividing-nationality-i-fully-agree-with-donald-trump-we-shouldvideo/
Traceback (most recent call last):
  File "C:\Users\User\Desktop\ia2\FakeNewsNet\code\news_content_collection.py", line 49, in crawl_link_article
    article.parse()
  File "C:\Users\User\AppData\Local\Packages\PythonSoftwareFoundation.Python.3.9_qbz5n2kfra8p0\LocalCache\local-packages\Python39\site-packages\newspaper\article.py", line 191, in parse
    self.throw_if_not_downloaded_verbose()
  File "C:\Users\User\AppData\Local\Packages\PythonSoftwareFoundation.Python.3.9_qbz5n2kfra8p0\LocalCache\local-packages\Python39\site-packages\newspaper\article.py", line 531, in throw_if_not_downloaded_verbose
    raise ArticleException('Article `download()` failed with %s on URL %s' %
newspaper.article.ArticleException: Article `download()` failed with HTTPSConnectionPool(host='www.chicagosuntimes.live', port=443): Max retries exceeded with url: /queen-elizabeth-says-muslim-refugees-are-dividing-nationality-i-fully-agree-with-donald-trump-we-shouldvideo/ (Caused by NewConnectionError('<urllib3.connection.VerifiedHTTPSConnection object at 0x000001DB5D7A8E50>: Failed to establish a new connection: [Errno 11001] getaddrinfo failed')) on URL https://www.chicagosuntimes.live/queen-elizabeth-says-muslim-refugees-are-dividing-nationality-i-fully-agree-with-donald-trump-we-shouldvideo/
2021-11-24 19:22:28,708 12820 news_content_collection ERROR Exception in getting data from url https://web.archive.org/web/20180819235451/https://www.chicagosuntimes.live/queen-elizabeth-says-muslim-refugees-are-dividing-nationality-i-fully-agree-with-donald-trump-we-shouldvideo/
Traceback (most recent call last):
  File "C:\Users\User\Desktop\ia2\FakeNewsNet\code\news_content_collection.py", line 49, in crawl_link_article
    article.parse()
  File "C:\Users\User\AppData\Local\Packages\PythonSoftwareFoundation.Python.3.9_qbz5n2kfra8p0\LocalCache\local-packages\Python39\site-packages\newspaper\article.py", line 191, in parse
    self.throw_if_not_downloaded_verbose()
  File "C:\Users\User\AppData\Local\Packages\PythonSoftwareFoundation.Python.3.9_qbz5n2kfra8p0\LocalCache\local-packages\Python39\site-packages\newspaper\article.py", line 531, in throw_if_not_downloaded_verbose
    raise ArticleException('Article `download()` failed with %s on URL %s' %
newspaper.article.ArticleException: Article `download()` failed with 404 Client Error: Not Found for url: https://web.archive.org/web/20180819235451/https://www.chicagosuntimes.live/queen-elizabeth-says-muslim-refugees-are-dividing-nationality-i-fully-agree-with-donald-trump-we-shouldvideo/ on URL https://web.archive.org/web/20180819235451/https://www.chicagosuntimes.live/queen-elizabeth-says-muslim-refugees-are-dividing-nationality-i-fully-agree-with-donald-trump-we-shouldvideo/
2021-11-24 19:22:30,736 12820 news_content_collection ERROR Exception in getting data from url https://theglobalheadlines.net/hollywood-actor-bruce-willis-trump-is-the-best-us-president-ever-anyone-who-dislikes-him-should-move-to-2/
Traceback (most recent call last):
  File "C:\Users\User\Desktop\ia2\FakeNewsNet\code\news_content_collection.py", line 49, in crawl_link_article
    article.parse()
  File "C:\Users\User\AppData\Local\Packages\PythonSoftwareFoundation.Python.3.9_qbz5n2kfra8p0\LocalCache\local-packages\Python39\site-packages\newspaper\article.py", line 191, in parse
    self.throw_if_not_downloaded_verbose()
  File "C:\Users\User\AppData\Local\Packages\PythonSoftwareFoundation.Python.3.9_qbz5n2kfra8p0\LocalCache\local-packages\Python39\site-packages\newspaper\article.py", line 531, in throw_if_not_downloaded_verbose
    raise ArticleException('Article `download()` failed with %s on URL %s' %
newspaper.article.ArticleException: Article `download()` failed with HTTPSConnectionPool(host='theglobalheadlines.net', port=443): Max retries exceeded with url: /hollywood-actor-bruce-willis-trump-is-the-best-us-president-ever-anyone-who-dislikes-him-should-move-to-2/ (Caused by NewConnectionError('<urllib3.connection.VerifiedHTTPSConnection object at 0x000001DB5D7A87F0>: Failed to establish a new connection: [Errno 11001] getaddrinfo failed')) on URL https://theglobalheadlines.net/hollywood-actor-bruce-willis-trump-is-the-best-us-president-ever-anyone-who-dislikes-him-should-move-to-2/
2021-11-24 19:22:51,097 12820 news_content_collection ERROR Exception in getting data from url http://patriotcrier.com/1-6kk-0/
Traceback (most recent call last):
  File "C:\Users\User\Desktop\ia2\FakeNewsNet\code\news_content_collection.py", line 49, in crawl_link_article
    article.parse()
  File "C:\Users\User\AppData\Local\Packages\PythonSoftwareFoundation.Python.3.9_qbz5n2kfra8p0\LocalCache\local-packages\Python39\site-packages\newspaper\article.py", line 191, in parse
    self.throw_if_not_downloaded_verbose()
  File "C:\Users\User\AppData\Local\Packages\PythonSoftwareFoundation.Python.3.9_qbz5n2kfra8p0\LocalCache\local-packages\Python39\site-packages\newspaper\article.py", line 531, in throw_if_not_downloaded_verbose
    raise ArticleException('Article `download()` failed with %s on URL %s' %
newspaper.article.ArticleException: Article `download()` failed with HTTPConnectionPool(host='patriotcrier.com', port=80): Max retries exceeded with url: /1-6kk-0/ (Caused by NewConnectionError('<urllib3.connection.HTTPConnection object at 0x000001DB5D7AD7C0>: Failed to establish a new connection: [Errno 11002] getaddrinfo failed')) on URL http://patriotcrier.com/1-6kk-0/
2021-11-24 19:23:04,779 12820 news_content_collection ERROR Exception in getting data from url http://americannews.com/busted-nasa-accidentally-destroys-every-climate-change-advocate-exposing-massive-truth-behind-antartica/
Traceback (most recent call last):
  File "C:\Users\User\Desktop\ia2\FakeNewsNet\code\news_content_collection.py", line 49, in crawl_link_article
    article.parse()
  File "C:\Users\User\AppData\Local\Packages\PythonSoftwareFoundation.Python.3.9_qbz5n2kfra8p0\LocalCache\local-packages\Python39\site-packages\newspaper\article.py", line 191, in parse
    self.throw_if_not_downloaded_verbose()
  File "C:\Users\User\AppData\Local\Packages\PythonSoftwareFoundation.Python.3.9_qbz5n2kfra8p0\LocalCache\local-packages\Python39\site-packages\newspaper\article.py", line 531, in throw_if_not_downloaded_verbose
    raise ArticleException('Article `download()` failed with %s on URL %s' %
newspaper.article.ArticleException: Article `download()` failed with HTTPConnectionPool(host='americannews.com', port=80): Read timed out. (read timeout=7) on URL http://americannews.com/busted-nasa-accidentally-destroys-every-climate-change-advocate-exposing-massive-truth-behind-antartica/
2021-11-24 19:23:17,894 12820 news_content_collection ERROR Exception in getting data from url http://www.bluedotdaily.com/trump-police-officers-and-firefighters-make-too-much-money-hits-them-with-tax-penalty/
Traceback (most recent call last):
  File "C:\Users\User\Desktop\ia2\FakeNewsNet\code\news_content_collection.py", line 49, in crawl_link_article
    article.parse()
  File "C:\Users\User\AppData\Local\Packages\PythonSoftwareFoundation.Python.3.9_qbz5n2kfra8p0\LocalCache\local-packages\Python39\site-packages\newspaper\article.py", line 191, in parse
    self.throw_if_not_downloaded_verbose()
  File "C:\Users\User\AppData\Local\Packages\PythonSoftwareFoundation.Python.3.9_qbz5n2kfra8p0\LocalCache\local-packages\Python39\site-packages\newspaper\article.py", line 531, in throw_if_not_downloaded_verbose
    raise ArticleException('Article `download()` failed with %s on URL %s' %
newspaper.article.ArticleException: Article `download()` failed with 404 Client Error: Not Found for url: http://www.bluedotdaily.com/trump-police-officers-and-firefighters-make-too-much-money-hits-them-with-tax-penalty/ on URL http://www.bluedotdaily.com/trump-police-officers-and-firefighters-make-too-much-money-hits-them-with-tax-penalty/
2021-11-24 19:23:22,286 12820 news_content_collection ERROR Exception in getting data from url https://web.archive.org/web/20171227233221/http://www.bluedotdaily.com/trump-police-officers-and-firefighters-make-too-much-money-hits-them-with-tax-penalty/
Traceback (most recent call last):
  File "C:\Users\User\Desktop\ia2\FakeNewsNet\code\news_content_collection.py", line 49, in crawl_link_article
    article.parse()
  File "C:\Users\User\AppData\Local\Packages\PythonSoftwareFoundation.Python.3.9_qbz5n2kfra8p0\LocalCache\local-packages\Python39\site-packages\newspaper\article.py", line 191, in parse
    self.throw_if_not_downloaded_verbose()
  File "C:\Users\User\AppData\Local\Packages\PythonSoftwareFoundation.Python.3.9_qbz5n2kfra8p0\LocalCache\local-packages\Python39\site-packages\newspaper\article.py", line 531, in throw_if_not_downloaded_verbose
    raise ArticleException('Article `download()` failed with %s on URL %s' %
newspaper.article.ArticleException: Article `download()` failed with 403 Client Error: Forbidden for url: https://web.archive.org/web/20171227233221/http://www.bluedotdaily.com/trump-police-officers-and-firefighters-make-too-much-money-hits-them-with-tax-penalty/ on URL https://web.archive.org/web/20171227233221/http://www.bluedotdaily.com/trump-police-officers-and-firefighters-make-too-much-money-hits-them-with-tax-penalty/
2021-11-24 19:23:42,970 12820 news_content_collection ERROR Exception in getting data from url http://yournewswire.com/melanic-trump-exorcist-white-house/
Traceback (most recent call last):
  File "C:\Users\User\Desktop\ia2\FakeNewsNet\code\news_content_collection.py", line 49, in crawl_link_article
    article.parse()
  File "C:\Users\User\AppData\Local\Packages\PythonSoftwareFoundation.Python.3.9_qbz5n2kfra8p0\LocalCache\local-packages\Python39\site-packages\newspaper\article.py", line 191, in parse
    self.throw_if_not_downloaded_verbose()
  File "C:\Users\User\AppData\Local\Packages\PythonSoftwareFoundation.Python.3.9_qbz5n2kfra8p0\LocalCache\local-packages\Python39\site-packages\newspaper\article.py", line 531, in throw_if_not_downloaded_verbose
    raise ArticleException('Article `download()` failed with %s on URL %s' %
newspaper.article.ArticleException: Article `download()` failed with 404 Client Error: Not Found for url: http://yournewswire.com/melanic-trump-exorcist-white-house/ on URL http://yournewswire.com/melanic-trump-exorcist-white-house/
2021-11-24 19:23:55,753 12820 news_content_collection ERROR Exception in getting data from url http://maga2020.us/news/clint-eastwood-leaves-his-estate-to-the-trump-2020-campaign/
Traceback (most recent call last):
  File "C:\Users\User\Desktop\ia2\FakeNewsNet\code\news_content_collection.py", line 49, in crawl_link_article
    article.parse()
  File "C:\Users\User\AppData\Local\Packages\PythonSoftwareFoundation.Python.3.9_qbz5n2kfra8p0\LocalCache\local-packages\Python39\site-packages\newspaper\article.py", line 191, in parse
    self.throw_if_not_downloaded_verbose()
  File "C:\Users\User\AppData\Local\Packages\PythonSoftwareFoundation.Python.3.9_qbz5n2kfra8p0\LocalCache\local-packages\Python39\site-packages\newspaper\article.py", line 531, in throw_if_not_downloaded_verbose
    raise ArticleException('Article `download()` failed with %s on URL %s' %
newspaper.article.ArticleException: Article `download()` failed with HTTPConnectionPool(host='maga2020.us', port=80): Max retries exceeded with url: /news/clint-eastwood-leaves-his-estate-to-the-trump-2020-campaign/ (Caused by NewConnectionError('<urllib3.connection.HTTPConnection object at 0x000001DB5D7AFE50>: Failed to establish a new connection: [Errno 11001] getaddrinfo failed')) on URL http://maga2020.us/news/clint-eastwood-leaves-his-estate-to-the-trump-2020-campaign/
2021-11-24 19:24:53,089 12820 news_content_collection ERROR Exception in getting data from url https://www.tdtalliance.com/jefferson-davis-statue-replaced-obama-likeness/
Traceback (most recent call last):
  File "C:\Users\User\Desktop\ia2\FakeNewsNet\code\news_content_collection.py", line 49, in crawl_link_article
    article.parse()
  File "C:\Users\User\AppData\Local\Packages\PythonSoftwareFoundation.Python.3.9_qbz5n2kfra8p0\LocalCache\local-packages\Python39\site-packages\newspaper\article.py", line 191, in parse
    self.throw_if_not_downloaded_verbose()
  File "C:\Users\User\AppData\Local\Packages\PythonSoftwareFoundation.Python.3.9_qbz5n2kfra8p0\LocalCache\local-packages\Python39\site-packages\newspaper\article.py", line 531, in throw_if_not_downloaded_verbose
    raise ArticleException('Article `download()` failed with %s on URL %s' %
newspaper.article.ArticleException: Article `download()` failed with 404 Client Error: Not Found for url: https://tdtalliance.com/jefferson-davis-statue-replaced-obama-likeness/ on URL https://www.tdtalliance.com/jefferson-davis-statue-replaced-obama-likeness/
2021-11-24 19:25:18,860 12820 news_content_collection ERROR Exception in getting data from url mainerepublicemailalert.com/2017/03/24/breaking-autopsy-results-from-vince-fosters-exhumed-body-cause-of-death-to-be-changed/
Traceback (most recent call last):
  File "C:\Users\User\Desktop\ia2\FakeNewsNet\code\news_content_collection.py", line 25, in crawl_link_article
    article.parse()
  File "C:\Users\User\AppData\Local\Packages\PythonSoftwareFoundation.Python.3.9_qbz5n2kfra8p0\LocalCache\local-packages\Python39\site-packages\newspaper\article.py", line 191, in parse
    self.throw_if_not_downloaded_verbose()
  File "C:\Users\User\AppData\Local\Packages\PythonSoftwareFoundation.Python.3.9_qbz5n2kfra8p0\LocalCache\local-packages\Python39\site-packages\newspaper\article.py", line 531, in throw_if_not_downloaded_verbose
    raise ArticleException('Article `download()` failed with %s on URL %s' %
newspaper.article.ArticleException: Article `download()` failed with 404 Client Error: Not Found for url: http://mainerepublicemailalert.com/2017/03/24/breaking-autopsy-results-from-vince-fosters-exhumed-body-cause-of-death-to-be-changed/ on URL http://mainerepublicemailalert.com/2017/03/24/breaking-autopsy-results-from-vince-fosters-exhumed-body-cause-of-death-to-be-changed/
2021-11-24 19:25:21,747 12820 news_content_collection ERROR Exception in getting data from url mainerepublicemailalert.com/2017/03/24/breaking-autopsy-results-from-vince-fosters-exhumed-body-cause-of-death-to-be-changed/
Traceback (most recent call last):
  File "C:\Users\User\Desktop\ia2\FakeNewsNet\code\news_content_collection.py", line 36, in crawl_link_article
    article.parse()
  File "C:\Users\User\AppData\Local\Packages\PythonSoftwareFoundation.Python.3.9_qbz5n2kfra8p0\LocalCache\local-packages\Python39\site-packages\newspaper\article.py", line 191, in parse
    self.throw_if_not_downloaded_verbose()
  File "C:\Users\User\AppData\Local\Packages\PythonSoftwareFoundation.Python.3.9_qbz5n2kfra8p0\LocalCache\local-packages\Python39\site-packages\newspaper\article.py", line 531, in throw_if_not_downloaded_verbose
    raise ArticleException('Article `download()` failed with %s on URL %s' %
newspaper.article.ArticleException: Article `download()` failed with 404 Client Error: Not Found for url: https://mainerepublicemailalert.com/2017/03/24/breaking-autopsy-results-from-vince-fosters-exhumed-body-cause-of-death-to-be-changed/ on URL https://mainerepublicemailalert.com/2017/03/24/breaking-autopsy-results-from-vince-fosters-exhumed-body-cause-of-death-to-be-changed/
2021-11-24 19:25:29,213 12820 news_content_collection ERROR Exception in getting data from url https://web.archive.org/web/20170325151856/http://mainerepublicemailalert.com/2017/03/24/breaking-autopsy-results-from-vince-fosters-exhumed-body-cause-of-death-to-be-changed/
Traceback (most recent call last):
  File "C:\Users\User\Desktop\ia2\FakeNewsNet\code\news_content_collection.py", line 49, in crawl_link_article
    article.parse()
  File "C:\Users\User\AppData\Local\Packages\PythonSoftwareFoundation.Python.3.9_qbz5n2kfra8p0\LocalCache\local-packages\Python39\site-packages\newspaper\article.py", line 191, in parse
    self.throw_if_not_downloaded_verbose()
  File "C:\Users\User\AppData\Local\Packages\PythonSoftwareFoundation.Python.3.9_qbz5n2kfra8p0\LocalCache\local-packages\Python39\site-packages\newspaper\article.py", line 531, in throw_if_not_downloaded_verbose
    raise ArticleException('Article `download()` failed with %s on URL %s' %
newspaper.article.ArticleException: Article `download()` failed with 404 Client Error: Not Found for url: https://web.archive.org/web/20210505123012/https://mainerepublicemailalert.com/2017/03/24/breaking-autopsy-results-from-vince-fosters-exhumed-body-cause-of-death-to-be-changed/ on URL https://web.archive.org/web/20170325151856/http://mainerepublicemailalert.com/2017/03/24/breaking-autopsy-results-from-vince-fosters-exhumed-body-cause-of-death-to-be-changed/
2021-11-24 19:25:39,357 12820 news_content_collection ERROR Exception in getting data from url www.usacarry.com/forums/politics-and-news/62210-hrc-caught-tape-laughing-about-irma-wiping-out-all-those-florida-hillbillies.html
Traceback (most recent call last):
  File "C:\Users\User\Desktop\ia2\FakeNewsNet\code\news_content_collection.py", line 25, in crawl_link_article
    article.parse()
  File "C:\Users\User\AppData\Local\Packages\PythonSoftwareFoundation.Python.3.9_qbz5n2kfra8p0\LocalCache\local-packages\Python39\site-packages\newspaper\article.py", line 191, in parse
    self.throw_if_not_downloaded_verbose()
  File "C:\Users\User\AppData\Local\Packages\PythonSoftwareFoundation.Python.3.9_qbz5n2kfra8p0\LocalCache\local-packages\Python39\site-packages\newspaper\article.py", line 531, in throw_if_not_downloaded_verbose
    raise ArticleException('Article `download()` failed with %s on URL %s' %
newspaper.article.ArticleException: Article `download()` failed with 403 Client Error: Forbidden for url: https://forums.usacarry.com/politics-and-news/62210-hrc-caught-tape-laughing-about-irma-wiping-out-all-those-florida-hillbillies.html on URL http://www.usacarry.com/forums/politics-and-news/62210-hrc-caught-tape-laughing-about-irma-wiping-out-all-those-florida-hillbillies.html
2021-11-24 19:25:42,115 12820 news_content_collection ERROR Exception in getting data from url www.usacarry.com/forums/politics-and-news/62210-hrc-caught-tape-laughing-about-irma-wiping-out-all-those-florida-hillbillies.html
Traceback (most recent call last):
  File "C:\Users\User\Desktop\ia2\FakeNewsNet\code\news_content_collection.py", line 36, in crawl_link_article
    article.parse()
  File "C:\Users\User\AppData\Local\Packages\PythonSoftwareFoundation.Python.3.9_qbz5n2kfra8p0\LocalCache\local-packages\Python39\site-packages\newspaper\article.py", line 191, in parse
    self.throw_if_not_downloaded_verbose()
  File "C:\Users\User\AppData\Local\Packages\PythonSoftwareFoundation.Python.3.9_qbz5n2kfra8p0\LocalCache\local-packages\Python39\site-packages\newspaper\article.py", line 531, in throw_if_not_downloaded_verbose
    raise ArticleException('Article `download()` failed with %s on URL %s' %
newspaper.article.ArticleException: Article `download()` failed with 403 Client Error: Forbidden for url: https://forums.usacarry.com/politics-and-news/62210-hrc-caught-tape-laughing-about-irma-wiping-out-all-those-florida-hillbillies.html on URL https://www.usacarry.com/forums/politics-and-news/62210-hrc-caught-tape-laughing-about-irma-wiping-out-all-those-florida-hillbillies.html
2021-11-24 19:25:58,577 12820 news_content_collection ERROR Exception in getting data from url http://usamirrornews.com/roy-moores-accuser-arrested-and-charged-with-falsification/
Traceback (most recent call last):
  File "C:\Users\User\Desktop\ia2\FakeNewsNet\code\news_content_collection.py", line 49, in crawl_link_article
    article.parse()
  File "C:\Users\User\AppData\Local\Packages\PythonSoftwareFoundation.Python.3.9_qbz5n2kfra8p0\LocalCache\local-packages\Python39\site-packages\newspaper\article.py", line 191, in parse
    self.throw_if_not_downloaded_verbose()
  File "C:\Users\User\AppData\Local\Packages\PythonSoftwareFoundation.Python.3.9_qbz5n2kfra8p0\LocalCache\local-packages\Python39\site-packages\newspaper\article.py", line 531, in throw_if_not_downloaded_verbose
    raise ArticleException('Article `download()` failed with %s on URL %s' %
newspaper.article.ArticleException: Article `download()` failed with HTTPConnectionPool(host='usamirrornews.com', port=80): Max retries exceeded with url: /roy-moores-accuser-arrested-and-charged-with-falsification/ (Caused by ConnectTimeoutError(<urllib3.connection.HTTPConnection object at 0x000001DB5D7BB5E0>, 'Connection to usamirrornews.com timed out. (connect timeout=7)')) on URL http://usamirrornews.com/roy-moores-accuser-arrested-and-charged-with-falsification/
2021-11-24 19:26:29,797 12820 news_content_collection ERROR Exception in getting data from url http://wkrg.com/2017/11/14/curious-robocall-seeks-damaging-information-on-moore/
Traceback (most recent call last):
  File "C:\Users\User\Desktop\ia2\FakeNewsNet\code\news_content_collection.py", line 49, in crawl_link_article
    article.parse()
  File "C:\Users\User\AppData\Local\Packages\PythonSoftwareFoundation.Python.3.9_qbz5n2kfra8p0\LocalCache\local-packages\Python39\site-packages\newspaper\article.py", line 191, in parse
    self.throw_if_not_downloaded_verbose()
  File "C:\Users\User\AppData\Local\Packages\PythonSoftwareFoundation.Python.3.9_qbz5n2kfra8p0\LocalCache\local-packages\Python39\site-packages\newspaper\article.py", line 531, in throw_if_not_downloaded_verbose
    raise ArticleException('Article `download()` failed with %s on URL %s' %
newspaper.article.ArticleException: Article `download()` failed with 404 Client Error: Not Found for url: https://www.wkrg.com/2017/11/14/curious-robocall-seeks-damaging-information-on-moore/ on URL http://wkrg.com/2017/11/14/curious-robocall-seeks-damaging-information-on-moore/
2021-11-24 19:26:36,279 12820 news_content_collection ERROR Exception in getting data from url https://www.viralwdc.site/national-guard-storms-mexico-border-makes-game-changing-impact-in-just-30-days/
Traceback (most recent call last):
  File "C:\Users\User\Desktop\ia2\FakeNewsNet\code\news_content_collection.py", line 49, in crawl_link_article
    article.parse()
  File "C:\Users\User\AppData\Local\Packages\PythonSoftwareFoundation.Python.3.9_qbz5n2kfra8p0\LocalCache\local-packages\Python39\site-packages\newspaper\article.py", line 191, in parse
    self.throw_if_not_downloaded_verbose()
  File "C:\Users\User\AppData\Local\Packages\PythonSoftwareFoundation.Python.3.9_qbz5n2kfra8p0\LocalCache\local-packages\Python39\site-packages\newspaper\article.py", line 531, in throw_if_not_downloaded_verbose
    raise ArticleException('Article `download()` failed with %s on URL %s' %
newspaper.article.ArticleException: Article `download()` failed with HTTPSConnectionPool(host='www.viralwdc.site', port=443): Max retries exceeded with url: /national-guard-storms-mexico-border-makes-game-changing-impact-in-just-30-days/ (Caused by NewConnectionError('<urllib3.connection.VerifiedHTTPSConnection object at 0x000001DB5D7B1160>: Failed to establish a new connection: [Errno 11001] getaddrinfo failed')) on URL https://www.viralwdc.site/national-guard-storms-mexico-border-makes-game-changing-impact-in-just-30-days/
2021-11-24 19:26:52,743 12820 news_content_collection ERROR Exception in getting data from url http://flashnewss.club/breaking-shep-smith-to-be-canned-because-he-cant-control-his-hate-for-donald-trump/
Traceback (most recent call last):
  File "C:\Users\User\Desktop\ia2\FakeNewsNet\code\news_content_collection.py", line 49, in crawl_link_article
    article.parse()
  File "C:\Users\User\AppData\Local\Packages\PythonSoftwareFoundation.Python.3.9_qbz5n2kfra8p0\LocalCache\local-packages\Python39\site-packages\newspaper\article.py", line 191, in parse
    self.throw_if_not_downloaded_verbose()
  File "C:\Users\User\AppData\Local\Packages\PythonSoftwareFoundation.Python.3.9_qbz5n2kfra8p0\LocalCache\local-packages\Python39\site-packages\newspaper\article.py", line 531, in throw_if_not_downloaded_verbose
    raise ArticleException('Article `download()` failed with %s on URL %s' %
newspaper.article.ArticleException: Article `download()` failed with HTTPConnectionPool(host='flashnewss.club', port=80): Max retries exceeded with url: /breaking-shep-smith-to-be-canned-because-he-cant-control-his-hate-for-donald-trump/ (Caused by NewConnectionError('<urllib3.connection.HTTPConnection object at 0x000001DB5D7AF8E0>: Failed to establish a new connection: [Errno 11002] getaddrinfo failed')) on URL http://flashnewss.club/breaking-shep-smith-to-be-canned-because-he-cant-control-his-hate-for-donald-trump/
2021-11-24 19:27:17,466 12820 news_content_collection ERROR Exception in getting data from url http://eveningw.com/breaking-woman-says-offered-big-money-washington-post-accuse-roy-moore-misconduct/
Traceback (most recent call last):
  File "C:\Users\User\Desktop\ia2\FakeNewsNet\code\news_content_collection.py", line 49, in crawl_link_article
    article.parse()
  File "C:\Users\User\AppData\Local\Packages\PythonSoftwareFoundation.Python.3.9_qbz5n2kfra8p0\LocalCache\local-packages\Python39\site-packages\newspaper\article.py", line 191, in parse
    self.throw_if_not_downloaded_verbose()
  File "C:\Users\User\AppData\Local\Packages\PythonSoftwareFoundation.Python.3.9_qbz5n2kfra8p0\LocalCache\local-packages\Python39\site-packages\newspaper\article.py", line 531, in throw_if_not_downloaded_verbose
    raise ArticleException('Article `download()` failed with %s on URL %s' %
newspaper.article.ArticleException: Article `download()` failed with HTTPConnectionPool(host='eveningw.com', port=80): Max retries exceeded with url: /breaking-woman-says-offered-big-money-washington-post-accuse-roy-moore-misconduct/ (Caused by NewConnectionError('<urllib3.connection.HTTPConnection object at 0x000001DB5D7ADF40>: Failed to establish a new connection: [Errno 11001] getaddrinfo failed')) on URL http://eveningw.com/breaking-woman-says-offered-big-money-washington-post-accuse-roy-moore-misconduct/
2021-11-24 19:27:24,477 12820 news_content_collection ERROR Exception in getting data from url https://www.conservativestories.com/2018/05/21/just-john-kerry-facing-prison/
Traceback (most recent call last):
  File "C:\Users\User\Desktop\ia2\FakeNewsNet\code\news_content_collection.py", line 49, in crawl_link_article
    article.parse()
  File "C:\Users\User\AppData\Local\Packages\PythonSoftwareFoundation.Python.3.9_qbz5n2kfra8p0\LocalCache\local-packages\Python39\site-packages\newspaper\article.py", line 191, in parse
    self.throw_if_not_downloaded_verbose()
  File "C:\Users\User\AppData\Local\Packages\PythonSoftwareFoundation.Python.3.9_qbz5n2kfra8p0\LocalCache\local-packages\Python39\site-packages\newspaper\article.py", line 531, in throw_if_not_downloaded_verbose
    raise ArticleException('Article `download()` failed with %s on URL %s' %
newspaper.article.ArticleException: Article `download()` failed with 404 Client Error: Not Found for url: https://www.conservativestories.com/2018/05/21/just-john-kerry-facing-prison/ on URL https://www.conservativestories.com/2018/05/21/just-john-kerry-facing-prison/
2021-11-24 19:27:45,738 12820 news_content_collection ERROR Exception in getting data from url http://realtimepolitics.com/2018/05/06/melania-hit-donald-trump/
Traceback (most recent call last):
  File "C:\Users\User\Desktop\ia2\FakeNewsNet\code\news_content_collection.py", line 49, in crawl_link_article
    article.parse()
  File "C:\Users\User\AppData\Local\Packages\PythonSoftwareFoundation.Python.3.9_qbz5n2kfra8p0\LocalCache\local-packages\Python39\site-packages\newspaper\article.py", line 191, in parse
    self.throw_if_not_downloaded_verbose()
  File "C:\Users\User\AppData\Local\Packages\PythonSoftwareFoundation.Python.3.9_qbz5n2kfra8p0\LocalCache\local-packages\Python39\site-packages\newspaper\article.py", line 531, in throw_if_not_downloaded_verbose
    raise ArticleException('Article `download()` failed with %s on URL %s' %
newspaper.article.ArticleException: Article `download()` failed with HTTPConnectionPool(host='realtimepolitics.com', port=80): Max retries exceeded with url: /2018/05/06/melania-hit-donald-trump/ (Caused by ConnectTimeoutError(<urllib3.connection.HTTPConnection object at 0x000001DB5D7AD790>, 'Connection to realtimepolitics.com timed out. (connect timeout=7)')) on URL http://realtimepolitics.com/2018/05/06/melania-hit-donald-trump/
2021-11-24 19:27:49,404 12820 news_content_collection ERROR Exception in getting data from url https://web.archive.org/web/20180512222117/http://realtimepolitics.com:80/2018/05/06/melania-hit-donald-trump/
Traceback (most recent call last):
  File "C:\Users\User\Desktop\ia2\FakeNewsNet\code\news_content_collection.py", line 49, in crawl_link_article
    article.parse()
  File "C:\Users\User\AppData\Local\Packages\PythonSoftwareFoundation.Python.3.9_qbz5n2kfra8p0\LocalCache\local-packages\Python39\site-packages\newspaper\article.py", line 191, in parse
    self.throw_if_not_downloaded_verbose()
  File "C:\Users\User\AppData\Local\Packages\PythonSoftwareFoundation.Python.3.9_qbz5n2kfra8p0\LocalCache\local-packages\Python39\site-packages\newspaper\article.py", line 531, in throw_if_not_downloaded_verbose
    raise ArticleException('Article `download()` failed with %s on URL %s' %
newspaper.article.ArticleException: Article `download()` failed with 403 Client Error: Forbidden for url: https://web.archive.org/web/20180512222117/http://realtimepolitics.com:80/2018/05/06/melania-hit-donald-trump/ on URL https://web.archive.org/web/20180512222117/http://realtimepolitics.com:80/2018/05/06/melania-hit-donald-trump/
2021-11-24 19:27:58,589 12820 news_content_collection ERROR Exception in getting data from url https://portalstate.com/index.php/2017/05/08/obama-canceled-it-trump-reinstated-it-a-very-sacred-day-is-back/
Traceback (most recent call last):
  File "C:\Users\User\Desktop\ia2\FakeNewsNet\code\news_content_collection.py", line 49, in crawl_link_article
    article.parse()
  File "C:\Users\User\AppData\Local\Packages\PythonSoftwareFoundation.Python.3.9_qbz5n2kfra8p0\LocalCache\local-packages\Python39\site-packages\newspaper\article.py", line 191, in parse
    self.throw_if_not_downloaded_verbose()
  File "C:\Users\User\AppData\Local\Packages\PythonSoftwareFoundation.Python.3.9_qbz5n2kfra8p0\LocalCache\local-packages\Python39\site-packages\newspaper\article.py", line 531, in throw_if_not_downloaded_verbose
    raise ArticleException('Article `download()` failed with %s on URL %s' %
newspaper.article.ArticleException: Article `download()` failed with HTTPSConnectionPool(host='portalstate.com', port=443): Max retries exceeded with url: /index.php/2017/05/08/obama-canceled-it-trump-reinstated-it-a-very-sacred-day-is-back/ (Caused by ConnectTimeoutError(<urllib3.connection.VerifiedHTTPSConnection object at 0x000001DB5D7B17F0>, 'Connection to portalstate.com timed out. (connect timeout=7)')) on URL https://portalstate.com/index.php/2017/05/08/obama-canceled-it-trump-reinstated-it-a-very-sacred-day-is-back/
