2021-11-17 19:27:48,842 17076 news_content_collection ERROR Exception in getting data from url speedtalk.com/forum/viewtopic.php?t=51650
Traceback (most recent call last):
  File "C:\Users\User\Desktop\ia2\FakeNewsNet\code\news_content_collection.py", line 23, in crawl_link_article
    article.download()
  File "C:\Users\User\AppData\Local\Packages\PythonSoftwareFoundation.Python.3.9_qbz5n2kfra8p0\LocalCache\local-packages\Python39\site-packages\newspaper\article.py", line 170, in download
    html = network.get_html_2XX_only(self.url, self.config)
  File "C:\Users\User\AppData\Local\Packages\PythonSoftwareFoundation.Python.3.9_qbz5n2kfra8p0\LocalCache\local-packages\Python39\site-packages\newspaper\network.py", line 62, in get_html_2XX_only
    response = requests.get(
  File "C:\Users\User\AppData\Local\Packages\PythonSoftwareFoundation.Python.3.9_qbz5n2kfra8p0\LocalCache\local-packages\Python39\site-packages\requests\api.py", line 75, in get
    return request('get', url, params=params, **kwargs)
  File "C:\Users\User\AppData\Local\Packages\PythonSoftwareFoundation.Python.3.9_qbz5n2kfra8p0\LocalCache\local-packages\Python39\site-packages\requests\api.py", line 60, in request
    return session.request(method=method, url=url, **kwargs)
  File "C:\Users\User\AppData\Local\Packages\PythonSoftwareFoundation.Python.3.9_qbz5n2kfra8p0\LocalCache\local-packages\Python39\site-packages\requests\sessions.py", line 533, in request
    resp = self.send(prep, **send_kwargs)
  File "C:\Users\User\AppData\Local\Packages\PythonSoftwareFoundation.Python.3.9_qbz5n2kfra8p0\LocalCache\local-packages\Python39\site-packages\requests\sessions.py", line 646, in send
    r = adapter.send(request, **kwargs)
  File "C:\Users\User\AppData\Local\Packages\PythonSoftwareFoundation.Python.3.9_qbz5n2kfra8p0\LocalCache\local-packages\Python39\site-packages\requests\adapters.py", line 439, in send
    resp = conn.urlopen(
  File "C:\Users\User\AppData\Local\Packages\PythonSoftwareFoundation.Python.3.9_qbz5n2kfra8p0\LocalCache\local-packages\Python39\site-packages\urllib3\connectionpool.py", line 597, in urlopen
    httplib_response = self._make_request(conn, method, url,
  File "C:\Users\User\AppData\Local\Packages\PythonSoftwareFoundation.Python.3.9_qbz5n2kfra8p0\LocalCache\local-packages\Python39\site-packages\urllib3\connectionpool.py", line 354, in _make_request
    conn.request(method, url, **httplib_request_kw)
  File "C:\Program Files\WindowsApps\PythonSoftwareFoundation.Python.3.9_3.9.2032.0_x64__qbz5n2kfra8p0\lib\http\client.py", line 1279, in request
    self._send_request(method, url, body, headers, encode_chunked)
  File "C:\Program Files\WindowsApps\PythonSoftwareFoundation.Python.3.9_3.9.2032.0_x64__qbz5n2kfra8p0\lib\http\client.py", line 1325, in _send_request
    self.endheaders(body, encode_chunked=encode_chunked)
  File "C:\Program Files\WindowsApps\PythonSoftwareFoundation.Python.3.9_3.9.2032.0_x64__qbz5n2kfra8p0\lib\http\client.py", line 1274, in endheaders
    self._send_output(message_body, encode_chunked=encode_chunked)
  File "C:\Program Files\WindowsApps\PythonSoftwareFoundation.Python.3.9_3.9.2032.0_x64__qbz5n2kfra8p0\lib\http\client.py", line 1034, in _send_output
    self.send(msg)
  File "C:\Program Files\WindowsApps\PythonSoftwareFoundation.Python.3.9_3.9.2032.0_x64__qbz5n2kfra8p0\lib\http\client.py", line 974, in send
    self.connect()
  File "C:\Users\User\AppData\Local\Packages\PythonSoftwareFoundation.Python.3.9_qbz5n2kfra8p0\LocalCache\local-packages\Python39\site-packages\urllib3\connection.py", line 181, in connect
    conn = self._new_conn()
  File "C:\Users\User\AppData\Local\Packages\PythonSoftwareFoundation.Python.3.9_qbz5n2kfra8p0\LocalCache\local-packages\Python39\site-packages\urllib3\connection.py", line 158, in _new_conn
    conn = connection.create_connection(
  File "C:\Users\User\AppData\Local\Packages\PythonSoftwareFoundation.Python.3.9_qbz5n2kfra8p0\LocalCache\local-packages\Python39\site-packages\urllib3\util\connection.py", line 57, in create_connection
    for res in socket.getaddrinfo(host, port, family, socket.SOCK_STREAM):
  File "C:\Program Files\WindowsApps\PythonSoftwareFoundation.Python.3.9_3.9.2032.0_x64__qbz5n2kfra8p0\lib\socket.py", line 954, in getaddrinfo
    for res in _socket.getaddrinfo(host, port, family, type, proto, flags):
KeyboardInterrupt
2021-11-17 19:27:50,887 17076 news_content_collection ERROR Exception in getting data from url speedtalk.com/forum/viewtopic.php?t=51650
Traceback (most recent call last):
  File "C:\Users\User\AppData\Local\Packages\PythonSoftwareFoundation.Python.3.9_qbz5n2kfra8p0\LocalCache\local-packages\Python39\site-packages\urllib3\connectionpool.py", line 377, in _make_request
    httplib_response = conn.getresponse(buffering=True)
TypeError: getresponse() got an unexpected keyword argument 'buffering'

During handling of the above exception, another exception occurred:

Traceback (most recent call last):
  File "C:\Users\User\Desktop\ia2\FakeNewsNet\code\news_content_collection.py", line 34, in crawl_link_article
    article.download()
  File "C:\Users\User\AppData\Local\Packages\PythonSoftwareFoundation.Python.3.9_qbz5n2kfra8p0\LocalCache\local-packages\Python39\site-packages\newspaper\article.py", line 170, in download
    html = network.get_html_2XX_only(self.url, self.config)
  File "C:\Users\User\AppData\Local\Packages\PythonSoftwareFoundation.Python.3.9_qbz5n2kfra8p0\LocalCache\local-packages\Python39\site-packages\newspaper\network.py", line 62, in get_html_2XX_only
    response = requests.get(
  File "C:\Users\User\AppData\Local\Packages\PythonSoftwareFoundation.Python.3.9_qbz5n2kfra8p0\LocalCache\local-packages\Python39\site-packages\requests\api.py", line 75, in get
    return request('get', url, params=params, **kwargs)
  File "C:\Users\User\AppData\Local\Packages\PythonSoftwareFoundation.Python.3.9_qbz5n2kfra8p0\LocalCache\local-packages\Python39\site-packages\requests\api.py", line 60, in request
    return session.request(method=method, url=url, **kwargs)
  File "C:\Users\User\AppData\Local\Packages\PythonSoftwareFoundation.Python.3.9_qbz5n2kfra8p0\LocalCache\local-packages\Python39\site-packages\requests\sessions.py", line 533, in request
    resp = self.send(prep, **send_kwargs)
  File "C:\Users\User\AppData\Local\Packages\PythonSoftwareFoundation.Python.3.9_qbz5n2kfra8p0\LocalCache\local-packages\Python39\site-packages\requests\sessions.py", line 646, in send
    r = adapter.send(request, **kwargs)
  File "C:\Users\User\AppData\Local\Packages\PythonSoftwareFoundation.Python.3.9_qbz5n2kfra8p0\LocalCache\local-packages\Python39\site-packages\requests\adapters.py", line 439, in send
    resp = conn.urlopen(
  File "C:\Users\User\AppData\Local\Packages\PythonSoftwareFoundation.Python.3.9_qbz5n2kfra8p0\LocalCache\local-packages\Python39\site-packages\urllib3\connectionpool.py", line 597, in urlopen
    httplib_response = self._make_request(conn, method, url,
  File "C:\Users\User\AppData\Local\Packages\PythonSoftwareFoundation.Python.3.9_qbz5n2kfra8p0\LocalCache\local-packages\Python39\site-packages\urllib3\connectionpool.py", line 380, in _make_request
    httplib_response = conn.getresponse()
  File "C:\Program Files\WindowsApps\PythonSoftwareFoundation.Python.3.9_3.9.2032.0_x64__qbz5n2kfra8p0\lib\http\client.py", line 1371, in getresponse
    response.begin()
  File "C:\Program Files\WindowsApps\PythonSoftwareFoundation.Python.3.9_3.9.2032.0_x64__qbz5n2kfra8p0\lib\http\client.py", line 319, in begin
    version, status, reason = self._read_status()
  File "C:\Program Files\WindowsApps\PythonSoftwareFoundation.Python.3.9_3.9.2032.0_x64__qbz5n2kfra8p0\lib\http\client.py", line 280, in _read_status
    line = str(self.fp.readline(_MAXLINE + 1), "iso-8859-1")
  File "C:\Program Files\WindowsApps\PythonSoftwareFoundation.Python.3.9_3.9.2032.0_x64__qbz5n2kfra8p0\lib\socket.py", line 704, in readinto
    return self._sock.recv_into(b)
  File "C:\Program Files\WindowsApps\PythonSoftwareFoundation.Python.3.9_3.9.2032.0_x64__qbz5n2kfra8p0\lib\ssl.py", line 1241, in recv_into
    return self.read(nbytes, buffer)
  File "C:\Program Files\WindowsApps\PythonSoftwareFoundation.Python.3.9_3.9.2032.0_x64__qbz5n2kfra8p0\lib\ssl.py", line 1099, in read
    return self._sslobj.read(len, buffer)
KeyboardInterrupt
